Workbook

Sheet Raw Snapshot
A1: subscription_id | B1: customer_id | C1: company_name | D1: account_owner | E1: region | F1: plan_name | G1: billing_cycle | H1: mrr
A2: SUB025 | B2: CUST025 | C2: Montreal Manufacturing Pro | D2: Sarah Chen | E2: Eastern Canada | F2: Analytics Enterprise | G2: Annual | H2: 6840
A3: SUB031 | B3: CUST031 | C3: Toronto Digital Media | D3: James Wilson | E3: Eastern Canada | F3: Platform Suite | G3: Annual | H3: 6750
A4: SUB018 | B4: CUST018 | C4: Vancouver FinTech Labs | D4: Michael Rodriguez | E4: Western Canada | F4: Analytics Enterprise | G4: Monthly | H4: 6300
A5: SUB016 | B5: CUST016 | C5: Quebec Manufacturing | D5: Sarah Chen | E5: Eastern Canada | F5: Platform Suite | G5: Annual | H5: 6300
A6: SUB053 | B6: CUST027 | C6: Pacific Finance Corp | D6: Michael Rodriguez | E6: Western Canada | F6: Analytics Enterprise | G6: Monthly | H6: 5580
A7: SUB006 | B7: CUST006 | C7: Northern Retail Solutions | D7: Michael Rodriguez | E7: Western Canada | F7: Analytics Enterprise | G7: Annual | H7: 5580
A8: SUB009 | B8: CUST009 | C8: West Coast Logistics | D8: Michael Rodriguez | E8: Western Canada | F8: Platform Suite | G8: Annual | H8: 5400
A9: SUB037 | B9: CUST037 | C9: Maritime SaaS Ventures | D9: Sarah Chen | E9: Eastern Canada | F9: Platform Suite | G9: Monthly | H9: 5250
A10: SUB022 | B10: CUST022 | C10: Toronto Tech Ventures | D10: James Wilson | E10: Eastern Canada | F10: Platform Suite | G10: Monthly | H10: 4950
A11: SUB032 | B11: CUST032 | C11: BC Manufacturing Systems | D11: Michael Rodriguez | E11: Western Canada | F11: Analytics Enterprise | G11: Monthly | H11: 4680
A12: SUB057 | B12: CUST021 | C12: Calgary Commerce Solutions | D12: Michael Rodriguez | E12: Western Canada | F12: Platform Suite | G12: Monthly | H12: 4200
A13: SUB048 | B13: CUST025 | C13: Montreal Manufacturing Pro | D13: Sarah Chen | E13: Eastern Canada | F13: Sales Hub | G13: Monthly | H13: 3960
... A52: SUB017 | B52: CUST017 | C52: Capital Education Tech | D52: James Wilson | E52: Eastern Canada | F52: Analytics Starter | G52: Monthly | H52: 540

Sheet Raw Events
A1: event_id | B1: subscription_id | C1: customer_id | D1: company_name | E1: region | F1: month | G1: event_date | H1: event_date | I1: event_type | J1: old_value | K1: new_value | L1: field_changed | M1: reason | N1: plan_name | O1: billing_cycle | P1: price_per_seat | Q1: discount_percent
A2: EVT001 | B2: SUB001 | C2: CUST001 | D2: TechVision Solutions | E2: Eastern Canada | F2: 45292 | G2: 45299 | H2: 45299 | I2: created | N2: Analytics Growth | O2: Monthly | P2: 95 | Q2: 0
A3: EVT002 | B3: SUB002 | C3: CUST002 | D3: Pacific Analytics Inc | E3: Western Canada | F3: 45292 | G3: 45313 | H3: 45313 | I3: created | N3: Platform Suite | O3: Annual | P3: 1800 | Q3: 0
A4: EVT003 | B4: SUB003 | C4: CUST003 | D4: Maple Healthcare Systems | E4: Eastern Canada | F4: 45323 | G4: 45327 | H4: 45327 | I4: created | N4: Marketing Pro | O4: Monthly | P4: 85 | Q4: 0
A5: EVT004 | B5: SUB004 | C5: CUST004 | D5: Prairie Commerce Group | E5: Western Canada | F5: 45323 | G5: 45341 | H5: 45341 | I5: created | N5: Sales Hub | O5: Monthly | P5: 110 | Q5: 0
A6: EVT005 | B6: SUB055 | C6: CUST004 | D6: Prairie Commerce Group | E6: Western Canada | F6: 45323 | G6: 45341 | H6: 45341 | I6: created | N6: Analytics Enterprise | O6: Monthly | P6: 180 | Q6: 0
A7: EVT006 | B7: SUB005 | C7: CUST005 | D7: Atlantic Media Corp | E7: Eastern Canada | F7: 45352 | G7: 45355 | H7: 45355 | I7: created | N7: Analytics Starter | O7: Monthly | P7: 45 | Q7: 0
A8: EVT007 | B8: SUB006 | C8: CUST006 | D8: Northern Retail Solutions | E8: Western Canada | F8: 45352 | G8: 45369 | H8: 45369 | I8: created | N8: Analytics Enterprise | O8: Annual | P8: 2160 | Q8: 0
A9: EVT008 | B9: SUB007 | C9: CUST007 | D9: Ontario Manufacturing Tech | E9: Eastern Canada | F9: 45383 | G9: 45383 | H9: 45383 | I9: created | N9: Marketing Pro | O9: Monthly | P9: 85 | Q9: 0
A10: EVT009 | B10: SUB050 | C10: CUST007 | D10: Ontario Manufacturing Tech | E10: Eastern Canada | F10: 45383 | G10: 45383 | H10: 45383 | I10: created | N10: Analytics Starter | O10: Monthly | P10: 45 | Q10: 12
A11: EVT010 | B11: SUB008 | C11: CUST008 | D11: Quantum Education Platform | E11: Eastern Canada | F11: 45383 | G11: 45397 | H11: 45397 | I11: created | N11: Analytics Growth | O11: Monthly | P11: 95 | Q11: 0
A12: EVT011 | B12: SUB009 | C12: CUST009 | D12: West Coast Logistics | E12: Western Canada | F12: 45383 | G12: 45411 | H12: 45411 | I12: created | N12: Platform Suite | O12: Annual | P12: 1800 | Q12: 0
A13: EVT012 | B13: SUB010 | C13: CUST010 | D13: Montreal Finance Hub | E13: Eastern Canada | F13: 45413 | G13: 45425 | H13: 45425 | I13: created | N13: Analytics Starter | O13: Monthly | P13: 45 | Q13: 0
... A23: EVT022 | B23: SUB017 | C23: CUST017 | D23: Capital Education Tech | E23: Eastern Canada | F23: 45505 | G23: 45523 | H23: 45523 | I23: created | N23: Analytics Starter | O23: Monthly | P23: 45 | Q23: 0
A24: EVT023 | B24: SUB001 | C24: CUST001 | D24: TechVision Solutions | E24: Eastern Canada | F24: 45505 | G24: 45531 | H24: 45531 | I24: cancelled | J24: active | K24: churned | L24: status | M24: Missing features | N24: Analytics Growth | O24: Monthly | P24: 95 | Q24: 0
A25: EVT024 | B25: SUB018 | C25: CUST018 | D25: Vancouver FinTech Labs | E25: Western Canada | F25: 45536 | G25: 45537 | H25: 45537 | I25: created | N25: Analytics Enterprise | O25: Monthly | P25: 180 | Q25: 0
A26: EVT025 | B26: SUB042 | C26: CUST003 | D26: Maple Healthcare Systems | E26: Eastern Canada | F26: 45536 | G26: 45545 | H26: 45545 | I26: created | N26: Sales Hub | O26: Monthly | P26: 110 | Q26: 0
A27: EVT026 | B27: SUB019 | C27: CUST019 | D27: Central Healthcare Partners | E27: Central Canada | F27: 45536 | G27: 45551 | H27: 45551 | I27: created | N27: Marketing Pro | O27: Monthly | P27: 85 | Q27: 0
A28: EVT027 | B28: SUB060 | C28: CUST019 | D28: Central Healthcare Partners | E28: Central Canada | F28: 45536 | G28: 45551 | H28: 45551 | I28: created | N28: Sales Hub | O28: Monthly | P28: 110 | Q28: 0
A29: EVT028 | B29: SUB020 | C29: CUST020 | D29: Atlantic SaaS Systems | E29: Eastern Canada | F29: 45536 | G29: 45565 | H29: 45565 | I29: created | N29: Sales Hub | O29: Monthly | P29: 110 | Q29: 0
A30: EVT029 | B30: SUB043 | C30: CUST006 | D30: Northern Retail Solutions | E30: Western Canada | F30: 45566 | G30: 45570 | H30: 45570 | I30: created | N30: Marketing Pro | O30: Monthly | P30: 85 | Q30: 0
A31: EVT030 | B31: SUB021 | C31: CUST021 | D31: Calgary Commerce Solutions | E31: Western Canada | F31: 45566 | G31: 45579 | H31: 45579 | I31: created | N31: Analytics Growth | O31: Monthly | P31: 95 | Q31: 0
A32: EVT031 | B32: SUB022 | C32: CUST022 | D32: Toronto Tech Ventures | E32: Eastern Canada | F32: 45566 | G32: 45593 | H32: 45593 | I32: created | N32: Platform Suite | O32: Monthly | P32: 150 | Q32: 0
A33: EVT032 | B33: SUB059 | C33: CUST008 | D33: Quantum Education Platform | E33: Eastern Canada | F33: 45597 | G33: 45601 | H33: 45601 | I33: created | N33: Marketing Pro | O33: Monthly | P33: 85 | Q33: 0
A34: EVT033 | B34: SUB023 | C34: CUST023 | D34: Island Media Productions | E34: Eastern Canada | F34: 45597 | G34: 45607 | H34: 45607 | I34: created | N34: Analytics Starter | O34: Monthly | P34: 45 | Q34: 0
A35: EVT034 | B35: SUB005 | C35: CUST005 | D35: Atlantic Media Corp | E35: Eastern Canada | F35: 45597 | G35: 45616 | H35: 45616 | I35: cancelled | J35: active | K35: churned | L35: status | M35: Price too high | N35: Analytics Starter | O35: Monthly | P35: 45 | Q35: 0
A36: EVT035 | B36: SUB024 | C36: CUST024 | D36: Western Retail Group | E36: Western Canada | F36: 45597 | G36: 45621 | H36: 45621 | I36: created | N36: Marketing Pro | O36: Monthly | P36: 85 | Q36: 0
A37: EVT036 | B37: SUB025 | C37: CUST025 | D37: Montreal Manufacturing Pro | E37: Eastern Canada | F37: 45627 | G37: 45635 | H37: 45635 | I37: created | N37: Analytics Enterprise | O37: Annual | P37: 2160 | Q37: 0
A38: EVT037 | B38: SUB056 | C38: CUST016 | D38: Quebec Manufacturing | E38: Eastern Canada | F38: 45627 | G38: 45638 | H38: 45638 | I38: created | N38: Marketing Pro | O38: Monthly | P38: 85 | Q38: 0
A39: EVT038 | B39: SUB044 | C39: CUST009 | D39: West Coast Logistics | E39: Western Canada | F39: 45627 | G39: 45646 | H39: 45646 | I39: created | N39: Analytics Growth | O39: Monthly | P39: 95 | Q39: 0
A40: EVT039 | B40: SUB008 | C40: CUST008 | D40: Quantum Education Platform | E40: Eastern Canada | F40: 45627 | G40: 45648 | H40: 45648 | I40: cancelled | J40: active | K40: churned | L40: status | M40: Price too high | N40: Analytics Growth | O40: Monthly | P40: 95 | Q40: 0
A41: EVT040 | B41: SUB026 | C41: CUST026 | D41: Ontario Education Connect | E41: Eastern Canada | F41: 45627 | G41: 45649 | H41: 45649 | I41: created | N41: Analytics Growth | O41: Monthly | P41: 95 | Q41: 0
A42: EVT041 | B42: SUB027 | C42: CUST027 | D42: Pacific Finance Corp | E42: Western Canada | F42: 45658 | G42: 45663 | H42: 45663 | I42: created | N42: Sales Hub | O42: Monthly | P42: 110 | Q42: 0
A43: EVT042 | B43: SUB014 | C43: CUST014 | D43: Toronto Media Group | E43: Eastern Canada | F43: 45658 | G43: 45665 | H43: 45665 | I43: price_change | J43: 80 | K43: 85 | L43: price_per_seat | M43: Annual price increase applied at renewal | N43: Marketing Pro | O43: Monthly | P43: 85 | Q43: 0
A44: EVT043 | B44: SUB013 | C44: CUST013 | D44: Alberta Tech Innovators | E44: Western Canada | F44: 45658 | G44: 45672 | H44: 45672 | I44: cancelled | J44: active | K44: churned | L44: status | M44: Switched to competitor | N44: Analytics Starter | O44: Monthly | P44: 45 | Q44: 0
A45: EVT044 | B45: SUB028 | C45: CUST028 | D45: Prairie SaaS Innovations | E45: Central Canada | F45: 45658 | G45: 45677 | H45: 45677 | I45: created | N45: Analytics Starter | O45: Monthly | P45: 45 | Q45: 0
A46: EVT045 | B46: SUB054 | C46: CUST002 | D46: Pacific Analytics Inc | E46: Western Canada | F46: 45658 | G46: 45679 | H46: 45679 | I46: created | N46: Analytics Growth | O46: Annual | P46: 1140 | Q46: 5
A47: EVT046 | B47: SUB057 | C47: CUST021 | D47: Calgary Commerce Solutions | E47: Western Canada | F47: 45658 | G47: 45685 | H47: 45685 | I47: created | N47: Platform Suite | O47: Monthly | P47: 150 | Q47: 0
A48: EVT047 | B48: SUB029 | C48: CUST029 | D48: Halifax Healthcare Tech | E48: Eastern Canada | F48: 45689 | G48: 45691 | H48: 45691 | I48: created | N48: Marketing Pro | O48: Monthly | P48: 85 | Q48: 0
A49: EVT048 | B49: SUB045 | C49: CUST010 | D49: Montreal Finance Hub | E49: Eastern Canada | F49: 45689 | G49: 45696 | H49: 45696 | I49: created | N49: Marketing Pro | O49: Monthly | P49: 85 | Q49: 0
...

Sheet Raw Cash
A1: month | B1: invoice_count | C1: revenue | D1: running_total | E1: prior_month_revenue | F1: pct_change
A2: 45292 | B2: 2 | C2: 48700 | D2: 48700
A3: 45323 | B3: 4 | C3: 10185 | D3: 58885 | E3: 48700 | F3: -79.1
A4: 45352 | B4: 6 | C4: 77640 | D4: 136525 | E4: 10185 | F4: 662.3
A5: 45383 | B5: 8 | C5: 78930 | D5: 215455 | E5: 77640 | F5: 1.7
A6: 45413 | B6: 10 | C6: 17580 | D6: 233035 | E6: 78930 | F6: -77.7
A7: 45444 | B7: 13 | C7: 20595 | D7: 253630 | E7: 17580 | F7: 17.2
A8: 45474 | B8: 16 | C8: 26400 | D8: 280030 | E8: 20595 | F8: 28.2
A9: 45505 | B9: 19 | C9: 106740 | D9: 386770 | E9: 26400 | F9: 304.3
A10: 45536 | B10: 22 | C10: 42010 | D10: 428780 | E10: 106740 | F10: -60.6
A11: 45566 | B11: 25 | C11: 51390 | D11: 480170 | E11: 42010 | F11: 22.3
A12: 45597 | B12: 28 | C12: 55700 | D12: 535870 | E12: 51390 | F12: 8.4
A13: 45627 | B13: 31 | C13: 144560 | D13: 680430 | E13: 55700 | F13: 159.5
A14: 45658 | B14: 33 | C14: 139635 | D14: 820065 | E14: 144560 | F14: -3.4
... A27: 46054 | B27: 2 | C27: 2075 | D27: 2475630 | E27: 179985 | F27: -98.8

Sheet Ref
A1: plan_name | B1: monthly_price
A2: Analytics Starter | B2: 45
A3: Analytics Growth | B3: 95
A4: Analytics Enterprise | B4: 180
A5: Marketing Pro | B5: 85
A6: Sales Hub | B6: 110
A7: Platform Suite | B7: 150

Sheet Engine
A1: event_id | B1: subscription_id | C1: customer_id | D1: company_name | E1: region | F1: month | G1: event_date | H1: event_type | I1: old_value | J1: new_value | K1: field_changed | L1: reason | M1: plan_name | N1: billing_cycle | O1: seats | P1: price_per_seat | Q1: discount_percent | R1: movement | S1: mrr_delta | T1: is_new_logo | U1: is_logo_churn | V1: is_logo_reactivation
A2: EVT001 | B2: SUB001 | C2: CUST001 | D2: TechVision Solutions | E2: Eastern Canada | F2: 45292 | G2: 45299 | H2: created | M2: Analytics Growth | N2: Monthly | O2: 20 | P2: 95 | Q2: 0 | R2: {=_xlfn.IFS(H2="created", "New", H2="cancelled", "Churned", AND(H2="seats_change", J2 > I2), "Expansion", AND(H2="seats_change", J2 < I2), "Contraction", AND(H2="price_change", J2 > I2), "Expansion", AND(H2="price_change", J2 < I2), "Contraction", H2="plan_upgrade", "Expansion", H2="plan_downgrade", "Contraction", H2="discount_added", "Contraction")} -> New | S2: {=IF(N2="Monthly",_xlfn.IFS(H2="created",O2*P2*(1-Q2/100),H2="cancelled",-(O2*P2*(1-Q2/100)),H2="seats_change",(J2-I2)*P2*(1-Q2/100),H2="price_change",(J2-I2)*O2*(1-Q2/100),H2="discount_added",-(O2*P2*(J2-I2)/100),H2="plan_upgrade",O2*(_xlfn.XLOOKUP(J2,$M:$M,$P:$P)-_xlfn.XLOOKUP(I2,$M:$M,$P:$P))*(1-Q2/100),H2="plan_downgrade",O2*(_xlfn.XLOOKUP(J2,$M:$M,$P:$P)-_xlfn.XLOOKUP(I2,$M:$M,$P:$P))*(1-Q2/100)),_xlfn.IFS(H2="created",O2*P2*(1-Q2/100)/12,H2="cancelled",-(O2*P2*(1-Q2/100))/12,H2="seats_change",(J2-I2)*P2*(1-Q2/100)/12,H2="price_change",(J2-I2)*O2*(1-Q2/100)/12,H2="plan_upgrade",(O2*(_xlfn.XLOOKUP(J2,$M:$M,$P:$P)-_xlfn.XLOOKUP(I2,$M:$M,$P:$P))*(1-Q2/100))/12,H2="plan_downgrade",(O2*(_xlfn.XLOOKUP(J2,$M:$M,$P:$P)-_xlfn.XLOOKUP(I2,$M:$M,$P:$P))*(1-Q2/100))/12,H2="discount_added",-(O2*P2*(J2-I2)/100)/12))} -> 1900 | T2: =IF(H2<>"created",0,IF(COUNTIFS($C$1:C1,$C2,$H$1:H1,"created")=0,1,0)) -> 1 | U2: =IF(H2<>"cancelled",0,IF(COUNTIFS($C$2:$C$98,$C2,$H$2:$H$98,"created",$F$2:$F$98,"<="&F2)-COUNTIFS($C$2:$C$98,$C2,$H$2:$H$98,"cancelled",$F$2:$F$98,"<="&F2)=0,1,0)) -> 0 | V2: =IF(AND(H2="created",T2=0,COUNTIFS($C$2:$C$98,$C2,$H$2:$H$98,"cancelled",$F$2:$F$98,"<"&F2)>0,COUNTIFS($C$2:$C$98,$C2,$H$2:$H$98,"created",$F$2:$F$98,"<"&F2)-COUNTIFS($C$2:$C$98,$C2,$H$2:$H$98,"cancelled",$F$2:$F$98,"<"&F2)=0),1,0) -> 0
A3: EVT002 | B3: SUB002 | C3: CUST002 | D3: Pacific Analytics Inc | E3: Western Canada | F3: 45292 | G3: 45313 | H3: created | M3: Platform Suite | N3: Annual | O3: 26 | P3: 1800 | Q3: 0 | R3: {=_xlfn.IFS(H3="created", "New", H3="cancelled", "Churned", AND(H3="seats_change", J3 > I3), "Expansion", AND(H3="seats_change", J3 < I3), "Contraction", AND(H3="price_change", J3 > I3), "Expansion", AND(H3="price_change", J3 < I3), "Contraction", H3="plan_upgrade", "Expansion", H3="plan_downgrade", "Contraction", H3="discount_added", "Contraction")} -> New | S3: {=IF(N3="Monthly",_xlfn.IFS(H3="created",O3*P3*(1-Q3/100),H3="cancelled",-(O3*P3*(1-Q3/100)),H3="seats_change",(J3-I3)*P3*(1-Q3/100),H3="price_change",(J3-I3)*O3*(1-Q3/100),H3="discount_added",-(O3*P3*(J3-I3)/100),H3="plan_upgrade",O3*(_xlfn.XLOOKUP(J3,$M:$M,$P:$P)-_xlfn.XLOOKUP(I3,$M:$M,$P:$P))*(1-Q3/100),H3="plan_downgrade",O3*(_xlfn.XLOOKUP(J3,$M:$M,$P:$P)-_xlfn.XLOOKUP(I3,$M:$M,$P:$P))*(1-Q3/100)),_xlfn.IFS(H3="created",O3*P3*(1-Q3/100)/12,H3="cancelled",-(O3*P3*(1-Q3/100))/12,H3="seats_change",(J3-I3)*P3*(1-Q3/100)/12,H3="price_change",(J3-I3)*O3*(1-Q3/100)/12,H3="plan_upgrade",(O3*(_xlfn.XLOOKUP(J3,$M:$M,$P:$P)-_xlfn.XLOOKUP(I3,$M:$M,$P:$P))*(1-Q3/100))/12,H3="plan_downgrade",(O3*(_xlfn.XLOOKUP(J3,$M:$M,$P:$P)-_xlfn.XLOOKUP(I3,$M:$M,$P:$P))*(1-Q3/100))/12,H3="discount_added",-(O3*P3*(J3-I3)/100)/12))} -> 3900 | T3: =IF(H3<>"created",0,IF(COUNTIFS($C$1:C2,$C3,$H$1:H2,"created")=0,1,0)) -> 1 | U3: =IF(H3<>"cancelled",0,IF(COUNTIFS($C$2:$C$98,$C3,$H$2:$H$98,"created",$F$2:$F$98,"<="&F3)-COUNTIFS($C$2:$C$98,$C3,$H$2:$H$98,"cancelled",$F$2:$F$98,"<="&F3)=0,1,0)) -> 0 | V3: =IF(AND(H3="created",T3=0,COUNTIFS($C$2:$C$98,$C3,$H$2:$H$98,"cancelled",$F$2:$F$98,"<"&F3)>0,COUNTIFS($C$2:$C$98,$C3,$H$2:$H$98,"created",$F$2:$F$98,"<"&F3)-COUNTIFS($C$2:$C$98,$C3,$H$2:$H$98,"cancelled",$F$2:$F$98,"<"&F3)=0),1,0) -> 0
A4: EVT003 | B4: SUB003 | C4: CUST003 | D4: Maple Healthcare Systems | E4: Eastern Canada | F4: 45323 | G4: 45327 | H4: created | M4: Marketing Pro | N4: Monthly | O4: 23 | P4: 85 | Q4: 0 | R4: {=_xlfn.IFS(H4="created", "New", H4="cancelled", "Churned", AND(H4="seats_change", J4 > I4), "Expansion", AND(H4="seats_change", J4 < I4), "Contraction", AND(H4="price_change", J4 > I4), "Expansion", AND(H4="price_change", J4 < I4), "Contraction", H4="plan_upgrade", "Expansion", H4="plan_downgrade", "Contraction", H4="discount_added", "Contraction")} -> New | S4: {=IF(N4="Monthly",_xlfn.IFS(H4="created",O4*P4*(1-Q4/100),H4="cancelled",-(O4*P4*(1-Q4/100)),H4="seats_change",(J4-I4)*P4*(1-Q4/100),H4="price_change",(J4-I4)*O4*(1-Q4/100),H4="discount_added",-(O4*P4*(J4-I4)/100),H4="plan_upgrade",O4*(_xlfn.XLOOKUP(J4,$M:$M,$P:$P)-_xlfn.XLOOKUP(I4,$M:$M,$P:$P))*(1-Q4/100),H4="plan_downgrade",O4*(_xlfn.XLOOKUP(J4,$M:$M,$P:$P)-_xlfn.XLOOKUP(I4,$M:$M,$P:$P))*(1-Q4/100)),_xlfn.IFS(H4="created",O4*P4*(1-Q4/100)/12,H4="cancelled",-(O4*P4*(1-Q4/100))/12,H4="seats_change",(J4-I4)*P4*(1-Q4/100)/12,H4="price_change",(J4-I4)*O4*(1-Q4/100)/12,H4="plan_upgrade",(O4*(_xlfn.XLOOKUP(J4,$M:$M,$P:$P)-_xlfn.XLOOKUP(I4,$M:$M,$P:$P))*(1-Q4/100))/12,H4="plan_downgrade",(O4*(_xlfn.XLOOKUP(J4,$M:$M,$P:$P)-_xlfn.XLOOKUP(I4,$M:$M,$P:$P))*(1-Q4/100))/12,H4="discount_added",-(O4*P4*(J4-I4)/100)/12))} -> 1955 | T4: =IF(H4<>"created",0,IF(COUNTIFS($C$1:C3,$C4,$H$1:H3,"created")=0,1,0)) -> 1 | U4: =IF(H4<>"cancelled",0,IF(COUNTIFS($C$2:$C$98,$C4,$H$2:$H$98,"created",$F$2:$F$98,"<="&F4)-COUNTIFS($C$2:$C$98,$C4,$H$2:$H$98,"cancelled",$F$2:$F$98,"<="&F4)=0,1,0)) -> 0 | V4: =IF(AND(H4="created",T4=0,COUNTIFS($C$2:$C$98,$C4,$H$2:$H$98,"cancelled",$F$2:$F$98,"<"&F4)>0,COUNTIFS($C$2:$C$98,$C4,$H$2:$H$98,"created",$F$2:$F$98,"<"&F4)-COUNTIFS($C$2:$C$98,$C4,$H$2:$H$98,"cancelled",$F$2:$F$98,"<"&F4)=0),1,0) -> 0
A5: EVT004 | B5: SUB004 | C5: CUST004 | D5: Prairie Commerce Group | E5: Western Canada | F5: 45323 | G5: 45341 | H5: created | M5: Sales Hub | N5: Monthly | O5: 18 | P5: 110 | Q5: 0 | R5: {=_xlfn.IFS(H5="created", "New", H5="cancelled", "Churned", AND(H5="seats_change", J5 > I5), "Expansion", AND(H5="seats_change", J5 < I5), "Contraction", AND(H5="price_change", J5 > I5), "Expansion", AND(H5="price_change", J5 < I5), "Contraction", H5="plan_upgrade", "Expansion", H5="plan_downgrade", "Contraction", H5="discount_added", "Contraction")} -> New | S5: {=IF(N5="Monthly",_xlfn.IFS(H5="created",O5*P5*(1-Q5/100),H5="cancelled",-(O5*P5*(1-Q5/100)),H5="seats_change",(J5-I5)*P5*(1-Q5/100),H5="price_change",(J5-I5)*O5*(1-Q5/100),H5="discount_added",-(O5*P5*(J5-I5)/100),H5="plan_upgrade",O5*(_xlfn.XLOOKUP(J5,$M:$M,$P:$P)-_xlfn.XLOOKUP(I5,$M:$M,$P:$P))*(1-Q5/100),H5="plan_downgrade",O5*(_xlfn.XLOOKUP(J5,$M:$M,$P:$P)-_xlfn.XLOOKUP(I5,$M:$M,$P:$P))*(1-Q5/100)),_xlfn.IFS(H5="created",O5*P5*(1-Q5/100)/12,H5="cancelled",-(O5*P5*(1-Q5/100))/12,H5="seats_change",(J5-I5)*P5*(1-Q5/100)/12,H5="price_change",(J5-I5)*O5*(1-Q5/100)/12,H5="plan_upgrade",(O5*(_xlfn.XLOOKUP(J5,$M:$M,$P:$P)-_xlfn.XLOOKUP(I5,$M:$M,$P:$P))*(1-Q5/100))/12,H5="plan_downgrade",(O5*(_xlfn.XLOOKUP(J5,$M:$M,$P:$P)-_xlfn.XLOOKUP(I5,$M:$M,$P:$P))*(1-Q5/100))/12,H5="discount_added",-(O5*P5*(J5-I5)/100)/12))} -> 1980 | T5: =IF(H5<>"created",0,IF(COUNTIFS($C$1:C4,$C5,$H$1:H4,"created")=0,1,0)) -> 1 | U5: =IF(H5<>"cancelled",0,IF(COUNTIFS($C$2:$C$98,$C5,$H$2:$H$98,"created",$F$2:$F$98,"<="&F5)-COUNTIFS($C$2:$C$98,$C5,$H$2:$H$98,"cancelled",$F$2:$F$98,"<="&F5)=0,1,0)) -> 0 | V5: =IF(AND(H5="created",T5=0,COUNTIFS($C$2:$C$98,$C5,$H$2:$H$98,"cancelled",$F$2:$F$98,"<"&F5)>0,COUNTIFS($C$2:$C$98,$C5,$H$2:$H$98,"created",$F$2:$F$98,"<"&F5)-COUNTIFS($C$2:$C$98,$C5,$H$2:$H$98,"cancelled",$F$2:$F$98,"<"&F5)=0),1,0) -> 0
A6: EVT005 | B6: SUB055 | C6: CUST004 | D6: Prairie Commerce Group | E6: Western Canada | F6: 45323 | G6: 45341 | H6: created | M6: Analytics Enterprise | N6: Monthly | O6: 26 | P6: 180 | Q6: 0 | R6: {=_xlfn.IFS(H6="created", "New", H6="cancelled", "Churned", AND(H6="seats_change", J6 > I6), "Expansion", AND(H6="seats_change", J6 < I6), "Contraction", AND(H6="price_change", J6 > I6), "Expansion", AND(H6="price_change", J6 < I6), "Contraction", H6="plan_upgrade", "Expansion", H6="plan_downgrade", "Contraction", H6="discount_added", "Contraction")} -> New | S6: {=IF(N6="Monthly",_xlfn.IFS(H6="created",O6*P6*(1-Q6/100),H6="cancelled",-(O6*P6*(1-Q6/100)),H6="seats_change",(J6-I6)*P6*(1-Q6/100),H6="price_change",(J6-I6)*O6*(1-Q6/100),H6="discount_added",-(O6*P6*(J6-I6)/100),H6="plan_upgrade",O6*(_xlfn.XLOOKUP(J6,$M:$M,$P:$P)-_xlfn.XLOOKUP(I6,$M:$M,$P:$P))*(1-Q6/100),H6="plan_downgrade",O6*(_xlfn.XLOOKUP(J6,$M:$M,$P:$P)-_xlfn.XLOOKUP(I6,$M:$M,$P:$P))*(1-Q6/100)),_xlfn.IFS(H6="created",O6*P6*(1-Q6/100)/12,H6="cancelled",-(O6*P6*(1-Q6/100))/12,H6="seats_change",(J6-I6)*P6*(1-Q6/100)/12,H6="price_change",(J6-I6)*O6*(1-Q6/100)/12,H6="plan_upgrade",(O6*(_xlfn.XLOOKUP(J6,$M:$M,$P:$P)-_xlfn.XLOOKUP(I6,$M:$M,$P:$P))*(1-Q6/100))/12,H6="plan_downgrade",(O6*(_xlfn.XLOOKUP(J6,$M:$M,$P:$P)-_xlfn.XLOOKUP(I6,$M:$M,$P:$P))*(1-Q6/100))/12,H6="discount_added",-(O6*P6*(J6-I6)/100)/12))} -> 4680 | T6: =IF(H6<>"created",0,IF(COUNTIFS($C$1:C5,$C6,$H$1:H5,"created")=0,1,0)) -> 0 | U6: =IF(H6<>"cancelled",0,IF(COUNTIFS($C$2:$C$98,$C6,$H$2:$H$98,"created",$F$2:$F$98,"<="&F6)-COUNTIFS($C$2:$C$98,$C6,$H$2:$H$98,"cancelled",$F$2:$F$98,"<="&F6)=0,1,0)) -> 0 | V6: =IF(AND(H6="created",T6=0,COUNTIFS($C$2:$C$98,$C6,$H$2:$H$98,"cancelled",$F$2:$F$98,"<"&F6)>0,COUNTIFS($C$2:$C$98,$C6,$H$2:$H$98,"created",$F$2:$F$98,"<"&F6)-COUNTIFS($C$2:$C$98,$C6,$H$2:$H$98,"cancelled",$F$2:$F$98,"<"&F6)=0),1,0) -> 0
A7: EVT006 | B7: SUB005 | C7: CUST005 | D7: Atlantic Media Corp | E7: Eastern Canada | F7: 45352 | G7: 45355 | H7: created | M7: Analytics Starter | N7: Monthly | O7: 11 | P7: 45 | Q7: 0 | R7: {=_xlfn.IFS(H7="created", "New", H7="cancelled", "Churned", AND(H7="seats_change", J7 > I7), "Expansion", AND(H7="seats_change", J7 < I7), "Contraction", AND(H7="price_change", J7 > I7), "Expansion", AND(H7="price_change", J7 < I7), "Contraction", H7="plan_upgrade", "Expansion", H7="plan_downgrade", "Contraction", H7="discount_added", "Contraction")} -> New | S7: {=IF(N7="Monthly",_xlfn.IFS(H7="created",O7*P7*(1-Q7/100),H7="cancelled",-(O7*P7*(1-Q7/100)),H7="seats_change",(J7-I7)*P7*(1-Q7/100),H7="price_change",(J7-I7)*O7*(1-Q7/100),H7="discount_added",-(O7*P7*(J7-I7)/100),H7="plan_upgrade",O7*(_xlfn.XLOOKUP(J7,$M:$M,$P:$P)-_xlfn.XLOOKUP(I7,$M:$M,$P:$P))*(1-Q7/100),H7="plan_downgrade",O7*(_xlfn.XLOOKUP(J7,$M:$M,$P:$P)-_xlfn.XLOOKUP(I7,$M:$M,$P:$P))*(1-Q7/100)),_xlfn.IFS(H7="created",O7*P7*(1-Q7/100)/12,H7="cancelled",-(O7*P7*(1-Q7/100))/12,H7="seats_change",(J7-I7)*P7*(1-Q7/100)/12,H7="price_change",(J7-I7)*O7*(1-Q7/100)/12,H7="plan_upgrade",(O7*(_xlfn.XLOOKUP(J7,$M:$M,$P:$P)-_xlfn.XLOOKUP(I7,$M:$M,$P:$P))*(1-Q7/100))/12,H7="plan_downgrade",(O7*(_xlfn.XLOOKUP(J7,$M:$M,$P:$P)-_xlfn.XLOOKUP(I7,$M:$M,$P:$P))*(1-Q7/100))/12,H7="discount_added",-(O7*P7*(J7-I7)/100)/12))} -> 495 | T7: =IF(H7<>"created",0,IF(COUNTIFS($C$1:C6,$C7,$H$1:H6,"created")=0,1,0)) -> 1 | U7: =IF(H7<>"cancelled",0,IF(COUNTIFS($C$2:$C$98,$C7,$H$2:$H$98,"created",$F$2:$F$98,"<="&F7)-COUNTIFS($C$2:$C$98,$C7,$H$2:$H$98,"cancelled",$F$2:$F$98,"<="&F7)=0,1,0)) -> 0 | V7: =IF(AND(H7="created",T7=0,COUNTIFS($C$2:$C$98,$C7,$H$2:$H$98,"cancelled",$F$2:$F$98,"<"&F7)>0,COUNTIFS($C$2:$C$98,$C7,$H$2:$H$98,"created",$F$2:$F$98,"<"&F7)-COUNTIFS($C$2:$C$98,$C7,$H$2:$H$98,"cancelled",$F$2:$F$98,"<"&F7)=0),1,0) -> 0
A8: EVT007 | B8: SUB006 | C8: CUST006 | D8: Northern Retail Solutions | E8: Western Canada | F8: 45352 | G8: 45369 | H8: created | M8: Analytics Enterprise | N8: Annual | O8: 31 | P8: 2160 | Q8: 0 | R8: {=_xlfn.IFS(H8="created", "New", H8="cancelled", "Churned", AND(H8="seats_change", J8 > I8), "Expansion", AND(H8="seats_change", J8 < I8), "Contraction", AND(H8="price_change", J8 > I8), "Expansion", AND(H8="price_change", J8 < I8), "Contraction", H8="plan_upgrade", "Expansion", H8="plan_downgrade", "Contraction", H8="discount_added", "Contraction")} -> New | S8: {=IF(N8="Monthly",_xlfn.IFS(H8="created",O8*P8*(1-Q8/100),H8="cancelled",-(O8*P8*(1-Q8/100)),H8="seats_change",(J8-I8)*P8*(1-Q8/100),H8="price_change",(J8-I8)*O8*(1-Q8/100),H8="discount_added",-(O8*P8*(J8-I8)/100),H8="plan_upgrade",O8*(_xlfn.XLOOKUP(J8,$M:$M,$P:$P)-_xlfn.XLOOKUP(I8,$M:$M,$P:$P))*(1-Q8/100),H8="plan_downgrade",O8*(_xlfn.XLOOKUP(J8,$M:$M,$P:$P)-_xlfn.XLOOKUP(I8,$M:$M,$P:$P))*(1-Q8/100)),_xlfn.IFS(H8="created",O8*P8*(1-Q8/100)/12,H8="cancelled",-(O8*P8*(1-Q8/100))/12,H8="seats_change",(J8-I8)*P8*(1-Q8/100)/12,H8="price_change",(J8-I8)*O8*(1-Q8/100)/12,H8="plan_upgrade",(O8*(_xlfn.XLOOKUP(J8,$M:$M,$P:$P)-_xlfn.XLOOKUP(I8,$M:$M,$P:$P))*(1-Q8/100))/12,H8="plan_downgrade",(O8*(_xlfn.XLOOKUP(J8,$M:$M,$P:$P)-_xlfn.XLOOKUP(I8,$M:$M,$P:$P))*(1-Q8/100))/12,H8="discount_added",-(O8*P8*(J8-I8)/100)/12))} -> 5580 | T8: =IF(H8<>"created",0,IF(COUNTIFS($C$1:C7,$C8,$H$1:H7,"created")=0,1,0)) -> 1 | U8: =IF(H8<>"cancelled",0,IF(COUNTIFS($C$2:$C$98,$C8,$H$2:$H$98,"created",$F$2:$F$98,"<="&F8)-COUNTIFS($C$2:$C$98,$C8,$H$2:$H$98,"cancelled",$F$2:$F$98,"<="&F8)=0,1,0)) -> 0 | V8: =IF(AND(H8="created",T8=0,COUNTIFS($C$2:$C$98,$C8,$H$2:$H$98,"cancelled",$F$2:$F$98,"<"&F8)>0,COUNTIFS($C$2:$C$98,$C8,$H$2:$H$98,"created",$F$2:$F$98,"<"&F8)-COUNTIFS($C$2:$C$98,$C8,$H$2:$H$98,"cancelled",$F$2:$F$98,"<"&F8)=0),1,0) -> 0
A9: EVT008 | B9: SUB007 | C9: CUST007 | D9: Ontario Manufacturing Tech | E9: Eastern Canada | F9: 45383 | G9: 45383 | H9: created | M9: Marketing Pro | N9: Monthly | O9: 16 | P9: 85 | Q9: 0 | R9: {=_xlfn.IFS(H9="created", "New", H9="cancelled", "Churned", AND(H9="seats_change", J9 > I9), "Expansion", AND(H9="seats_change", J9 < I9), "Contraction", AND(H9="price_change", J9 > I9), "Expansion", AND(H9="price_change", J9 < I9), "Contraction", H9="plan_upgrade", "Expansion", H9="plan_downgrade", "Contraction", H9="discount_added", "Contraction")} -> New | S9: {=IF(N9="Monthly",_xlfn.IFS(H9="created",O9*P9*(1-Q9/100),H9="cancelled",-(O9*P9*(1-Q9/100)),H9="seats_change",(J9-I9)*P9*(1-Q9/100),H9="price_change",(J9-I9)*O9*(1-Q9/100),H9="discount_added",-(O9*P9*(J9-I9)/100),H9="plan_upgrade",O9*(_xlfn.XLOOKUP(J9,$M:$M,$P:$P)-_xlfn.XLOOKUP(I9,$M:$M,$P:$P))*(1-Q9/100),H9="plan_downgrade",O9*(_xlfn.XLOOKUP(J9,$M:$M,$P:$P)-_xlfn.XLOOKUP(I9,$M:$M,$P:$P))*(1-Q9/100)),_xlfn.IFS(H9="created",O9*P9*(1-Q9/100)/12,H9="cancelled",-(O9*P9*(1-Q9/100))/12,H9="seats_change",(J9-I9)*P9*(1-Q9/100)/12,H9="price_change",(J9-I9)*O9*(1-Q9/100)/12,H9="plan_upgrade",(O9*(_xlfn.XLOOKUP(J9,$M:$M,$P:$P)-_xlfn.XLOOKUP(I9,$M:$M,$P:$P))*(1-Q9/100))/12,H9="plan_downgrade",(O9*(_xlfn.XLOOKUP(J9,$M:$M,$P:$P)-_xlfn.XLOOKUP(I9,$M:$M,$P:$P))*(1-Q9/100))/12,H9="discount_added",-(O9*P9*(J9-I9)/100)/12))} -> 1360 | T9: =IF(H9<>"created",0,IF(COUNTIFS($C$1:C8,$C9,$H$1:H8,"created")=0,1,0)) -> 1 | U9: =IF(H9<>"cancelled",0,IF(COUNTIFS($C$2:$C$98,$C9,$H$2:$H$98,"created",$F$2:$F$98,"<="&F9)-COUNTIFS($C$2:$C$98,$C9,$H$2:$H$98,"cancelled",$F$2:$F$98,"<="&F9)=0,1,0)) -> 0 | V9: =IF(AND(H9="created",T9=0,COUNTIFS($C$2:$C$98,$C9,$H$2:$H$98,"cancelled",$F$2:$F$98,"<"&F9)>0,COUNTIFS($C$2:$C$98,$C9,$H$2:$H$98,"created",$F$2:$F$98,"<"&F9)-COUNTIFS($C$2:$C$98,$C9,$H$2:$H$98,"cancelled",$F$2:$F$98,"<"&F9)=0),1,0) -> 0
A10: EVT009 | B10: SUB050 | C10: CUST007 | D10: Ontario Manufacturing Tech | E10: Eastern Canada | F10: 45383 | G10: 45383 | H10: created | M10: Analytics Starter | N10: Monthly | O10: 15 | P10: 45 | Q10: 12 | R10: {=_xlfn.IFS(H10="created", "New", H10="cancelled", "Churned", AND(H10="seats_change", J10 > I10), "Expansion", AND(H10="seats_change", J10 < I10), "Contraction", AND(H10="price_change", J10 > I10), "Expansion", AND(H10="price_change", J10 < I10), "Contraction", H10="plan_upgrade", "Expansion", H10="plan_downgrade", "Contraction", H10="discount_added", "Contraction")} -> New | S10: {=IF(N10="Monthly",_xlfn.IFS(H10="created",O10*P10*(1-Q10/100),H10="cancelled",-(O10*P10*(1-Q10/100)),H10="seats_change",(J10-I10)*P10*(1-Q10/100),H10="price_change",(J10-I10)*O10*(1-Q10/100),H10="discount_added",-(O10*P10*(J10-I10)/100),H10="plan_upgrade",O10*(_xlfn.XLOOKUP(J10,$M:$M,$P:$P)-_xlfn.XLOOKUP(I10,$M:$M,$P:$P))*(1-Q10/100),H10="plan_downgrade",O10*(_xlfn.XLOOKUP(J10,$M:$M,$P:$P)-_xlfn.XLOOKUP(I10,$M:$M,$P:$P))*(1-Q10/100)),_xlfn.IFS(H10="created",O10*P10*(1-Q10/100)/12,H10="cancelled",-(O10*P10*(1-Q10/100))/12,H10="seats_change",(J10-I10)*P10*(1-Q10/100)/12,H10="price_change",(J10-I10)*O10*(1-Q10/100)/12,H10="plan_upgrade",(O10*(_xlfn.XLOOKUP(J10,$M:$M,$P:$P)-_xlfn.XLOOKUP(I10,$M:$M,$P:$P))*(1-Q10/100))/12,H10="plan_downgrade",(O10*(_xlfn.XLOOKUP(J10,$M:$M,$P:$P)-_xlfn.XLOOKUP(I10,$M:$M,$P:$P))*(1-Q10/100))/12,H10="discount_added",-(O10*P10*(J10-I10)/100)/12))} -> 594 | T10: =IF(H10<>"created",0,IF(COUNTIFS($C$1:C9,$C10,$H$1:H9,"created")=0,1,0)) -> 0 | U10: =IF(H10<>"cancelled",0,IF(COUNTIFS($C$2:$C$98,$C10,$H$2:$H$98,"created",$F$2:$F$98,"<="&F10)-COUNTIFS($C$2:$C$98,$C10,$H$2:$H$98,"cancelled",$F$2:$F$98,"<="&F10)=0,1,0)) -> 0 | V10: =IF(AND(H10="created",T10=0,COUNTIFS($C$2:$C$98,$C10,$H$2:$H$98,"cancelled",$F$2:$F$98,"<"&F10)>0,COUNTIFS($C$2:$C$98,$C10,$H$2:$H$98,"created",$F$2:$F$98,"<"&F10)-COUNTIFS($C$2:$C$98,$C10,$H$2:$H$98,"cancelled",$F$2:$F$98,"<"&F10)=0),1,0) -> 0
A11: EVT010 | B11: SUB008 | C11: CUST008 | D11: Quantum Education Platform | E11: Eastern Canada | F11: 45383 | G11: 45397 | H11: created | M11: Analytics Growth | N11: Monthly | O11: 22 | P11: 95 | Q11: 0 | R11: {=_xlfn.IFS(H11="created", "New", H11="cancelled", "Churned", AND(H11="seats_change", J11 > I11), "Expansion", AND(H11="seats_change", J11 < I11), "Contraction", AND(H11="price_change", J11 > I11), "Expansion", AND(H11="price_change", J11 < I11), "Contraction", H11="plan_upgrade", "Expansion", H11="plan_downgrade", "Contraction", H11="discount_added", "Contraction")} -> New | S11: {=IF(N11="Monthly",_xlfn.IFS(H11="created",O11*P11*(1-Q11/100),H11="cancelled",-(O11*P11*(1-Q11/100)),H11="seats_change",(J11-I11)*P11*(1-Q11/100),H11="price_change",(J11-I11)*O11*(1-Q11/100),H11="discount_added",-(O11*P11*(J11-I11)/100),H11="plan_upgrade",O11*(_xlfn.XLOOKUP(J11,$M:$M,$P:$P)-_xlfn.XLOOKUP(I11,$M:$M,$P:$P))*(1-Q11/100),H11="plan_downgrade",O11*(_xlfn.XLOOKUP(J11,$M:$M,$P:$P)-_xlfn.XLOOKUP(I11,$M:$M,$P:$P))*(1-Q11/100)),_xlfn.IFS(H11="created",O11*P11*(1-Q11/100)/12,H11="cancelled",-(O11*P11*(1-Q11/100))/12,H11="seats_change",(J11-I11)*P11*(1-Q11/100)/12,H11="price_change",(J11-I11)*O11*(1-Q11/100)/12,H11="plan_upgrade",(O11*(_xlfn.XLOOKUP(J11,$M:$M,$P:$P)-_xlfn.XLOOKUP(I11,$M:$M,$P:$P))*(1-Q11/100))/12,H11="plan_downgrade",(O11*(_xlfn.XLOOKUP(J11,$M:$M,$P:$P)-_xlfn.XLOOKUP(I11,$M:$M,$P:$P))*(1-Q11/100))/12,H11="discount_added",-(O11*P11*(J11-I11)/100)/12))} -> 2090 | T11: =IF(H11<>"created",0,IF(COUNTIFS($C$1:C10,$C11,$H$1:H10,"created")=0,1,0)) -> 1 | U11: =IF(H11<>"cancelled",0,IF(COUNTIFS($C$2:$C$98,$C11,$H$2:$H$98,"created",$F$2:$F$98,"<="&F11)-COUNTIFS($C$2:$C$98,$C11,$H$2:$H$98,"cancelled",$F$2:$F$98,"<="&F11)=0,1,0)) -> 0 | V11: =IF(AND(H11="created",T11=0,COUNTIFS($C$2:$C$98,$C11,$H$2:$H$98,"cancelled",$F$2:$F$98,"<"&F11)>0,COUNTIFS($C$2:$C$98,$C11,$H$2:$H$98,"created",$F$2:$F$98,"<"&F11)-COUNTIFS($C$2:$C$98,$C11,$H$2:$H$98,"cancelled",$F$2:$F$98,"<"&F11)=0),1,0) -> 0
A12: EVT011 | B12: SUB009 | C12: CUST009 | D12: West Coast Logistics | E12: Western Canada | F12: 45383 | G12: 45411 | H12: created | M12: Platform Suite | N12: Annual | O12: 36 | P12: 1800 | Q12: 0 | R12: {=_xlfn.IFS(H12="created", "New", H12="cancelled", "Churned", AND(H12="seats_change", J12 > I12), "Expansion", AND(H12="seats_change", J12 < I12), "Contraction", AND(H12="price_change", J12 > I12), "Expansion", AND(H12="price_change", J12 < I12), "Contraction", H12="plan_upgrade", "Expansion", H12="plan_downgrade", "Contraction", H12="discount_added", "Contraction")} -> New | S12: {=IF(N12="Monthly",_xlfn.IFS(H12="created",O12*P12*(1-Q12/100),H12="cancelled",-(O12*P12*(1-Q12/100)),H12="seats_change",(J12-I12)*P12*(1-Q12/100),H12="price_change",(J12-I12)*O12*(1-Q12/100),H12="discount_added",-(O12*P12*(J12-I12)/100),H12="plan_upgrade",O12*(_xlfn.XLOOKUP(J12,$M:$M,$P:$P)-_xlfn.XLOOKUP(I12,$M:$M,$P:$P))*(1-Q12/100),H12="plan_downgrade",O12*(_xlfn.XLOOKUP(J12,$M:$M,$P:$P)-_xlfn.XLOOKUP(I12,$M:$M,$P:$P))*(1-Q12/100)),_xlfn.IFS(H12="created",O12*P12*(1-Q12/100)/12,H12="cancelled",-(O12*P12*(1-Q12/100))/12,H12="seats_change",(J12-I12)*P12*(1-Q12/100)/12,H12="price_change",(J12-I12)*O12*(1-Q12/100)/12,H12="plan_upgrade",(O12*(_xlfn.XLOOKUP(J12,$M:$M,$P:$P)-_xlfn.XLOOKUP(I12,$M:$M,$P:$P))*(1-Q12/100))/12,H12="plan_downgrade",(O12*(_xlfn.XLOOKUP(J12,$M:$M,$P:$P)-_xlfn.XLOOKUP(I12,$M:$M,$P:$P))*(1-Q12/100))/12,H12="discount_added",-(O12*P12*(J12-I12)/100)/12))} -> 5400 | T12: =IF(H12<>"created",0,IF(COUNTIFS($C$1:C11,$C12,$H$1:H11,"created")=0,1,0)) -> 1 | U12: =IF(H12<>"cancelled",0,IF(COUNTIFS($C$2:$C$98,$C12,$H$2:$H$98,"created",$F$2:$F$98,"<="&F12)-COUNTIFS($C$2:$C$98,$C12,$H$2:$H$98,"cancelled",$F$2:$F$98,"<="&F12)=0,1,0)) -> 0 | V12: =IF(AND(H12="created",T12=0,COUNTIFS($C$2:$C$98,$C12,$H$2:$H$98,"cancelled",$F$2:$F$98,"<"&F12)>0,COUNTIFS($C$2:$C$98,$C12,$H$2:$H$98,"created",$F$2:$F$98,"<"&F12)-COUNTIFS($C$2:$C$98,$C12,$H$2:$H$98,"cancelled",$F$2:$F$98,"<"&F12)=0),1,0) -> 0
A13: EVT012 | B13: SUB010 | C13: CUST010 | D13: Montreal Finance Hub | E13: Eastern Canada | F13: 45413 | G13: 45425 | H13: created | M13: Analytics Starter | N13: Monthly | O13: 13 | P13: 45 | Q13: 0 | R13: {=_xlfn.IFS(H13="created", "New", H13="cancelled", "Churned", AND(H13="seats_change", J13 > I13), "Expansion", AND(H13="seats_change", J13 < I13), "Contraction", AND(H13="price_change", J13 > I13), "Expansion", AND(H13="price_change", J13 < I13), "Contraction", H13="plan_upgrade", "Expansion", H13="plan_downgrade", "Contraction", H13="discount_added", "Contraction")} -> New | S13: {=IF(N13="Monthly",_xlfn.IFS(H13="created",O13*P13*(1-Q13/100),H13="cancelled",-(O13*P13*(1-Q13/100)),H13="seats_change",(J13-I13)*P13*(1-Q13/100),H13="price_change",(J13-I13)*O13*(1-Q13/100),H13="discount_added",-(O13*P13*(J13-I13)/100),H13="plan_upgrade",O13*(_xlfn.XLOOKUP(J13,$M:$M,$P:$P)-_xlfn.XLOOKUP(I13,$M:$M,$P:$P))*(1-Q13/100),H13="plan_downgrade",O13*(_xlfn.XLOOKUP(J13,$M:$M,$P:$P)-_xlfn.XLOOKUP(I13,$M:$M,$P:$P))*(1-Q13/100)),_xlfn.IFS(H13="created",O13*P13*(1-Q13/100)/12,H13="cancelled",-(O13*P13*(1-Q13/100))/12,H13="seats_change",(J13-I13)*P13*(1-Q13/100)/12,H13="price_change",(J13-I13)*O13*(1-Q13/100)/12,H13="plan_upgrade",(O13*(_xlfn.XLOOKUP(J13,$M:$M,$P:$P)-_xlfn.XLOOKUP(I13,$M:$M,$P:$P))*(1-Q13/100))/12,H13="plan_downgrade",(O13*(_xlfn.XLOOKUP(J13,$M:$M,$P:$P)-_xlfn.XLOOKUP(I13,$M:$M,$P:$P))*(1-Q13/100))/12,H13="discount_added",-(O13*P13*(J13-I13)/100)/12))} -> 585 | T13: =IF(H13<>"created",0,IF(COUNTIFS($C$1:C12,$C13,$H$1:H12,"created")=0,1,0)) -> 1 | U13: =IF(H13<>"cancelled",0,IF(COUNTIFS($C$2:$C$98,$C13,$H$2:$H$98,"created",$F$2:$F$98,"<="&F13)-COUNTIFS($C$2:$C$98,$C13,$H$2:$H$98,"cancelled",$F$2:$F$98,"<="&F13)=0,1,0)) -> 0 | V13: =IF(AND(H13="created",T13=0,COUNTIFS($C$2:$C$98,$C13,$H$2:$H$98,"cancelled",$F$2:$F$98,"<"&F13)>0,COUNTIFS($C$2:$C$98,$C13,$H$2:$H$98,"created",$F$2:$F$98,"<"&F13)-COUNTIFS($C$2:$C$98,$C13,$H$2:$H$98,"cancelled",$F$2:$F$98,"<"&F13)=0),1,0) -> 0
... A23: EVT022 | B23: SUB017 | C23: CUST017 | D23: Capital Education Tech | E23: Eastern Canada | F23: 45505 | G23: 45523 | H23: created | M23: Analytics Starter | N23: Monthly | O23: 12 | P23: 45 | Q23: 0 | R23: {=_xlfn.IFS(H23="created", "New", H23="cancelled", "Churned", AND(H23="seats_change", J23 > I23), "Expansion", AND(H23="seats_change", J23 < I23), "Contraction", AND(H23="price_change", J23 > I23), "Expansion", AND(H23="price_change", J23 < I23), "Contraction", H23="plan_upgrade", "Expansion", H23="plan_downgrade", "Contraction", H23="discount_added", "Contraction")} -> New | S23: {=IF(N23="Monthly",_xlfn.IFS(H23="created",O23*P23*(1-Q23/100),H23="cancelled",-(O23*P23*(1-Q23/100)),H23="seats_change",(J23-I23)*P23*(1-Q23/100),H23="price_change",(J23-I23)*O23*(1-Q23/100),H23="discount_added",-(O23*P23*(J23-I23)/100),H23="plan_upgrade",O23*(_xlfn.XLOOKUP(J23,$M:$M,$P:$P)-_xlfn.XLOOKUP(I23,$M:$M,$P:$P))*(1-Q23/100),H23="plan_downgrade",O23*(_xlfn.XLOOKUP(J23,$M:$M,$P:$P)-_xlfn.XLOOKUP(I23,$M:$M,$P:$P))*(1-Q23/100)),_xlfn.IFS(H23="created",O23*P23*(1-Q23/100)/12,H23="cancelled",-(O23*P23*(1-Q23/100))/12,H23="seats_change",(J23-I23)*P23*(1-Q23/100)/12,H23="price_change",(J23-I23)*O23*(1-Q23/100)/12,H23="plan_upgrade",(O23*(_xlfn.XLOOKUP(J23,$M:$M,$P:$P)-_xlfn.XLOOKUP(I23,$M:$M,$P:$P))*(1-Q23/100))/12,H23="plan_downgrade",(O23*(_xlfn.XLOOKUP(J23,$M:$M,$P:$P)-_xlfn.XLOOKUP(I23,$M:$M,$P:$P))*(1-Q23/100))/12,H23="discount_added",-(O23*P23*(J23-I23)/100)/12))} -> 540 | T23: =IF(H23<>"created",0,IF(COUNTIFS($C$1:C22,$C23,$H$1:H22,"created")=0,1,0)) -> 1 | U23: =IF(H23<>"cancelled",0,IF(COUNTIFS($C$2:$C$98,$C23,$H$2:$H$98,"created",$F$2:$F$98,"<="&F23)-COUNTIFS($C$2:$C$98,$C23,$H$2:$H$98,"cancelled",$F$2:$F$98,"<="&F23)=0,1,0)) -> 0 | V23: =IF(AND(H23="created",T23=0,COUNTIFS($C$2:$C$98,$C23,$H$2:$H$98,"cancelled",$F$2:$F$98,"<"&F23)>0,COUNTIFS($C$2:$C$98,$C23,$H$2:$H$98,"created",$F$2:$F$98,"<"&F23)-COUNTIFS($C$2:$C$98,$C23,$H$2:$H$98,"cancelled",$F$2:$F$98,"<"&F23)=0),1,0) -> 0
A24: EVT023 | B24: SUB001 | C24: CUST001 | D24: TechVision Solutions | E24: Eastern Canada | F24: 45505 | G24: 45531 | H24: cancelled | I24: active | J24: churned | K24: status | L24: Missing features | M24: Analytics Growth | N24: Monthly | O24: 20 | P24: 95 | Q24: 0 | R24: {=_xlfn.IFS(H24="created", "New", H24="cancelled", "Churned", AND(H24="seats_change", J24 > I24), "Expansion", AND(H24="seats_change", J24 < I24), "Contraction", AND(H24="price_change", J24 > I24), "Expansion", AND(H24="price_change", J24 < I24), "Contraction", H24="plan_upgrade", "Expansion", H24="plan_downgrade", "Contraction", H24="discount_added", "Contraction")} -> Churned | S24: {=IF(N24="Monthly",_xlfn.IFS(H24="created",O24*P24*(1-Q24/100),H24="cancelled",-(O24*P24*(1-Q24/100)),H24="seats_change",(J24-I24)*P24*(1-Q24/100),H24="price_change",(J24-I24)*O24*(1-Q24/100),H24="discount_added",-(O24*P24*(J24-I24)/100),H24="plan_upgrade",O24*(_xlfn.XLOOKUP(J24,$M:$M,$P:$P)-_xlfn.XLOOKUP(I24,$M:$M,$P:$P))*(1-Q24/100),H24="plan_downgrade",O24*(_xlfn.XLOOKUP(J24,$M:$M,$P:$P)-_xlfn.XLOOKUP(I24,$M:$M,$P:$P))*(1-Q24/100)),_xlfn.IFS(H24="created",O24*P24*(1-Q24/100)/12,H24="cancelled",-(O24*P24*(1-Q24/100))/12,H24="seats_change",(J24-I24)*P24*(1-Q24/100)/12,H24="price_change",(J24-I24)*O24*(1-Q24/100)/12,H24="plan_upgrade",(O24*(_xlfn.XLOOKUP(J24,$M:$M,$P:$P)-_xlfn.XLOOKUP(I24,$M:$M,$P:$P))*(1-Q24/100))/12,H24="plan_downgrade",(O24*(_xlfn.XLOOKUP(J24,$M:$M,$P:$P)-_xlfn.XLOOKUP(I24,$M:$M,$P:$P))*(1-Q24/100))/12,H24="discount_added",-(O24*P24*(J24-I24)/100)/12))} -> -1900 | T24: =IF(H24<>"created",0,IF(COUNTIFS($C$1:C23,$C24,$H$1:H23,"created")=0,1,0)) -> 0 | U24: =IF(H24<>"cancelled",0,IF(COUNTIFS($C$2:$C$98,$C24,$H$2:$H$98,"created",$F$2:$F$98,"<="&F24)-COUNTIFS($C$2:$C$98,$C24,$H$2:$H$98,"cancelled",$F$2:$F$98,"<="&F24)=0,1,0)) -> 0 | V24: =IF(AND(H24="created",T24=0,COUNTIFS($C$2:$C$98,$C24,$H$2:$H$98,"cancelled",$F$2:$F$98,"<"&F24)>0,COUNTIFS($C$2:$C$98,$C24,$H$2:$H$98,"created",$F$2:$F$98,"<"&F24)-COUNTIFS($C$2:$C$98,$C24,$H$2:$H$98,"cancelled",$F$2:$F$98,"<"&F24)=0),1,0) -> 0
A25: EVT024 | B25: SUB018 | C25: CUST018 | D25: Vancouver FinTech Labs | E25: Western Canada | F25: 45536 | G25: 45537 | H25: created | M25: Analytics Enterprise | N25: Monthly | O25: 35 | P25: 180 | Q25: 0 | R25: {=_xlfn.IFS(H25="created", "New", H25="cancelled", "Churned", AND(H25="seats_change", J25 > I25), "Expansion", AND(H25="seats_change", J25 < I25), "Contraction", AND(H25="price_change", J25 > I25), "Expansion", AND(H25="price_change", J25 < I25), "Contraction", H25="plan_upgrade", "Expansion", H25="plan_downgrade", "Contraction", H25="discount_added", "Contraction")} -> New | S25: {=IF(N25="Monthly",_xlfn.IFS(H25="created",O25*P25*(1-Q25/100),H25="cancelled",-(O25*P25*(1-Q25/100)),H25="seats_change",(J25-I25)*P25*(1-Q25/100),H25="price_change",(J25-I25)*O25*(1-Q25/100),H25="discount_added",-(O25*P25*(J25-I25)/100),H25="plan_upgrade",O25*(_xlfn.XLOOKUP(J25,$M:$M,$P:$P)-_xlfn.XLOOKUP(I25,$M:$M,$P:$P))*(1-Q25/100),H25="plan_downgrade",O25*(_xlfn.XLOOKUP(J25,$M:$M,$P:$P)-_xlfn.XLOOKUP(I25,$M:$M,$P:$P))*(1-Q25/100)),_xlfn.IFS(H25="created",O25*P25*(1-Q25/100)/12,H25="cancelled",-(O25*P25*(1-Q25/100))/12,H25="seats_change",(J25-I25)*P25*(1-Q25/100)/12,H25="price_change",(J25-I25)*O25*(1-Q25/100)/12,H25="plan_upgrade",(O25*(_xlfn.XLOOKUP(J25,$M:$M,$P:$P)-_xlfn.XLOOKUP(I25,$M:$M,$P:$P))*(1-Q25/100))/12,H25="plan_downgrade",(O25*(_xlfn.XLOOKUP(J25,$M:$M,$P:$P)-_xlfn.XLOOKUP(I25,$M:$M,$P:$P))*(1-Q25/100))/12,H25="discount_added",-(O25*P25*(J25-I25)/100)/12))} -> 6300 | T25: =IF(H25<>"created",0,IF(COUNTIFS($C$1:C24,$C25,$H$1:H24,"created")=0,1,0)) -> 1 | U25: =IF(H25<>"cancelled",0,IF(COUNTIFS($C$2:$C$98,$C25,$H$2:$H$98,"created",$F$2:$F$98,"<="&F25)-COUNTIFS($C$2:$C$98,$C25,$H$2:$H$98,"cancelled",$F$2:$F$98,"<="&F25)=0,1,0)) -> 0 | V25: =IF(AND(H25="created",T25=0,COUNTIFS($C$2:$C$98,$C25,$H$2:$H$98,"cancelled",$F$2:$F$98,"<"&F25)>0,COUNTIFS($C$2:$C$98,$C25,$H$2:$H$98,"created",$F$2:$F$98,"<"&F25)-COUNTIFS($C$2:$C$98,$C25,$H$2:$H$98,"cancelled",$F$2:$F$98,"<"&F25)=0),1,0) -> 0
A26: EVT025 | B26: SUB042 | C26: CUST003 | D26: Maple Healthcare Systems | E26: Eastern Canada | F26: 45536 | G26: 45545 | H26: created | M26: Sales Hub | N26: Monthly | O26: 19 | P26: 110 | Q26: 0 | R26: {=_xlfn.IFS(H26="created", "New", H26="cancelled", "Churned", AND(H26="seats_change", J26 > I26), "Expansion", AND(H26="seats_change", J26 < I26), "Contraction", AND(H26="price_change", J26 > I26), "Expansion", AND(H26="price_change", J26 < I26), "Contraction", H26="plan_upgrade", "Expansion", H26="plan_downgrade", "Contraction", H26="discount_added", "Contraction")} -> New | S26: {=IF(N26="Monthly",_xlfn.IFS(H26="created",O26*P26*(1-Q26/100),H26="cancelled",-(O26*P26*(1-Q26/100)),H26="seats_change",(J26-I26)*P26*(1-Q26/100),H26="price_change",(J26-I26)*O26*(1-Q26/100),H26="discount_added",-(O26*P26*(J26-I26)/100),H26="plan_upgrade",O26*(_xlfn.XLOOKUP(J26,$M:$M,$P:$P)-_xlfn.XLOOKUP(I26,$M:$M,$P:$P))*(1-Q26/100),H26="plan_downgrade",O26*(_xlfn.XLOOKUP(J26,$M:$M,$P:$P)-_xlfn.XLOOKUP(I26,$M:$M,$P:$P))*(1-Q26/100)),_xlfn.IFS(H26="created",O26*P26*(1-Q26/100)/12,H26="cancelled",-(O26*P26*(1-Q26/100))/12,H26="seats_change",(J26-I26)*P26*(1-Q26/100)/12,H26="price_change",(J26-I26)*O26*(1-Q26/100)/12,H26="plan_upgrade",(O26*(_xlfn.XLOOKUP(J26,$M:$M,$P:$P)-_xlfn.XLOOKUP(I26,$M:$M,$P:$P))*(1-Q26/100))/12,H26="plan_downgrade",(O26*(_xlfn.XLOOKUP(J26,$M:$M,$P:$P)-_xlfn.XLOOKUP(I26,$M:$M,$P:$P))*(1-Q26/100))/12,H26="discount_added",-(O26*P26*(J26-I26)/100)/12))} -> 2090 | T26: =IF(H26<>"created",0,IF(COUNTIFS($C$1:C25,$C26,$H$1:H25,"created")=0,1,0)) -> 0 | U26: =IF(H26<>"cancelled",0,IF(COUNTIFS($C$2:$C$98,$C26,$H$2:$H$98,"created",$F$2:$F$98,"<="&F26)-COUNTIFS($C$2:$C$98,$C26,$H$2:$H$98,"cancelled",$F$2:$F$98,"<="&F26)=0,1,0)) -> 0 | V26: =IF(AND(H26="created",T26=0,COUNTIFS($C$2:$C$98,$C26,$H$2:$H$98,"cancelled",$F$2:$F$98,"<"&F26)>0,COUNTIFS($C$2:$C$98,$C26,$H$2:$H$98,"created",$F$2:$F$98,"<"&F26)-COUNTIFS($C$2:$C$98,$C26,$H$2:$H$98,"cancelled",$F$2:$F$98,"<"&F26)=0),1,0) -> 0
A27: EVT026 | B27: SUB019 | C27: CUST019 | D27: Central Healthcare Partners | E27: Central Canada | F27: 45536 | G27: 45551 | H27: created | M27: Marketing Pro | N27: Monthly | O27: 19 | P27: 85 | Q27: 0 | R27: {=_xlfn.IFS(H27="created", "New", H27="cancelled", "Churned", AND(H27="seats_change", J27 > I27), "Expansion", AND(H27="seats_change", J27 < I27), "Contraction", AND(H27="price_change", J27 > I27), "Expansion", AND(H27="price_change", J27 < I27), "Contraction", H27="plan_upgrade", "Expansion", H27="plan_downgrade", "Contraction", H27="discount_added", "Contraction")} -> New | S27: {=IF(N27="Monthly",_xlfn.IFS(H27="created",O27*P27*(1-Q27/100),H27="cancelled",-(O27*P27*(1-Q27/100)),H27="seats_change",(J27-I27)*P27*(1-Q27/100),H27="price_change",(J27-I27)*O27*(1-Q27/100),H27="discount_added",-(O27*P27*(J27-I27)/100),H27="plan_upgrade",O27*(_xlfn.XLOOKUP(J27,$M:$M,$P:$P)-_xlfn.XLOOKUP(I27,$M:$M,$P:$P))*(1-Q27/100),H27="plan_downgrade",O27*(_xlfn.XLOOKUP(J27,$M:$M,$P:$P)-_xlfn.XLOOKUP(I27,$M:$M,$P:$P))*(1-Q27/100)),_xlfn.IFS(H27="created",O27*P27*(1-Q27/100)/12,H27="cancelled",-(O27*P27*(1-Q27/100))/12,H27="seats_change",(J27-I27)*P27*(1-Q27/100)/12,H27="price_change",(J27-I27)*O27*(1-Q27/100)/12,H27="plan_upgrade",(O27*(_xlfn.XLOOKUP(J27,$M:$M,$P:$P)-_xlfn.XLOOKUP(I27,$M:$M,$P:$P))*(1-Q27/100))/12,H27="plan_downgrade",(O27*(_xlfn.XLOOKUP(J27,$M:$M,$P:$P)-_xlfn.XLOOKUP(I27,$M:$M,$P:$P))*(1-Q27/100))/12,H27="discount_added",-(O27*P27*(J27-I27)/100)/12))} -> 1615 | T27: =IF(H27<>"created",0,IF(COUNTIFS($C$1:C26,$C27,$H$1:H26,"created")=0,1,0)) -> 1 | U27: =IF(H27<>"cancelled",0,IF(COUNTIFS($C$2:$C$98,$C27,$H$2:$H$98,"created",$F$2:$F$98,"<="&F27)-COUNTIFS($C$2:$C$98,$C27,$H$2:$H$98,"cancelled",$F$2:$F$98,"<="&F27)=0,1,0)) -> 0 | V27: =IF(AND(H27="created",T27=0,COUNTIFS($C$2:$C$98,$C27,$H$2:$H$98,"cancelled",$F$2:$F$98,"<"&F27)>0,COUNTIFS($C$2:$C$98,$C27,$H$2:$H$98,"created",$F$2:$F$98,"<"&F27)-COUNTIFS($C$2:$C$98,$C27,$H$2:$H$98,"cancelled",$F$2:$F$98,"<"&F27)=0),1,0) -> 0
A28: EVT027 | B28: SUB060 | C28: CUST019 | D28: Central Healthcare Partners | E28: Central Canada | F28: 45536 | G28: 45551 | H28: created | M28: Sales Hub | N28: Monthly | O28: 16 | P28: 110 | Q28: 0 | R28: {=_xlfn.IFS(H28="created", "New", H28="cancelled", "Churned", AND(H28="seats_change", J28 > I28), "Expansion", AND(H28="seats_change", J28 < I28), "Contraction", AND(H28="price_change", J28 > I28), "Expansion", AND(H28="price_change", J28 < I28), "Contraction", H28="plan_upgrade", "Expansion", H28="plan_downgrade", "Contraction", H28="discount_added", "Contraction")} -> New | S28: {=IF(N28="Monthly",_xlfn.IFS(H28="created",O28*P28*(1-Q28/100),H28="cancelled",-(O28*P28*(1-Q28/100)),H28="seats_change",(J28-I28)*P28*(1-Q28/100),H28="price_change",(J28-I28)*O28*(1-Q28/100),H28="discount_added",-(O28*P28*(J28-I28)/100),H28="plan_upgrade",O28*(_xlfn.XLOOKUP(J28,$M:$M,$P:$P)-_xlfn.XLOOKUP(I28,$M:$M,$P:$P))*(1-Q28/100),H28="plan_downgrade",O28*(_xlfn.XLOOKUP(J28,$M:$M,$P:$P)-_xlfn.XLOOKUP(I28,$M:$M,$P:$P))*(1-Q28/100)),_xlfn.IFS(H28="created",O28*P28*(1-Q28/100)/12,H28="cancelled",-(O28*P28*(1-Q28/100))/12,H28="seats_change",(J28-I28)*P28*(1-Q28/100)/12,H28="price_change",(J28-I28)*O28*(1-Q28/100)/12,H28="plan_upgrade",(O28*(_xlfn.XLOOKUP(J28,$M:$M,$P:$P)-_xlfn.XLOOKUP(I28,$M:$M,$P:$P))*(1-Q28/100))/12,H28="plan_downgrade",(O28*(_xlfn.XLOOKUP(J28,$M:$M,$P:$P)-_xlfn.XLOOKUP(I28,$M:$M,$P:$P))*(1-Q28/100))/12,H28="discount_added",-(O28*P28*(J28-I28)/100)/12))} -> 1760 | T28: =IF(H28<>"created",0,IF(COUNTIFS($C$1:C27,$C28,$H$1:H27,"created")=0,1,0)) -> 0 | U28: =IF(H28<>"cancelled",0,IF(COUNTIFS($C$2:$C$98,$C28,$H$2:$H$98,"created",$F$2:$F$98,"<="&F28)-COUNTIFS($C$2:$C$98,$C28,$H$2:$H$98,"cancelled",$F$2:$F$98,"<="&F28)=0,1,0)) -> 0 | V28: =IF(AND(H28="created",T28=0,COUNTIFS($C$2:$C$98,$C28,$H$2:$H$98,"cancelled",$F$2:$F$98,"<"&F28)>0,COUNTIFS($C$2:$C$98,$C28,$H$2:$H$98,"created",$F$2:$F$98,"<"&F28)-COUNTIFS($C$2:$C$98,$C28,$H$2:$H$98,"cancelled",$F$2:$F$98,"<"&F28)=0),1,0) -> 0
A29: EVT028 | B29: SUB020 | C29: CUST020 | D29: Atlantic SaaS Systems | E29: Eastern Canada | F29: 45536 | G29: 45565 | H29: created | M29: Sales Hub | N29: Monthly | O29: 15 | P29: 110 | Q29: 0 | R29: {=_xlfn.IFS(H29="created", "New", H29="cancelled", "Churned", AND(H29="seats_change", J29 > I29), "Expansion", AND(H29="seats_change", J29 < I29), "Contraction", AND(H29="price_change", J29 > I29), "Expansion", AND(H29="price_change", J29 < I29), "Contraction", H29="plan_upgrade", "Expansion", H29="plan_downgrade", "Contraction", H29="discount_added", "Contraction")} -> New | S29: {=IF(N29="Monthly",_xlfn.IFS(H29="created",O29*P29*(1-Q29/100),H29="cancelled",-(O29*P29*(1-Q29/100)),H29="seats_change",(J29-I29)*P29*(1-Q29/100),H29="price_change",(J29-I29)*O29*(1-Q29/100),H29="discount_added",-(O29*P29*(J29-I29)/100),H29="plan_upgrade",O29*(_xlfn.XLOOKUP(J29,$M:$M,$P:$P)-_xlfn.XLOOKUP(I29,$M:$M,$P:$P))*(1-Q29/100),H29="plan_downgrade",O29*(_xlfn.XLOOKUP(J29,$M:$M,$P:$P)-_xlfn.XLOOKUP(I29,$M:$M,$P:$P))*(1-Q29/100)),_xlfn.IFS(H29="created",O29*P29*(1-Q29/100)/12,H29="cancelled",-(O29*P29*(1-Q29/100))/12,H29="seats_change",(J29-I29)*P29*(1-Q29/100)/12,H29="price_change",(J29-I29)*O29*(1-Q29/100)/12,H29="plan_upgrade",(O29*(_xlfn.XLOOKUP(J29,$M:$M,$P:$P)-_xlfn.XLOOKUP(I29,$M:$M,$P:$P))*(1-Q29/100))/12,H29="plan_downgrade",(O29*(_xlfn.XLOOKUP(J29,$M:$M,$P:$P)-_xlfn.XLOOKUP(I29,$M:$M,$P:$P))*(1-Q29/100))/12,H29="discount_added",-(O29*P29*(J29-I29)/100)/12))} -> 1650 | T29: =IF(H29<>"created",0,IF(COUNTIFS($C$1:C28,$C29,$H$1:H28,"created")=0,1,0)) -> 1 | U29: =IF(H29<>"cancelled",0,IF(COUNTIFS($C$2:$C$98,$C29,$H$2:$H$98,"created",$F$2:$F$98,"<="&F29)-COUNTIFS($C$2:$C$98,$C29,$H$2:$H$98,"cancelled",$F$2:$F$98,"<="&F29)=0,1,0)) -> 0 | V29: =IF(AND(H29="created",T29=0,COUNTIFS($C$2:$C$98,$C29,$H$2:$H$98,"cancelled",$F$2:$F$98,"<"&F29)>0,COUNTIFS($C$2:$C$98,$C29,$H$2:$H$98,"created",$F$2:$F$98,"<"&F29)-COUNTIFS($C$2:$C$98,$C29,$H$2:$H$98,"cancelled",$F$2:$F$98,"<"&F29)=0),1,0) -> 0
A30: EVT029 | B30: SUB043 | C30: CUST006 | D30: Northern Retail Solutions | E30: Western Canada | F30: 45566 | G30: 45570 | H30: created | M30: Marketing Pro | N30: Monthly | O30: 33 | P30: 85 | Q30: 0 | R30: {=_xlfn.IFS(H30="created", "New", H30="cancelled", "Churned", AND(H30="seats_change", J30 > I30), "Expansion", AND(H30="seats_change", J30 < I30), "Contraction", AND(H30="price_change", J30 > I30), "Expansion", AND(H30="price_change", J30 < I30), "Contraction", H30="plan_upgrade", "Expansion", H30="plan_downgrade", "Contraction", H30="discount_added", "Contraction")} -> New | S30: {=IF(N30="Monthly",_xlfn.IFS(H30="created",O30*P30*(1-Q30/100),H30="cancelled",-(O30*P30*(1-Q30/100)),H30="seats_change",(J30-I30)*P30*(1-Q30/100),H30="price_change",(J30-I30)*O30*(1-Q30/100),H30="discount_added",-(O30*P30*(J30-I30)/100),H30="plan_upgrade",O30*(_xlfn.XLOOKUP(J30,$M:$M,$P:$P)-_xlfn.XLOOKUP(I30,$M:$M,$P:$P))*(1-Q30/100),H30="plan_downgrade",O30*(_xlfn.XLOOKUP(J30,$M:$M,$P:$P)-_xlfn.XLOOKUP(I30,$M:$M,$P:$P))*(1-Q30/100)),_xlfn.IFS(H30="created",O30*P30*(1-Q30/100)/12,H30="cancelled",-(O30*P30*(1-Q30/100))/12,H30="seats_change",(J30-I30)*P30*(1-Q30/100)/12,H30="price_change",(J30-I30)*O30*(1-Q30/100)/12,H30="plan_upgrade",(O30*(_xlfn.XLOOKUP(J30,$M:$M,$P:$P)-_xlfn.XLOOKUP(I30,$M:$M,$P:$P))*(1-Q30/100))/12,H30="plan_downgrade",(O30*(_xlfn.XLOOKUP(J30,$M:$M,$P:$P)-_xlfn.XLOOKUP(I30,$M:$M,$P:$P))*(1-Q30/100))/12,H30="discount_added",-(O30*P30*(J30-I30)/100)/12))} -> 2805 | T30: =IF(H30<>"created",0,IF(COUNTIFS($C$1:C29,$C30,$H$1:H29,"created")=0,1,0)) -> 0 | U30: =IF(H30<>"cancelled",0,IF(COUNTIFS($C$2:$C$98,$C30,$H$2:$H$98,"created",$F$2:$F$98,"<="&F30)-COUNTIFS($C$2:$C$98,$C30,$H$2:$H$98,"cancelled",$F$2:$F$98,"<="&F30)=0,1,0)) -> 0 | V30: =IF(AND(H30="created",T30=0,COUNTIFS($C$2:$C$98,$C30,$H$2:$H$98,"cancelled",$F$2:$F$98,"<"&F30)>0,COUNTIFS($C$2:$C$98,$C30,$H$2:$H$98,"created",$F$2:$F$98,"<"&F30)-COUNTIFS($C$2:$C$98,$C30,$H$2:$H$98,"cancelled",$F$2:$F$98,"<"&F30)=0),1,0) -> 0
A31: EVT030 | B31: SUB021 | C31: CUST021 | D31: Calgary Commerce Solutions | E31: Western Canada | F31: 45566 | G31: 45579 | H31: created | M31: Analytics Growth | N31: Monthly | O31: 25 | P31: 95 | Q31: 0 | R31: {=_xlfn.IFS(H31="created", "New", H31="cancelled", "Churned", AND(H31="seats_change", J31 > I31), "Expansion", AND(H31="seats_change", J31 < I31), "Contraction", AND(H31="price_change", J31 > I31), "Expansion", AND(H31="price_change", J31 < I31), "Contraction", H31="plan_upgrade", "Expansion", H31="plan_downgrade", "Contraction", H31="discount_added", "Contraction")} -> New | S31: {=IF(N31="Monthly",_xlfn.IFS(H31="created",O31*P31*(1-Q31/100),H31="cancelled",-(O31*P31*(1-Q31/100)),H31="seats_change",(J31-I31)*P31*(1-Q31/100),H31="price_change",(J31-I31)*O31*(1-Q31/100),H31="discount_added",-(O31*P31*(J31-I31)/100),H31="plan_upgrade",O31*(_xlfn.XLOOKUP(J31,$M:$M,$P:$P)-_xlfn.XLOOKUP(I31,$M:$M,$P:$P))*(1-Q31/100),H31="plan_downgrade",O31*(_xlfn.XLOOKUP(J31,$M:$M,$P:$P)-_xlfn.XLOOKUP(I31,$M:$M,$P:$P))*(1-Q31/100)),_xlfn.IFS(H31="created",O31*P31*(1-Q31/100)/12,H31="cancelled",-(O31*P31*(1-Q31/100))/12,H31="seats_change",(J31-I31)*P31*(1-Q31/100)/12,H31="price_change",(J31-I31)*O31*(1-Q31/100)/12,H31="plan_upgrade",(O31*(_xlfn.XLOOKUP(J31,$M:$M,$P:$P)-_xlfn.XLOOKUP(I31,$M:$M,$P:$P))*(1-Q31/100))/12,H31="plan_downgrade",(O31*(_xlfn.XLOOKUP(J31,$M:$M,$P:$P)-_xlfn.XLOOKUP(I31,$M:$M,$P:$P))*(1-Q31/100))/12,H31="discount_added",-(O31*P31*(J31-I31)/100)/12))} -> 2375 | T31: =IF(H31<>"created",0,IF(COUNTIFS($C$1:C30,$C31,$H$1:H30,"created")=0,1,0)) -> 1 | U31: =IF(H31<>"cancelled",0,IF(COUNTIFS($C$2:$C$98,$C31,$H$2:$H$98,"created",$F$2:$F$98,"<="&F31)-COUNTIFS($C$2:$C$98,$C31,$H$2:$H$98,"cancelled",$F$2:$F$98,"<="&F31)=0,1,0)) -> 0 | V31: =IF(AND(H31="created",T31=0,COUNTIFS($C$2:$C$98,$C31,$H$2:$H$98,"cancelled",$F$2:$F$98,"<"&F31)>0,COUNTIFS($C$2:$C$98,$C31,$H$2:$H$98,"created",$F$2:$F$98,"<"&F31)-COUNTIFS($C$2:$C$98,$C31,$H$2:$H$98,"cancelled",$F$2:$F$98,"<"&F31)=0),1,0) -> 0
A32: EVT031 | B32: SUB022 | C32: CUST022 | D32: Toronto Tech Ventures | E32: Eastern Canada | F32: 45566 | G32: 45593 | H32: created | M32: Platform Suite | N32: Monthly | O32: 33 | P32: 150 | Q32: 0 | R32: {=_xlfn.IFS(H32="created", "New", H32="cancelled", "Churned", AND(H32="seats_change", J32 > I32), "Expansion", AND(H32="seats_change", J32 < I32), "Contraction", AND(H32="price_change", J32 > I32), "Expansion", AND(H32="price_change", J32 < I32), "Contraction", H32="plan_upgrade", "Expansion", H32="plan_downgrade", "Contraction", H32="discount_added", "Contraction")} -> New | S32: {=IF(N32="Monthly",_xlfn.IFS(H32="created",O32*P32*(1-Q32/100),H32="cancelled",-(O32*P32*(1-Q32/100)),H32="seats_change",(J32-I32)*P32*(1-Q32/100),H32="price_change",(J32-I32)*O32*(1-Q32/100),H32="discount_added",-(O32*P32*(J32-I32)/100),H32="plan_upgrade",O32*(_xlfn.XLOOKUP(J32,$M:$M,$P:$P)-_xlfn.XLOOKUP(I32,$M:$M,$P:$P))*(1-Q32/100),H32="plan_downgrade",O32*(_xlfn.XLOOKUP(J32,$M:$M,$P:$P)-_xlfn.XLOOKUP(I32,$M:$M,$P:$P))*(1-Q32/100)),_xlfn.IFS(H32="created",O32*P32*(1-Q32/100)/12,H32="cancelled",-(O32*P32*(1-Q32/100))/12,H32="seats_change",(J32-I32)*P32*(1-Q32/100)/12,H32="price_change",(J32-I32)*O32*(1-Q32/100)/12,H32="plan_upgrade",(O32*(_xlfn.XLOOKUP(J32,$M:$M,$P:$P)-_xlfn.XLOOKUP(I32,$M:$M,$P:$P))*(1-Q32/100))/12,H32="plan_downgrade",(O32*(_xlfn.XLOOKUP(J32,$M:$M,$P:$P)-_xlfn.XLOOKUP(I32,$M:$M,$P:$P))*(1-Q32/100))/12,H32="discount_added",-(O32*P32*(J32-I32)/100)/12))} -> 4950 | T32: =IF(H32<>"created",0,IF(COUNTIFS($C$1:C31,$C32,$H$1:H31,"created")=0,1,0)) -> 1 | U32: =IF(H32<>"cancelled",0,IF(COUNTIFS($C$2:$C$98,$C32,$H$2:$H$98,"created",$F$2:$F$98,"<="&F32)-COUNTIFS($C$2:$C$98,$C32,$H$2:$H$98,"cancelled",$F$2:$F$98,"<="&F32)=0,1,0)) -> 0 | V32: =IF(AND(H32="created",T32=0,COUNTIFS($C$2:$C$98,$C32,$H$2:$H$98,"cancelled",$F$2:$F$98,"<"&F32)>0,COUNTIFS($C$2:$C$98,$C32,$H$2:$H$98,"created",$F$2:$F$98,"<"&F32)-COUNTIFS($C$2:$C$98,$C32,$H$2:$H$98,"cancelled",$F$2:$F$98,"<"&F32)=0),1,0) -> 0
A33: EVT032 | B33: SUB059 | C33: CUST008 | D33: Quantum Education Platform | E33: Eastern Canada | F33: 45597 | G33: 45601 | H33: created | M33: Marketing Pro | N33: Monthly | O33: 22 | P33: 85 | Q33: 0 | R33: {=_xlfn.IFS(H33="created", "New", H33="cancelled", "Churned", AND(H33="seats_change", J33 > I33), "Expansion", AND(H33="seats_change", J33 < I33), "Contraction", AND(H33="price_change", J33 > I33), "Expansion", AND(H33="price_change", J33 < I33), "Contraction", H33="plan_upgrade", "Expansion", H33="plan_downgrade", "Contraction", H33="discount_added", "Contraction")} -> New | S33: {=IF(N33="Monthly",_xlfn.IFS(H33="created",O33*P33*(1-Q33/100),H33="cancelled",-(O33*P33*(1-Q33/100)),H33="seats_change",(J33-I33)*P33*(1-Q33/100),H33="price_change",(J33-I33)*O33*(1-Q33/100),H33="discount_added",-(O33*P33*(J33-I33)/100),H33="plan_upgrade",O33*(_xlfn.XLOOKUP(J33,$M:$M,$P:$P)-_xlfn.XLOOKUP(I33,$M:$M,$P:$P))*(1-Q33/100),H33="plan_downgrade",O33*(_xlfn.XLOOKUP(J33,$M:$M,$P:$P)-_xlfn.XLOOKUP(I33,$M:$M,$P:$P))*(1-Q33/100)),_xlfn.IFS(H33="created",O33*P33*(1-Q33/100)/12,H33="cancelled",-(O33*P33*(1-Q33/100))/12,H33="seats_change",(J33-I33)*P33*(1-Q33/100)/12,H33="price_change",(J33-I33)*O33*(1-Q33/100)/12,H33="plan_upgrade",(O33*(_xlfn.XLOOKUP(J33,$M:$M,$P:$P)-_xlfn.XLOOKUP(I33,$M:$M,$P:$P))*(1-Q33/100))/12,H33="plan_downgrade",(O33*(_xlfn.XLOOKUP(J33,$M:$M,$P:$P)-_xlfn.XLOOKUP(I33,$M:$M,$P:$P))*(1-Q33/100))/12,H33="discount_added",-(O33*P33*(J33-I33)/100)/12))} -> 1870 | T33: =IF(H33<>"created",0,IF(COUNTIFS($C$1:C32,$C33,$H$1:H32,"created")=0,1,0)) -> 0 | U33: =IF(H33<>"cancelled",0,IF(COUNTIFS($C$2:$C$98,$C33,$H$2:$H$98,"created",$F$2:$F$98,"<="&F33)-COUNTIFS($C$2:$C$98,$C33,$H$2:$H$98,"cancelled",$F$2:$F$98,"<="&F33)=0,1,0)) -> 0 | V33: =IF(AND(H33="created",T33=0,COUNTIFS($C$2:$C$98,$C33,$H$2:$H$98,"cancelled",$F$2:$F$98,"<"&F33)>0,COUNTIFS($C$2:$C$98,$C33,$H$2:$H$98,"created",$F$2:$F$98,"<"&F33)-COUNTIFS($C$2:$C$98,$C33,$H$2:$H$98,"cancelled",$F$2:$F$98,"<"&F33)=0),1,0) -> 0
A34: EVT033 | B34: SUB023 | C34: CUST023 | D34: Island Media Productions | E34: Eastern Canada | F34: 45597 | G34: 45607 | H34: created | M34: Analytics Starter | N34: Monthly | O34: 10 | P34: 45 | Q34: 0 | R34: {=_xlfn.IFS(H34="created", "New", H34="cancelled", "Churned", AND(H34="seats_change", J34 > I34), "Expansion", AND(H34="seats_change", J34 < I34), "Contraction", AND(H34="price_change", J34 > I34), "Expansion", AND(H34="price_change", J34 < I34), "Contraction", H34="plan_upgrade", "Expansion", H34="plan_downgrade", "Contraction", H34="discount_added", "Contraction")} -> New | S34: {=IF(N34="Monthly",_xlfn.IFS(H34="created",O34*P34*(1-Q34/100),H34="cancelled",-(O34*P34*(1-Q34/100)),H34="seats_change",(J34-I34)*P34*(1-Q34/100),H34="price_change",(J34-I34)*O34*(1-Q34/100),H34="discount_added",-(O34*P34*(J34-I34)/100),H34="plan_upgrade",O34*(_xlfn.XLOOKUP(J34,$M:$M,$P:$P)-_xlfn.XLOOKUP(I34,$M:$M,$P:$P))*(1-Q34/100),H34="plan_downgrade",O34*(_xlfn.XLOOKUP(J34,$M:$M,$P:$P)-_xlfn.XLOOKUP(I34,$M:$M,$P:$P))*(1-Q34/100)),_xlfn.IFS(H34="created",O34*P34*(1-Q34/100)/12,H34="cancelled",-(O34*P34*(1-Q34/100))/12,H34="seats_change",(J34-I34)*P34*(1-Q34/100)/12,H34="price_change",(J34-I34)*O34*(1-Q34/100)/12,H34="plan_upgrade",(O34*(_xlfn.XLOOKUP(J34,$M:$M,$P:$P)-_xlfn.XLOOKUP(I34,$M:$M,$P:$P))*(1-Q34/100))/12,H34="plan_downgrade",(O34*(_xlfn.XLOOKUP(J34,$M:$M,$P:$P)-_xlfn.XLOOKUP(I34,$M:$M,$P:$P))*(1-Q34/100))/12,H34="discount_added",-(O34*P34*(J34-I34)/100)/12))} -> 450 | T34: =IF(H34<>"created",0,IF(COUNTIFS($C$1:C33,$C34,$H$1:H33,"created")=0,1,0)) -> 1 | U34: =IF(H34<>"cancelled",0,IF(COUNTIFS($C$2:$C$98,$C34,$H$2:$H$98,"created",$F$2:$F$98,"<="&F34)-COUNTIFS($C$2:$C$98,$C34,$H$2:$H$98,"cancelled",$F$2:$F$98,"<="&F34)=0,1,0)) -> 0 | V34: =IF(AND(H34="created",T34=0,COUNTIFS($C$2:$C$98,$C34,$H$2:$H$98,"cancelled",$F$2:$F$98,"<"&F34)>0,COUNTIFS($C$2:$C$98,$C34,$H$2:$H$98,"created",$F$2:$F$98,"<"&F34)-COUNTIFS($C$2:$C$98,$C34,$H$2:$H$98,"cancelled",$F$2:$F$98,"<"&F34)=0),1,0) -> 0
