Workbook

Sheet billing_jan_2026
A1: invoice_id | B1: invoice_number | C1: invoice_date | D1: customer_id | E1: customer_name | F1: subscription_id | G1: plan_name | H1: billing_cycle | I1: period_start | J1: period_end | K1: seats | L1: unit_price_usd | M1: subtotal | N1: discount_pct | O1: discount_amount | P1: amount_due_usd | Q1: status | R1: payment_date | S1: failure_reason
A2: in_20260100001 | B2: INV-2026-01-0001 | C2: 46023 | D2: CUST007 | E2: Ontario Manufacturing Tech | F2: SUB007 | G2: Marketing Pro | H2: Monthly | I2: 46023 | J2: 46053 | K2: 16 | L2: 85 | M2: 1360 | N2: 0 | O2: 0 | P2: 1360 | Q2: paid | R2: 46023
A3: in_20260100002 | B3: INV-2026-01-0002 | C3: 46023 | D3: CUST007 | E3: Ontario Manufacturing Tech | F3: SUB050 | G3: Analytics Starter | H3: Monthly | I3: 46023 | J3: 46053 | K3: 15 | L3: 45 | M3: 675 | N3: 12 | O3: 81 | P3: 594 | Q3: paid | R3: 46023
A4: in_20260100003 | B4: INV-2026-01-0003 | C4: 46024 | D4: CUST018 | E4: Vancouver FinTech Labs | F4: SUB018 | G4: Analytics Enterprise | H4: Monthly | I4: 46024 | J4: 46053 | K4: 35 | L4: 180 | M4: 6300 | N4: 0 | O4: 0 | P4: 6300 | Q4: paid | R4: 46024
A5: in_20260100004 | B5: INV-2026-01-0004 | C5: 46025 | D5: CUST029 | E5: Halifax Healthcare Tech | F5: SUB029 | G5: Marketing Pro | H5: Monthly | I5: 46025 | J5: 46053 | K5: 22 | L5: 85 | M5: 1870 | N5: 0 | O5: 0 | P5: 1870 | Q5: paid | R5: 46025
A6: in_20260100005 | B6: INV-2026-01-0005 | C6: 46027 | D6: CUST003 | E6: Maple Healthcare Systems | F6: SUB003 | G6: Marketing Pro | H6: Monthly | I6: 46027 | J6: 46053 | K6: 23 | L6: 85 | M6: 1955 | N6: 0 | O6: 0 | P6: 1955 | Q6: paid | R6: 46027
A7: in_20260100006 | B7: INV-2026-01-0006 | C7: 46027 | D7: CUST006 | E7: Northern Retail Solutions | F7: SUB043 | G7: Marketing Pro | H7: Monthly | I7: 46027 | J7: 46053 | K7: 33 | L7: 85 | M7: 2805 | N7: 0 | O7: 0 | P7: 2805 | Q7: paid | R7: 46027
A8: in_20260100007 | B8: INV-2026-01-0007 | C8: 46027 | D8: CUST027 | E8: Pacific Finance Corp | F8: SUB053 | G8: Analytics Enterprise | H8: Monthly | I8: 46027 | J8: 46053 | K8: 31 | L8: 180 | M8: 5580 | N8: 0 | O8: 0 | P8: 5580 | Q8: paid | R8: 46027
A9: in_20260100008 | B9: INV-2026-01-0008 | C9: 46027 | D9: CUST008 | E9: Quantum Education Platform | F9: SUB059 | G9: Marketing Pro | H9: Monthly | I9: 46027 | J9: 46053 | K9: 22 | L9: 85 | M9: 1870 | N9: 0 | O9: 0 | P9: 1870 | Q9: paid | R9: 46027
A10: in_20260100009 | B10: INV-2026-01-0009 | C10: 46028 | D10: CUST027 | E10: Pacific Finance Corp | F10: SUB027 | G10: Sales Hub | H10: Monthly | I10: 46028 | J10: 46053 | K10: 28 | L10: 110 | M10: 3080 | N10: 0 | O10: 0 | P10: 3080 | Q10: paid | R10: 46028
A11: in_20260100010 | B11: INV-2026-01-0010 | C11: 46030 | D11: CUST014 | E11: Toronto Media Group | F11: SUB014 | G11: Marketing Pro | H11: Monthly | I11: 46030 | J11: 46053 | K11: 28 | L11: 85 | M11: 2380 | N11: 0 | O11: 0 | P11: 2380 | Q11: paid | R11: 46030
A12: in_20260100011 | B12: INV-2026-01-0011 | C12: 46030 | D12: CUST010 | E12: Montreal Finance Hub | F12: SUB045 | G12: Marketing Pro | H12: Monthly | I12: 46030 | J12: 46053 | K12: 13 | L12: 85 | M12: 1105 | N12: 0 | O12: 0 | P12: 1105 | Q12: paid | R12: 46030
A13: in_20260100012 | B13: INV-2026-01-0012 | C13: 46030 | D13: CUST024 | E13: Western Retail Group | F13: SUB058 | G13: Sales Hub | H13: Monthly | I13: 46030 | J13: 46053 | K13: 26 | L13: 110 | M13: 2860 | N13: 0 | O13: 0 | P13: 2860 | Q13: paid | R13: 46030
... A30: in_20260100029 | B30: INV-2026-01-0029 | C30: 46041 | D30: CUST017 | E30: Capital Education Tech | F30: SUB017 | G30: Analytics Starter | H30: Monthly | I30: 46041 | J30: 46053 | K30: 12 | L30: 45 | M30: 540 | N30: 0 | O30: 0 | P30: 540 | Q30: paid | R30: 46041
A31: in_20260100030 | B31: INV-2026-01-0030 | C31: 46042 | D31: CUST028 | E31: Prairie SaaS Innovations | F31: SUB028 | G31: Analytics Starter | H31: Monthly | I31: 46042 | J31: 46053 | K31: 15 | L31: 45 | M31: 675 | N31: 0 | O31: 0 | P31: 675 | Q31: failed | S31: Insufficient funds
A32: in_20260100031 | B32: INV-2026-01-0031 | C32: 46042 | D32: CUST009 | E32: West Coast Logistics | F32: SUB044 | G32: Analytics Growth | H32: Monthly | I32: 46042 | J32: 46053 | K32: 35 | L32: 95 | M32: 3325 | N32: 0 | O32: 0 | P32: 3325 | Q32: paid | R32: 46042
A33: in_20260100032 | B33: INV-2026-01-0032 | C33: 46042 | D33: CUST013 | E33: Alberta Tech Innovators | F33: SUB061 | G33: Analytics Growth | H33: Monthly | I33: 46042 | J33: 46053 | K33: 12 | L33: 95 | M33: 1140 | N33: 0 | O33: 0 | P33: 1140 | Q33: paid | R33: 46042
A34: in_20260100033 | B34: INV-2026-01-0033 | C34: 46044 | D34: CUST002 | E34: Pacific Analytics Inc | F34: SUB002 | G34: Platform Suite | H34: Annual | I34: 46044 | J34: 46408 | K34: 26 | L34: 1800 | M34: 46800 | N34: 0 | O34: 0 | P34: 46800 | Q34: paid | R34: 46044
A35: in_20260100034 | B35: INV-2026-01-0034 | C35: 46044 | D35: CUST015 | E35: BC Retail Networks | F35: SUB046 | G35: Analytics Enterprise | H35: Monthly | I35: 46044 | J35: 46053 | K35: 20 | L35: 180 | M35: 3600 | N35: 0 | O35: 0 | P35: 3600 | Q35: paid | R35: 46044
A36: in_20260100035 | B36: INV-2026-01-0035 | C36: 46044 | D36: CUST025 | E36: Montreal Manufacturing Pro | F36: SUB048 | G36: Sales Hub | H36: Monthly | I36: 46044 | J36: 46053 | K36: 36 | L36: 110 | M36: 3960 | N36: 0 | O36: 0 | P36: 3960 | Q36: paid | R36: 46044
A37: in_20260100036 | B37: INV-2026-01-0036 | C37: 46044 | D37: CUST002 | E37: Pacific Analytics Inc | F37: SUB054 | G37: Analytics Growth | H37: Annual | I37: 46044 | J37: 46408 | K37: 22 | L37: 1140 | M37: 25080 | N37: 5 | O37: 1254 | P37: 23826 | Q37: paid | R37: 46044
A38: in_20260100037 | B38: INV-2026-01-0037 | C38: 46045 | D38: CUST026 | E38: Ontario Education Connect | F38: SUB026 | G38: Analytics Growth | H38: Monthly | I38: 46045 | J38: 46053 | K38: 16 | L38: 95 | M38: 1520 | N38: 0 | O38: 0 | P38: 1520 | Q38: paid | R38: 46045
A39: in_20260100038 | B39: INV-2026-01-0038 | C39: 46045 | D39: CUST039 | E39: Toronto Commerce Cloud | F39: SUB039 | G39: Marketing Pro | H39: Monthly | I39: 46045 | J39: 46053 | K39: 29 | L39: 85 | M39: 2465 | N39: 0 | O39: 0 | P39: 2465 | Q39: paid | R39: 46045
A40: in_20260100039 | B40: INV-2026-01-0039 | C40: 46047 | D40: CUST024 | E40: Western Retail Group | F40: SUB024 | G40: Marketing Pro | H40: Monthly | I40: 46047 | J40: 46053 | K40: 31 | L40: 85 | M40: 2635 | N40: 0 | O40: 0 | P40: 2635 | Q40: paid | R40: 46047
A41: in_20260100040 | B41: INV-2026-01-0040 | C41: 46048 | D41: CUST037 | E41: Maritime SaaS Ventures | F41: SUB037 | G41: Platform Suite | H41: Monthly | I41: 46048 | J41: 46053 | K41: 35 | L41: 150 | M41: 5250 | N41: 0 | O41: 0 | P41: 5250 | Q41: paid | R41: 46048
A42: in_20260100041 | B42: INV-2026-01-0041 | C42: 46048 | D42: CUST040 | E42: BC Education Innovations | F42: SUB040 | G42: Analytics Growth | H42: Monthly | I42: 46048 | J42: 46053 | K42: 18 | L42: 95 | M42: 1710 | N42: 0 | O42: 0 | P42: 1710 | Q42: paid | R42: 46048
A43: in_20260100042 | B43: INV-2026-01-0042 | C43: 46049 | D43: CUST011 | E43: Prairie Health Connect | F43: SUB011 | G43: Sales Hub | H43: Monthly | I43: 46049 | J43: 46053 | K43: 18 | L43: 110 | M43: 1980 | N43: 0 | O43: 0 | P43: 1980 | Q43: paid | R43: 46049
... A48: in_20260100047 | B48: INV-2026-01-0047 | C48: 46053 | D48: CUST033 | E48: Ottawa Retail Solutions | F48: SUB033 | G48: Marketing Pro | H48: Monthly | I48: 46053 | J48: 46053 | K48: 25 | L48: 85 | M48: 2125 | N48: 0 | O48: 0 | P48: 2125 | Q48: paid | R48: 46053

Sheet billing_feb_2026
A1: invoice_id | B1: invoice_number | C1: invoice_date | D1: customer_id | E1: customer_name | F1: subscription_id | G1: plan_name | H1: billing_cycle | I1: period_start | J1: period_end | K1: seats | L1: unit_price_usd | M1: subtotal | N1: discount_pct | O1: discount_amount | P1: amount_due_usd | Q1: status | R1: payment_date | S1: failure_reason
A2: in_20260200001 | B2: INV-2026-02-0001 | C2: 46054 | D2: CUST007 | E2: Ontario Manufacturing Tech | F2: SUB007 | G2: Marketing Pro | H2: Monthly | I2: 46054 | J2: 46081 | K2: 16 | L2: 85 | M2: 1360 | N2: 0 | O2: 0 | P2: 1360 | Q2: paid | R2: 46054
A3: in_20260200002 | B3: INV-2026-02-0002 | C3: 46054 | D3: CUST007 | E3: Ontario Manufacturing Tech | F3: SUB050 | G3: Analytics Starter | H3: Monthly | I3: 46054 | J3: 46081 | K3: 15 | L3: 45 | M3: 675 | N3: 12 | O3: 81 | P3: 594 | Q3: paid | R3: 46054
A4: in_20260200003 | B4: INV-2026-02-0003 | C4: 46055 | D4: CUST018 | E4: Vancouver FinTech Labs | F4: SUB018 | G4: Analytics Enterprise | H4: Monthly | I4: 46055 | J4: 46081 | K4: 35 | L4: 180 | M4: 6300 | N4: 0 | O4: 0 | P4: 6300 | Q4: paid | R4: 46055
A5: in_20260200004 | B5: INV-2026-02-0004 | C5: 46056 | D5: CUST029 | E5: Halifax Healthcare Tech | F5: SUB029 | G5: Marketing Pro | H5: Monthly | I5: 46056 | J5: 46081 | K5: 22 | L5: 85 | M5: 1870 | N5: 0 | O5: 0 | P5: 1870 | Q5: paid | R5: 46056
A6: in_20260200005 | B6: INV-2026-02-0005 | C6: 46058 | D6: CUST003 | E6: Maple Healthcare Systems | F6: SUB003 | G6: Marketing Pro | H6: Monthly | I6: 46058 | J6: 46081 | K6: 23 | L6: 85 | M6: 1955 | N6: 0 | O6: 0 | P6: 1955 | Q6: paid | R6: 46058
A7: in_20260200006 | B7: INV-2026-02-0006 | C7: 46058 | D7: CUST006 | E7: Northern Retail Solutions | F7: SUB043 | G7: Marketing Pro | H7: Monthly | I7: 46058 | J7: 46081 | K7: 33 | L7: 85 | M7: 2805 | N7: 0 | O7: 0 | P7: 2805 | Q7: paid | R7: 46058
A8: in_20260200007 | B8: INV-2026-02-0007 | C8: 46058 | D8: CUST027 | E8: Pacific Finance Corp | F8: SUB053 | G8: Analytics Enterprise | H8: Monthly | I8: 46058 | J8: 46081 | K8: 31 | L8: 180 | M8: 5580 | N8: 0 | O8: 0 | P8: 5580 | Q8: paid | R8: 46058
A9: in_20260200008 | B9: INV-2026-02-0008 | C9: 46058 | D9: CUST008 | E9: Quantum Education Platform | F9: SUB059 | G9: Marketing Pro | H9: Monthly | I9: 46058 | J9: 46081 | K9: 22 | L9: 85 | M9: 1870 | N9: 0 | O9: 0 | P9: 1870 | Q9: paid | R9: 46058
A10: in_20260200009 | B10: INV-2026-02-0009 | C10: 46059 | D10: CUST027 | E10: Pacific Finance Corp | F10: SUB027 | G10: Sales Hub | H10: Monthly | I10: 46059 | J10: 46081 | K10: 28 | L10: 110 | M10: 3080 | N10: 0 | O10: 0 | P10: 3080 | Q10: paid | R10: 46059
A11: in_20260200010 | B11: INV-2026-02-0010 | C11: 46061 | D11: CUST014 | E11: Toronto Media Group | F11: SUB014 | G11: Marketing Pro | H11: Monthly | I11: 46061 | J11: 46081 | K11: 28 | L11: 85 | M11: 2380 | N11: 0 | O11: 0 | P11: 2380 | Q11: paid | R11: 46061
A12: in_20260200011 | B12: INV-2026-02-0011 | C12: 46061 | D12: CUST010 | E12: Montreal Finance Hub | F12: SUB045 | G12: Marketing Pro | H12: Monthly | I12: 46061 | J12: 46081 | K12: 13 | L12: 85 | M12: 1105 | N12: 0 | O12: 0 | P12: 1105 | Q12: paid | R12: 46061
A13: in_20260200012 | B13: INV-2026-02-0012 | C13: 46061 | D13: CUST024 | E13: Western Retail Group | F13: SUB058 | G13: Sales Hub | H13: Monthly | I13: 46061 | J13: 46081 | K13: 26 | L13: 110 | M13: 2860 | N13: 0 | O13: 0 | P13: 2860 | Q13: paid | R13: 46061
... A35: in_20260200034 | B35: INV-2026-02-0034 | C35: 46073 | D35: CUST042 | E35: Pacific Coast Analytics | F35: SUB064 | G35: Analytics Growth | H35: Monthly | I35: 46073 | J35: 46081 | K35: 32 | L35: 95 | M35: 3040 | N35: 0 | O35: 0 | P35: 3040 | Q35: paid | R35: 46073
A36: in_20260299001 | B36: CN-2026-02-0001 | C36: 46074 | D36: CUST007 | E36: Ontario Manufacturing Tech | F36: SUB050 | G36: Analytics Starter | H36: Monthly | I36: 46074 | J36: 46081 | K36: 15 | L36: 45 | M36: 675 | N36: 12 | O36: 81 | P36: -169.71 | Q36: refunded | R36: 46074 | S36: Prorated refund â€” subscription cancelled 2026-02-20
A37: in_20260200035 | B37: INV-2026-02-0035 | C37: 46075 | D37: CUST015 | E37: BC Retail Networks | F37: SUB046 | G37: Analytics Enterprise | H37: Monthly | I37: 46075 | J37: 46081 | K37: 20 | L37: 180 | M37: 3600 | N37: 0 | O37: 0 | P37: 3600 | Q37: paid | R37: 46075
A38: in_20260200036 | B38: INV-2026-02-0036 | C38: 46075 | D38: CUST025 | E38: Montreal Manufacturing Pro | F38: SUB048 | G38: Sales Hub | H38: Monthly | I38: 46075 | J38: 46081 | K38: 36 | L38: 110 | M38: 3960 | N38: 0 | O38: 0 | P38: 3960 | Q38: paid | R38: 46075
A39: in_20260200037 | B39: INV-2026-02-0037 | C39: 46076 | D39: CUST026 | E39: Ontario Education Connect | F39: SUB026 | G39: Analytics Growth | H39: Monthly | I39: 46076 | J39: 46081 | K39: 16 | L39: 95 | M39: 1520 | N39: 0 | O39: 0 | P39: 1520 | Q39: paid | R39: 46076
A40: in_20260200038 | B40: INV-2026-02-0038 | C40: 46076 | D40: CUST039 | E40: Toronto Commerce Cloud | F40: SUB039 | G40: Marketing Pro | H40: Monthly | I40: 46076 | J40: 46081 | K40: 29 | L40: 85 | M40: 2465 | N40: 0 | O40: 0 | P40: 2465 | Q40: paid | R40: 46076
A41: in_20260200039 | B41: INV-2026-02-0039 | C41: 46078 | D41: CUST024 | E41: Western Retail Group | F41: SUB024 | G41: Marketing Pro | H41: Monthly | I41: 46078 | J41: 46081 | K41: 31 | L41: 85 | M41: 2635 | N41: 0 | O41: 0 | P41: 2635 | Q41: paid | R41: 46078
A42: in_20260200040 | B42: INV-2026-02-0040 | C42: 46079 | D42: CUST037 | E42: Maritime SaaS Ventures | F42: SUB037 | G42: Platform Suite | H42: Monthly | I42: 46079 | J42: 46081 | K42: 35 | L42: 150 | M42: 5250 | N42: 0 | O42: 0 | P42: 5250 | Q42: paid | R42: 46079
A43: in_20260200041 | B43: INV-2026-02-0041 | C43: 46079 | D43: CUST040 | E43: BC Education Innovations | F43: SUB040 | G43: Analytics Growth | H43: Monthly | I43: 46079 | J43: 46081 | K43: 18 | L43: 95 | M43: 1710 | N43: 0 | O43: 0 | P43: 1710 | Q43: paid | R43: 46079
A44: in_20260200042 | B44: INV-2026-02-0042 | C44: 46080 | D44: CUST011 | E44: Prairie Health Connect | F44: SUB011 | G44: Sales Hub | H44: Monthly | I44: 46080 | J44: 46081 | K44: 18 | L44: 110 | M44: 1980 | N44: 0 | O44: 0 | P44: 1980 | Q44: paid | R44: 46080
A45: in_20260200043 | B45: INV-2026-02-0043 | C45: 46081 | D45: CUST020 | E45: Atlantic SaaS Systems | F45: SUB020 | G45: Sales Hub | H45: Monthly | I45: 46081 | J45: 46081 | K45: 15 | L45: 110 | M45: 1650 | N45: 0 | O45: 0 | P45: 1650 | Q45: paid | R45: 46081
A46: in_20260200044 | B46: INV-2026-02-0044 | C46: 46081 | D46: CUST022 | E46: Toronto Tech Ventures | F46: SUB022 | G46: Platform Suite | H46: Monthly | I46: 46081 | J46: 46081 | K46: 33 | L46: 150 | M46: 4950 | N46: 0 | O46: 0 | P46: 4950 | Q46: paid | R46: 46081
A47: in_20260200045 | B47: INV-2026-02-0045 | C47: 46081 | D47: CUST033 | E47: Ottawa Retail Solutions | F47: SUB033 | G47: Marketing Pro | H47: Monthly | I47: 46081 | J47: 46081 | K47: 25 | L47: 85 | M47: 2125 | N47: 0 | O47: 0 | P47: 2125 | Q47: paid | R47: 46081
A48: in_20260200046 | B48: INV-2026-02-0046 | C48: 46081 | D48: CUST035 | E48: Vancouver Health Systems | F48: SUB035 | G48: Sales Hub | H48: Monthly | I48: 46081 | J48: 46081 | K48: 20 | L48: 110 | M48: 2200 | N48: 0 | O48: 0 | P48: 2200 | Q48: paid | R48: 46081
A49: in_20260200047 | B49: INV-2026-02-0047 | C49: 46081 | D49: CUST021 | E49: Calgary Commerce Solutions | F49: SUB057 | G49: Platform Suite | H49: Monthly | I49: 46081 | J49: 46081 | K49: 28 | L49: 150 | M49: 4200 | N49: 0 | O49: 0 | P49: 4200 | Q49: paid | R49: 46081

Sheet bank_statement_jan_2026
A1: Account: iDynamics SaaS Inc - Operating
A2: Period: January 2026
A3: Opening Balance: | B3: 1250000
A5: transaction_date | B5: post_date | C5: description | D5: type | E5: amount | F5: reference_number | G5: running_balance
A6: 46023 | B6: 46023 | C6: ACH CREDIT â€” ONTARIO MANUFACTURING TECH â€” REF:SUB007 | D6: Credit | E6: 1360 | F6: TXN-2026-02-0001 | G6: 1251360
A7: 46023 | B7: 46023 | C7: ACH CREDIT â€” ONTARIO MANUFACTURING TECH â€” REF:SUB050 | D7: Credit | E7: 594 | F7: TXN-2026-02-0002 | G7: 1251954
A8: 46024 | B8: 46024 | C8: ACH CREDIT â€” VANCOUVER FINTECH LABS â€” REF:SUB018 | D8: Credit | E8: 6300 | F8: TXN-2026-02-0003 | G8: 1258254
A9: 46025 | B9: 46025 | C9: ACH CREDIT â€” HALIFAX HEALTHCARE TECH â€” REF:SUB029 | D9: Credit | E9: 1870 | F9: TXN-2026-02-0004 | G9: 1260124
A10: 46027 | B10: 46027 | C10: ACH CREDIT â€” MAPLE HEALTHCARE SYSTEMS â€” REF:SUB003 | D10: Credit | E10: 1955 | F10: TXN-2026-02-0005 | G10: 1262079
A11: 46027 | B11: 46027 | C11: ACH CREDIT â€” NORTHERN RETAIL SOLUTIONS â€” REF:SUB043 | D11: Credit | E11: 2805 | F11: TXN-2026-02-0006 | G11: 1264884
A12: 46027 | B12: 46027 | C12: ACH CREDIT â€” PACIFIC FINANCE CORP â€” REF:SUB053 | D12: Credit | E12: 5580 | F12: TXN-2026-02-0007 | G12: 1270464
A13: 46027 | B13: 46027 | C13: ACH CREDIT â€” QUANTUM EDUCATION PLATFORM â€” REF:SUB059 | D13: Credit | E13: 1870 | F13: TXN-2026-02-0008 | G13: 1272334
A14: 46028 | B14: 46028 | C14: ACH CREDIT â€” PACIFIC FINANCE CORP â€” REF:SUB027 | D14: Credit | E14: 3080 | F14: TXN-2026-02-0009 | G14: 1275414
A15: 46030 | B15: 46030 | C15: ACH CREDIT â€” TORONTO MEDIA GROUP â€” REF:SUB014 | D15: Credit | E15: 2380 | F15: TXN-2026-02-0010 | G15: 1277794
A16: 46030 | B16: 46030 | C16: ACH CREDIT â€” MONTREAL FINANCE HUB â€” REF:SUB045 | D16: Credit | E16: 1105 | F16: TXN-2026-02-0011 | G16: 1278899
A17: 46030 | B17: 46030 | C17: ACH CREDIT â€” WESTERN RETAIL GROUP â€” REF:SUB058 | D17: Credit | E17: 2860 | F17: TXN-2026-02-0012 | G17: 1281759
... A51: 46053 | B51: 46053 | C51: ACH CREDIT â€” OTTAWA RETAIL SOLUTIONS â€” REF:SUB033 | D51: Credit | E51: 2125 | F51: TXN-2026-02-0046 | G51: 1427975

Sheet bank_statement_feb_2026
A1: Account: iDynamics SaaS Inc - Operating
A2: Period: February 2026
A3: Opening Balance: | B3: 1427945
A5: transaction_date | B5: post_date | C5: description | D5: type | E5: amount | F5: reference_number | G5: running_balance
A6: 46058 | B6: 46058 | C6: ACH CREDIT â€” PRAIRIE SAAS INNOVATIONS â€” RETRY REF:SUB028 INV:INV-2026-01-0030 | D6: Credit | E6: 675 | F6: TXN-2026-02-0001 | G6: 1428650
A7: 46054 | B7: 46054 | C7: ACH CREDIT â€” ONTARIO MANUFACTURING TECH â€” REF:SUB007 | D7: Credit | E7: 1360 | F7: TXN-2026-02-0002 | G7: 1430010
A8: 46054 | B8: 46054 | C8: ACH CREDIT â€” ONTARIO MANUFACTURING TECH â€” REF:SUB050 | D8: Credit | E8: 594 | F8: TXN-2026-02-0003 | G8: 1430604
A9: 46055 | B9: 46055 | C9: ACH CREDIT â€” VANCOUVER FINTECH LABS â€” REF:SUB018 | D9: Credit | E9: 6300 | F9: TXN-2026-02-0004 | G9: 1436904
A10: 46056 | B10: 46056 | C10: ACH CREDIT â€” HALIFAX HEALTHCARE TECH â€” REF:SUB029 | D10: Credit | E10: 1870 | F10: TXN-2026-02-0005 | G10: 1438774
A11: 46058 | B11: 46058 | C11: ACH CREDIT â€” MAPLE HEALTHCARE SYSTEMS â€” REF:SUB003 | D11: Credit | E11: 1955 | F11: TXN-2026-02-0006 | G11: 1440729
A12: 46058 | B12: 46058 | C12: ACH CREDIT â€” NORTHERN RETAIL SOLUTIONS â€” REF:SUB043 | D12: Credit | E12: 2805 | F12: TXN-2026-02-0007 | G12: 1443534
A13: 46058 | B13: 46058 | C13: ACH CREDIT â€” PACIFIC FINANCE CORP â€” REF:SUB053 | D13: Credit | E13: 5580 | F13: TXN-2026-02-0008 | G13: 1449114
A14: 46058 | B14: 46058 | C14: ACH CREDIT â€” QUANTUM EDUCATION PLATFORM â€” REF:SUB059 | D14: Credit | E14: 1870 | F14: TXN-2026-02-0009 | G14: 1450984
A15: 46059 | B15: 46059 | C15: ACH CREDIT â€” PACIFIC FINANCE CORP â€” REF:SUB027 | D15: Credit | E15: 3080 | F15: TXN-2026-02-0010 | G15: 1454064
A16: 46061 | B16: 46061 | C16: ACH CREDIT â€” TORONTO MEDIA GROUP â€” REF:SUB014 | D16: Credit | E16: 2380 | F16: TXN-2026-02-0011 | G16: 1456444
A17: 46061 | B17: 46061 | C17: ACH CREDIT â€” MONTREAL FINANCE HUB â€” REF:SUB045 | D17: Credit | E17: 1105 | F17: TXN-2026-02-0012 | G17: 1457549
... A54: 46081 | B54: 46081 | C54: ACH CREDIT â€” CALGARY COMMERCE SOLUTIONS â€” REF:SUB057 | D54: Credit | E54: 4200 | F54: TXN-2026-02-0049 | G54: 1542624.3

Sheet Actuals
A1: Metric | B1: 46023 | C1: 46054 | D1: 46082
A2: Opening MRR | B2: 143069.5 | C2: =B6 -> 144779.5 | D2: =C6 -> 150305.5
A3: New MRR | B3: 1710 | C3: 6120 | D3: 3000
A4: Expansion MRR | B4: 0 | C4: 0 | D4: 380
A5: Churned MRR | B5: 0 | C5: 594 | D5: 0
A6: Closing MRR | B6: =B2+B3+B4-B5 -> 144779.5 | C6: =C2+C3+C4-C5 -> 150305.5 | D6: =D2+D3+D4-D5 -> 153685.5
A7: S&M | B7: 30000 | C7: 31000 | D7: 29000
A8: R&D | B8: 25000 | C8: 25000 | D8: 22000
A9: G&A | B9: 19000 | C9: 19000 | D9: 22000
A10: Total OpEx | B10: =B7+B8+B9 -> 74000 | C10: =C7+C8+C9 -> 75000 | D10: =D7+D8+D9 -> 73000
A11: COGS | B11: =B6*0.3 -> 43433.85 | C11: =C6*0.3 -> 45091.65 | D11: =D6*0.3 -> 46105.65
A12: Gross Profit | B12: =B6-B11 -> 101345.65 | C12: =C6-C11 -> 105213.85 | D12: =D6-D11 -> 107579.85
A13: EBITDA | B13: =B12-B10 -> 27345.65 | C13: =C12-C10 -> 30213.85 | D13: =D12-D10 -> 34579.85
A14: New Customers | B14: 1 | C14: 2 | D14: 2
A15: Active Customers | B15: 39 | C15: 41 | D15: 42
A16: Active Subscriptions | B16: 52 | C16: 53 | D16: 54
A18: Legend: | B18: INPUT = type here | C18: FORMULA = never type here | D18: ANCHOR = one-time historical

Sheet Billing Reconciliation
A1: Metric | B1: Jan-26 | C1: Feb-26
A2: MRR | B2: ='Jan 2026 A vs F '!B9 -> 144779.5 | C2: ='Feb 2026 A vs F'!B9 -> 150305.5
A3: Total Invoiced | B3: =SUM(billing_jan_2026!P2:P48) -> 178650 | C3: =SUM(billing_feb_2026!P2:P49) -> 113974.29
A4: Total Collected | B4: =SUM(bank_statement_jan_2026!E6:E51) -> 177975 | C4: =SUM(bank_statement_feb_2026!E6:E54) -> 114649.29
A5: MRR vs Invoiced | B5: =B3-B2 -> 33870.5 | C5: =C3-C2 -> -36331.21
A6: Invoiced vs Collected | B6: =B3-B4 -> 675 | C6: =C3-C4 -> -675
A8: Bridge 1: MRR to Invoiced
A9: Item | B9: Jan-26 | C9: Feb-26
A10: MRR | B10: =B2 -> 144779.5 | C10: =C2 -> 150305.5
A11: _+ Annual billing excess | B11: =SUMIF(billing_jan_2026!H:H, "Annual", billing_jan_2026!P:P) * (11/12) -> 64740.5 | C11: =SUMIF(billing_feb_2026!H:H, "Annual", billing_feb_2026!P:P) * (11/12) -> 0
A12: _- Annual MRR with no billing this month | B12: =(billing_jan_2026!P34 + billing_jan_2026!P37) / 12 -> 5885.5 | C12: =(billing_jan_2026!P34 + billing_jan_2026!P37) / 12 -> 5885.5
A13: _= Total Invoiced | B13: =B10+B11 -> 209520 | C13: =C10+C11-C12 -> 144420
A14: Difference | B14: =B13-B3 -> 30870 | C14: =C13-C3 -> 30445.71
A16: Bridge 2: Invoiced to Collected
A17: Item | B17: Jan-26 | C17: Feb-26
A18: Total Invoiced | B18: =B3 -> 178650 | C18: =C3 -> 113974.29
A19: Total Collected | B19: =B4 -> 177975 | C19: =C4 -> 114649.29
A20: Difference | B20: =B19-B18 -> -675 | C20: =C19-C18 -> 675
A22: Part 5:
A23: The billing file for January shows $2185 for SUB012.
A24: The database for January shows $2185 for SUB012.
A25: The billing file represents a point in time record while the database represents a historical period.
A26: They share the same number therefore $2185 is the correct number.
A28: Part 6:
A29: The negative row is row number 36.
A30: This row relates to Ontario Manufacturing Tech and their monthly Analytics Starter subscription.
A31: A refund was issued because OMT cancelled their subscription on 2026-02-20.
A32: Since a refund was issued, total collected will be lowered. They were billed at the beginning of the month and because of the cancellation occurring near the end, they received a prorated refund.
A33: Total billed will also be reduced since the billing system recorded that the invoice was partially reversed.
A35: Commentary:
... A40: Along with this, the negative entry from Ontario Manufacturing Tech (SUB050) comes from a prorated refund on February 20th following a cancellation in the middle of the month. This confirms that when the billing system properly records partial reversals, downstream reporting should be audited to make sure these changes are reflected.

Sheet Historical Baseline
A1: HISTORICAL BASELINE — 2024 & 2025 ACTUALS
A2: Fill this table from your MRR workbook and database. Show your source for every number.
A3: This is the foundation for the 2026 forecast. If these numbers are wrong, everything downstream is wrong.
A5: MRR WATERFALL (QUARTERLY)
A6: Metric | B6: Q1 2024 | C6: Q2 2024 | D6: Q3 2024 | E6: Q4 2024 | F6: Q1 2025 | G6: Q2 2025 | H6: Q3 2025 | I6: Q4 2025 | K6: Source
A7: Opening MRR | B7: =Waterfall!B3 -> 0 | C7: =B13 -> 20490 | D7: =C13 -> 35989 | E7: =D13 -> 63708.5 | F7: =E13 -> 91123.5 | G7: =F13 -> 126539.5 | H7: =G13 -> 152114.5 | I7: =H13 -> 150359.5 | K7: e.g. Waterfall tab, prior Q closing
A8: + New MRR | B8: =SUM(Waterfall!C3:C5) -> 20490 | C8: =SUM(Waterfall!C6:C8) -> 15499 | D8: =SUM(Waterfall!C9:C11) -> 29619.5 | E8: =SUM(Waterfall!C12:C14) -> 30000 | F8: =SUM(Waterfall!C15:C17) -> 36735.5 | G8: =SUM(Waterfall!C18:C20) -> 26470 | H8: =SUM(Waterfall!C21:C23) -> 0 | I8: =SUM(Waterfall!C24:C26) -> 935 | K8: Waterfall tab, sum of New column
A9: + Expansion MRR | B9: =SUM(Waterfall!D3:D5) -> 0 | C9: =SUM(Waterfall!D6:D8) -> 0 | D9: =SUM(Waterfall!D9:D11) -> 0 | E9: =SUM(Waterfall!D12:D14) -> 0 | F9: =SUM(Waterfall!D15:D17) -> 140 | G9: =SUM(Waterfall!D18:D20) -> 2785 | H9: =SUM(Waterfall!D21:D23) -> 5520 | I9: =SUM(Waterfall!D24:D26) -> 1765 | K9: Waterfall tab, sum of Expansion column
A10: − Contraction MRR | B10: =SUM(Waterfall!E3:E5) -> 0 | C10: =SUM(Waterfall!E6:E8) -> 0 | D10: =SUM(Waterfall!E9:E11) -> 0 | E10: =SUM(Waterfall!E12:E14) -> 0 | F10: =SUM(Waterfall!E15:E17) -> -1009.5 | G10: =SUM(Waterfall!E18:E20) -> 0 | H10: =SUM(Waterfall!E21:E23) -> -835 | I10: =SUM(Waterfall!E24:E26) -> -516.5 | K10: Waterfall tab, sum of Contraction column
A11: − Churned MRR | B11: =SUM(Waterfall!F3:F5) -> 0 | C11: =SUM(Waterfall!F6:F8) -> 0 | D11: =SUM(Waterfall!F9:F11) -> -1900 | E11: =SUM(Waterfall!F12:F14) -> -2585 | F11: =SUM(Waterfall!F15:F17) -> -450 | G11: =SUM(Waterfall!F18:F20) -> -3680 | H11: =SUM(Waterfall!F21:F23) -> -6440 | I11: =SUM(Waterfall!F24:F26) -> -1624.5 | K11: Waterfall tab, sum of Churned column
A12: Net New MRR | B12: =B13-B7 -> 20490 | C12: =C13-C7 -> 15499 | D12: =D13-D7 -> 27719.5 | E12: =E13-E7 -> 27415 | F12: =F13-F7 -> 35416 | G12: =G13-G7 -> 25575 | H12: =H13-H7 -> -1755 | I12: =I13-I7 -> -7290 | K12: Should equal Closing − Opening
A13: Closing MRR | B13: =Waterfall!H5 -> 20490 | C13: =Waterfall!H8 -> 35989 | D13: =Waterfall!H11 -> 63708.5 | E13: =Waterfall!H14 -> 91123.5 | F13: =Waterfall!H17 -> 126539.5 | G13: =Waterfall!H20 -> 152114.5 | H13: =Waterfall!H23 -> 150359.5 | I13: 143069.5 | K13: Waterfall tab, last month of quarter
A15: CUSTOMERS & SUBSCRIPTIONS
A16: Metric | B16: Q1 2024 | C16: Q2 2024 | D16: Q3 2024 | E16: Q4 2024 | F16: Q1 2025 | G16: Q2 2025 | H16: Q3 2025 | I16: Q4 2025 | K16: Source
A17: New customers | B17: =Retention!D19-0 -> 4 | C17: =Retention!G19-Retention!D19 -> 7 | D17: =Retention!J19-Retention!G19 -> 6 | E17: =Retention!M19-Retention!J19 -> 6 | F17: =Retention!Q19-Retention!N19 -> 6 | G17: =Retention!T19-Retention!Q19 -> 6 | H17: =Retention!V19-Retention!S19 -> 1 | I17: =SUM('Unit Economics'!J76:J78) -> 0 | K17: S&M data on Unit Economics tab
A18: Churned subscriptions | B18: =SUM(Retention!B17:D17) -> 0 | C18: =SUM(Retention!E17:G17) -> 0 | D18: =SUM(Retention!H17:J17) -> 1 | E18: =SUM(Retention!K17:M17) -> 2 | F18: =SUM(Retention!N17:P17) -> 1 | G18: =SUM(Retention!Q17:S17) -> 3 | H18: =SUM(Retention!T17:V17) -> 2 | I18: =SUM(Retention!W17:Y17) -> 1 | K18: Retention tab
A19: Active subscriptions (end of Q) | B19: =Retention!D16 -> 5 | C19: =Retention!G16 -> 13 | D19: =Retention!J16 -> 21 | E19: =Retention!M16 -> 31 | F19: =Retention!Q16 -> 46 | G19: =Retention!T16 -> 53 | H19: =Retention!W16 -> 51 | I19: =Retention!Z16 -> 51 | K19: Retention tab running count
A20: Active customers (end of Q) | B20: =Retention!D19 -> 4 | C20: =Retention!G19 -> 11 | D20: =Retention!J19 -> 17 | E20: =Retention!M19 -> 23 | F20: =Retention!Q19 -> 31 | G20: =Retention!T19 -> 37 | H20: =Retention!W19 -> 37 | I20: =Retention!Z19 -> 38 | K20: Unique cust IDs with ≥1 active sub
A22: P&L SUMMARY
A23: Metric | B23: Q1 2024 | C23: Q2 2024 | D23: Q3 2024 | E23: Q4 2024 | F23: Q1 2025 | G23: Q2 2025 | H23: Q3 2025 | I23: Q4 2025 | K23: Source
A24: Revenue | B24: =B13*3 -> 61470 | C24: =C13*3 -> 107967 | D24: =D13*3 -> 191125.5 | E24: =E13*3 -> 273370.5 | F24: =F13*3 -> 379618.5 | G24: =G13*3 -> 456343.5 | H24: =H13*3 -> 451078.5 | I24: =I13*3 -> 429208.5 | K24: Sum of monthly MRR from workbook
A25: COGS (30%) | B25: =B24*0.3 -> 18441 | C25: =C24*0.3 -> 32390.1 | D25: =D24*0.3 -> 57337.65 | E25: =E24*0.3 -> 82011.15 | F25: =F24*0.3 -> 113885.55 | G25: =G24*0.3 -> 136903.05 | H25: =H24*0.3 -> 135323.55 | I25: =I24*0.3 -> 128762.55 | K25: Revenue × 30%
A26: Gross Profit | B26: =B24-B25 -> 43029 | C26: =C24-C25 -> 75576.9 | D26: =D24-D25 -> 133787.85 | E26: =E24-E25 -> 191359.35 | F26: =F24-F25 -> 265732.95 | G26: =G24-G25 -> 319440.45 | H26: =H24-H25 -> 315754.95 | I26: =I24-I25 -> 300445.95 | K26: Revenue − COGS
A27: Gross Margin % | B27: =B26/B24 -> 0.7 | C27: =C26/C24 -> 0.7 | D27: =D26/D24 -> 0.7 | E27: =E26/E24 -> 0.7 | F27: =F26/F24 -> 0.7 | G27: =G26/G24 -> 0.7 | H27: =H26/H24 -> 0.7 | I27: =I26/I24 -> 0.7 | K27: GP / Revenue
A28: S&M | B28: 18500 | C28: 29000 | D28: 47000 | E28: 63000 | F28: ='Unit Economics'!I67+'Unit Economics'!I68+'Unit Economics'!I69 -> 88250 | G28: ='Unit Economics'!I70+'Unit Economics'!I71+'Unit Economics'!I72 -> 87550 | H28: ='Unit Economics'!I73+'Unit Economics'!I74+'Unit Economics'!I75 -> 91450 | I28: ='Unit Economics'!I76+'Unit Economics'!I77+'Unit Economics'!I78 -> 74150 | K28: Accounting data, Unit Economics tab
A29: R&D | B29: 15000 | C29: 25000 | D29: 42000 | E29: 57000 | F29: 62000 | G29: 68000 | H29: 72000 | I29: 65000 | K29: Company cost structure
A30: G&A | B30: 8000 | C30: 13000 | D30: 21000 | E30: 28000 | F30: 32000 | G30: 34000 | H30: 36000 | I30: 33000 | K30: Company cost structure
A31: Total OpEx | B31: =B28+B29+B30 -> 41500 | C31: =C28+C29+C30 -> 67000 | D31: =D28+D29+D30 -> 110000 | E31: =E28+E29+E30 -> 148000 | F31: =F28+F29+F30 -> 182250 | G31: =G28+G29+G30 -> 189550 | H31: =H28+H29+H30 -> 199450 | I31: =I28+I29+I30 -> 172150 | K31: S&M + R&D + G&A
A32: EBITDA | B32: =B26-B31 -> 1529 | C32: =C26-C31 -> 8576.9 | D32: =D26-D31 -> 23787.85 | E32: =E26-E31 -> 43359.35 | F32: =F26-F31 -> 83482.95 | G32: =G26-G31 -> 129890.45 | H32: =H26-H31 -> 116304.95 | I32: =I26-I31 -> 128295.95 | K32: Gross Profit − Total OpEx
A33: EBITDA Margin % | B33: =B32/B24 -> 0.024873922 | C33: =C32/C24 -> 0.079440014 | D33: =D32/D24 -> 0.12446194 | E33: =E32/E24 -> 0.1586102 | F33: =IF(F24=0,"",F32/F24) -> 0.21991275 | G33: =IF(G24=0,"",G32/G24) -> 0.28463307 | H33: =IF(H24=0,"",H32/H24) -> 0.25783749 | I33: =IF(I24=0,"",I32/I24) -> 0.29891288 | K33: EBITDA / Revenue
A35: KEY RATES (CALCULATED)
A36: Metric | B36: Q1 2024 | C36: Q2 2024 | D36: Q3 2024 | E36: Q4 2024 | F36: Q1 2025 | G36: Q2 2025 | H36: Q3 2025 | I36: Q4 2025 | K36: Source
A37: MRR churn rate (quarterly) | B37: =IF(B7=0,"",ABS(B11)/B7) | C37: =IF(C7=0,"",ABS(C11)/C7) -> 0 | D37: =IF(D7=0,"",ABS(D11)/D7) -> 0.052793909 | E37: =IF(E7=0,"",ABS(E11)/E7) -> 0.040575433 | F37: =IF(F7=0,"",ABS(F11)/F7) -> 0.0049383529 | G37: =IF(G7=0,"",ABS(G11)/G7) -> 0.029081828 | H37: =IF(H7=0,"",ABS(H11)/H7) -> 0.042336529 | I37: =IF(I7=0,"",ABS(I11)/I7) -> 0.010804106 | K37: Churned MRR / Opening MRR
A38: MRR expansion rate (quarterly) | B38: =IF(B7=0,"",B9/B7) | C38: =IF(C7=0,"",C9/C7) -> 0 | D38: =IF(D7=0,"",D9/D7) -> 0 | E38: =IF(E7=0,"",E9/E7) -> 0 | F38: =IF(F7=0,"",F9/F7) -> 0.0015363765 | G38: =IF(G7=0,"",G9/G7) -> 0.022008938 | H38: =IF(H7=0,"",H9/H7) -> 0.036288454 | I38: =IF(I7=0,"",I9/I7) -> 0.011738533 | K38: Expansion MRR / Opening MRR
A39: Avg MRR per new customer | B39: =IF(B17=0,"",B8/B17) -> 5122.5 | C39: =IF(C17=0,"",C8/C17) -> 2214.1429 | D39: =IF(D17=0,"",D8/D17) -> 4936.5833 | E39: =IF(E17=0,"",E8/E17) -> 5000 | F39: =IF(F17=0,"",F8/F17) -> 6122.5833 | G39: =IF(G17=0,"",G8/G17) -> 4411.6667 | H39: =IF(H17=0,"",H8/H17) -> 0 | I39: N/A | K39: New MRR / New customers
A40: CAC (quarterly S&M / new custs) | B40: =IF(B17=0,"N/A",B28/B17) -> 4625 | C40: =IF(C17=0,"N/A",C28/C17) -> 4142.8571 | D40: =IF(D17=0,"N/A",D28/D17) -> 7833.3333 | E40: =IF(E17=0,"N/A",E28/E17) -> 10500 | F40: =IF(F17=0,"N/A",F28/F17) -> 14708.333 | G40: =IF(G17=0,"N/A",G28/G17) -> 14591.667 | H40: =IF(H17=0,"N/A",H28/H17) -> 91450 | I40: =IF(I17=0,"N/A",I28/I17) -> N/A | K40: Only meaningful if new custs > 0
A43: RECONCILIATION NOTES
A44: Dec 2025 closing MRR (this table): | B44: =I13 -> 143069.5
A45: Feb 2026 snapshot MRR: | B45: ='Unit Economics'!B6 -> 144185.5
A46: Difference: | B46: =B44-B45 -> -1116
...

Sheet Forecast Assumptions
A1: 2026 FORECAST ASSUMPTIONS
A2: From: David Chen, VP Finance — Leadership planning meeting, December 2025
A3: All values are hardcoded inputs. Every formula on the Forecast tab must reference these cells.
A5: STARTING POSITION
A6: Opening MRR (Jan 2026) | B6: ='Historical Baseline'!B44 -> 143069.5 | D6: ← Pull from your Historical Baseline tab
A7: Active subscriptions (Dec 2025) | B7: ='Historical Baseline'!I19 -> 51 | D7: ← Pull from your Historical Baseline tab
A8: Active customers (Dec 2025) | B8: ='Historical Baseline'!I20 -> 38 | D8: ← Pull from your Historical Baseline tab
A10: GROWTH ASSUMPTIONS
A11: Metric | B11: Q1 2026 | C11: Q2 2026 | D11: Q3 2026 | E11: Q4 2026
A12: New customers | B12: 4 | C12: 6 | D12: 9 | E12: 9
A13: Avg MRR per new customer | B13: 3000 | C13: 3200 | D13: 3200 | E13: 3400
A14: Quarterly expansion rate | B14: 0.015 | C14: 0.015 | D14: 0.015 | E14: 0.015
A15: Quarterly churn rate | B15: 0.02 | C15: 0.02 | D15: 0.02 | E15: 0.02
A17: Expansion rate: 0.50%/month compounded to quarterly. Seat adds + upsells from existing base.
A18: Churn rate: 0.67%/month compounded to quarterly. Target ~8% annual (down from 2025 actual).
A19: Both rates apply to BEGINNING-of-quarter MRR, not ending.
A21: MARGIN
A22: Gross margin | B22: 0.7 | C22: Same across all quarters — no cost structure changes planned.
A24: OPERATING EXPENSES
A25: Metric | B25: Q1 2026 | C25: Q2 2026 | D25: Q3 2026 | E25: Q4 2026
A26: Sales & Marketing | B26: 90000 | C26: 90000 | D26: 108000 | E26: 108000
A27: Research & Development | B27: 75000 | C27: 75000 | D27: 75000 | E27: 75000
A28: General & Administrative | B28: 57000 | C28: 57000 | D28: 57000 | E28: 57000
A29: Total OpEx | B29: 222000 | C29: 222000 | D29: 240000 | E29: 240000
A31: S&M increases H2 to fund acquisition push. Not repeating H2 2025 drought.
A33: REVENUE CONVENTION
A34: Quarterly Revenue = Closing MRR × 3
A35: This is the standard convention for forward-looking models: the ending run-rate × months in the period.

Sheet Jan 2026 A vs F 
A1: MRR Waterfall
A2: Metric | B2: Actual - Jan 26 | C2: Forecast - Jan 26 | D2: $ Variance | E2: % Variance | F2: F/U
A3: Opening MRR | B3: 143069.5 | C3: ='2026 Forecast'!B7 -> 143069.5 | D3: =B3-C3 -> 0 | E3: =IFERROR(B3/C3-1, 0) -> 0 | F3: {=_xlfn.IFS(D3<0, "U", D3>0, "F", D3=0, "-")} -> -
A4: + New MRR | B4: 1710 | C4: 4000 | D4: =B4-C4 -> -2290 | E4: =IFERROR(B4/C4-1, 0) -> -0.5725 | F4: {=_xlfn.IFS(D4<0, "U", D4>0, "F", D4=0, "-")} -> U
A5: + Expansion MRR | B5: 0 | C5: ='2026 Forecast'!B9/3 -> 715.3475 | D5: =B5-C5 -> -715.3475 | E5: =IFERROR(B5/C5-1, 0) -> -1 | F5: {=_xlfn.IFS(D5<0, "U", D5>0, "F", D5=0, "-")} -> U
A6: - Contraction MRR | B6: 0 | C6: 0 | D6: =B6-C6 -> 0 | E6: =IFERROR(B6/C6-1, 0) -> 0 | F6: {=_xlfn.IFS(D6<0, "U", D6>0, "F", D6=0, "-")} -> -
A7: − Churned MRR | B7: 0 | C7: ='2026 Forecast'!B10/3 -> 953.79667 | D7: =C7-B7 -> 953.79667 | E7: =IFERROR(B7/C7-1, 0) -> -1 | F7: {=_xlfn.IFS(D7>0, "U", D7<0, "F", D7=0, "-")} -> U
A8: Net New MRR | B8: =B4+B5-B7 -> 1710 | C8: =C4+C5-C7 -> 3761.5508 | D8: =B8-C8 -> -2051.5508 | E8: =B8/C8-1 -> -0.54540027 | F8: {=_xlfn.IFS(D8<0, "U", D8>0, "F", D8=0, "-")} -> U
A9: Closing MRR | B9: =B3+B4+B5-B7 -> 144779.5 | C9: =C3+C8 -> 146831.05 | D9: =B9-C9 -> -2051.5508 | E9: =B9/C9-1 -> -0.013972187 | F9: {=_xlfn.IFS(D9<0, "U", D9>0, "F", D9=0, "-")} -> U
A10: Closing ARR | B10: =B9*12 -> 1737354 | C10: =C9*12 -> 1761972.6 | D10: =B10-C10 -> -24618.61 | E10: =B10/C10-1 -> -0.013972187 | F10: {=_xlfn.IFS(D10<0, "U", D10>0, "F", D10=0, "-")} -> U
A12: P&L
A13: Metric | B13: Actual - Jan 26 | C13: Forecast - Jan 26 | D13: $ Variance | E13: % Variance | F13: F/U
A14: Revenue | B14: =B9 -> 144779.5 | C14: =C9 -> 146831.05 | D14: =B14-C14 -> -2051.5508 | E14: =B14/C14-1 -> -0.013972187 | F14: {=_xlfn.IFS(D14<0, "U", D14>0, "F", D14=0, "-")} -> U
A15: COGS | B15: =B14*(1-B17) -> 43433.85 | C15: =C14*0.3 -> 44049.315 | D15: =B15-C15 -> -615.46525 | E15: =B15/C15-1 -> -0.013972187 | F15: {=_xlfn.IFS(D15>0, "U", D15<0, "F", D15=0, "-")} -> F | H15: → Revenue × (1 − gross margin)
A16: Gross Profit | B16: =B14-B15 -> 101345.65 | C16: =C14-C15 -> 102781.74 | D16: =B16-C16 -> -1436.0856 | E16: =B16/C16-1 -> -0.013972187 | F16: {=_xlfn.IFS(D16<0, "U", D16>0, "F", D16=0, "-")} -> U | H16: → Revenue − COGS
A17: Gross Margin % | B17: 0.7 | C17: =C16/C14 -> 0.7 | E17: =B17/C17-1 -> 0 | F17: {=_xlfn.IFS(D17<0, "U", D17>0, "F", D17=0, "-")} -> - | H17: → GP / Revenue
A18: Sales & Marketing | B18: ='Forecast Assumptions'!B26/3 -> 30000 | C18: ='2026 Forecast'!B25/3 -> 30000 | D18: =B18-C18 -> 0 | E18: =B18/C18-1 -> 0 | F18: {=_xlfn.IFS(D18<0, "U", D18>0, "F", D18=0, "-")} -> - | H18: ← From Assumptions tab
A19: Research & Development | B19: ='Forecast Assumptions'!B27/3 -> 25000 | C19: ='2026 Forecast'!B26/3 -> 25000 | D19: =B19-C19 -> 0 | E19: =B19/C19-1 -> 0 | F19: {=_xlfn.IFS(D19<0, "U", D19>0, "F", D19=0, "-")} -> - | H19: ← From Assumptions tab
A20: General & Administrative | B20: ='Forecast Assumptions'!B28/3 -> 19000 | C20: ='2026 Forecast'!B27/3 -> 19000 | D20: =B20-C20 -> 0 | E20: =B20/C20-1 -> 0 | F20: {=_xlfn.IFS(D20<0, "U", D20>0, "F", D20=0, "-")} -> - | H20: ← From Assumptions tab
A21: Total OpEx | B21: =SUM(B18:B20) -> 74000 | C21: ='2026 Forecast'!B28/3 -> 74000 | D21: =B21-C21 -> 0 | E21: =B21/C21-1 -> 0 | F21: {=_xlfn.IFS(D21<0, "U", D21>0, "F", D21=0, "-")} -> - | H21: S&M + R&D + G&A
A22: EBITDA | B22: =B16-B21 -> 27345.65 | C22: =C16-C21 -> 28781.736 | D22: =B22-C22 -> -1436.0856 | E22: =B22/C22-1 -> -0.049895726 | F22: {=_xlfn.IFS(D22<0, "U", D22>0, "F", D22=0, "-")} -> U | H22: → Gross Profit − Total OpEx
A23: EBITDA Margin % | B23: =B22/B14 -> 0.18887791 | C23: =C22/C14 -> 0.19601941 | D23: =B23-C23 -> -0.0071414931 | E23: =B23/C23-1 -> -0.036432582 | F23: {=_xlfn.IFS(D23<0, "U", D23>0, "F", D23=0, "-")} -> U | H23: → EBITDA / Revenue
A25: Summary:
A26: January closed with an MRR of $144,780, -$2,051.55 (-1.4%) below expectation.
A27: This is due to the lack of new customers acquired this month.
A28: There was only 1 new customer signing this month which is less than the expected 1.3 new customers
A29: The customers revenue was $1,710 which is 43% less than the planned rate of $3000 per customer.
A30: There was no expansion recorded this month versus the expected $715.35.
A31: Offsetting this was the lack of churned MRR this month which resulted in a favorable variance of $954.
A32: EBITDA of $27,345.65 was 5% lower than the expected $28,781.74. This was driven by the shortfall in Gross Profit due to the Closing MRR being less than anticipated.
A33: Operating Expenses were in line with expectation.
A34: Currently, Q1 is approximately $6000 less than planned, which could be fixed with a strong performance in February.
A36: January 2026 — SaaS KPIs
A38: Metric | B38: Value | C38: Notes
A39: Active Customers | B39: 39 | C39: From your Jan 31 SQL snapshot
A40: Active Subscriptions | B40: 52 | C40: From your Jan 31 SQL snapshot
A41: ARPA | B41: ='Jan 2026 A vs F '!B9/'Jan 2026 A vs F '!B39 -> 3712.2949 | C41: Excel 04
A42: Gross Margin | B42: =B17 -> 0.7 | C42: Already in your P&L
A43: GRR | B43: =Retention!Z6 -> 1 | C43: Excel 03
A44: NRR | B44: =Retention!Z7 -> 1 | C44: Excel 03
...

Sheet Feb 2026 A vs F
A1: MRR Waterfall
A2: Metric | B2: Actual - Feb 26 | C2: Forecast - Feb 26 | D2: $ Variance | E2: % Variance | F2: F/U
A3: Opening MRR | B3: ='Jan 2026 A vs F '!B9 -> 144779.5 | C3: 146831.05 | D3: =B3-C3 -> -2051.55 | E3: =IFERROR(B3/C3-1, 0) -> -0.013972181 | F3: {=_xlfn.IFS(D3<0, "U", D3>0, "F", D3=0, "-")} -> U
A4: + New MRR | B4: 6120 | C4: 4000 | D4: =B4-C4 -> 2120 | E4: =IFERROR(B4/C4-1, 0) -> 0.53 | F4: {=_xlfn.IFS(D4<0, "U", D4>0, "F", D4=0, "-")} -> F
A5: + Expansion MRR | B5: 0 | C5: ='2026 Forecast'!B9/3 -> 715.3475 | D5: =B5-C5 -> -715.3475 | E5: =IFERROR(B5/C5-1, 0) -> -1 | F5: {=_xlfn.IFS(D5<0, "U", D5>0, "F", D5=0, "-")} -> U
A6: - Contraction MRR | B6: 0 | C6: 0 | D6: =B6-C6 -> 0 | E6: =IFERROR(B6/C6-1, 0) -> 0 | F6: {=_xlfn.IFS(D6<0, "U", D6>0, "F", D6=0, "-")} -> -
A7: − Churned MRR | B7: 594 | C7: ='2026 Forecast'!B10/3 -> 953.79667 | D7: =C7-B7 -> 359.79667 | E7: =IFERROR(B7/C7-1, 0) -> -0.37722575 | F7: {=_xlfn.IFS(D7>0, "F", D7<0, "U", D7=0, "-")} -> F
A8: Net New MRR | B8: =B4+B5-B7 -> 5526 | C8: =C4+C5-C7 -> 3761.5508 | D8: =B8-C8 -> 1764.4492 | E8: =B8/C8-1 -> 0.46907492 | F8: {=_xlfn.IFS(D8<0, "U", D8>0, "F", D8=0, "-")} -> F
A9: Closing MRR | B9: =B3+B4+B5-B7 -> 150305.5 | C9: =C3+C8 -> 150592.6 | D9: =B9-C9 -> -287.10083 | E9: =B9/C9-1 -> -0.0019064737 | F9: {=_xlfn.IFS(D9<0, "U", D9>0, "F", D9=0, "-")} -> U
A10: Closing ARR | B10: =B9*12 -> 1803666 | C10: =C9*12 -> 1807111.2 | D10: =B10-C10 -> -3445.21 | E10: =B10/C10-1 -> -0.0019064737 | F10: {=_xlfn.IFS(D10<0, "U", D10>0, "F", D10=0, "-")} -> U
A12: P&L
A13: Metric | B13: Actual - Feb 26 | C13: Forecast - Feb 26 | D13: $ Variance | E13: % Variance | F13: F/U
A14: Revenue | B14: =B9 -> 150305.5 | C14: =C9 -> 150592.6 | D14: =B14-C14 -> -287.10083 | E14: =B14/C14-1 -> -0.0019064737 | F14: {=_xlfn.IFS(D14<0, "U", D14>0, "F", D14=0, "-")} -> U | H14: → Revenue × (1 − gross margin)
A15: COGS | B15: =B14*(1-B17) -> 45091.65 | C15: =C14*0.3 -> 45177.78 | D15: =B15-C15 -> -86.13025 | E15: =B15/C15-1 -> -0.0019064737 | F15: {=_xlfn.IFS(D15>0, "U", D15<0, "F", D15=0, "-")} -> F | H15: → Revenue − COGS
A16: Gross Profit | B16: =B14-B15 -> 105213.85 | C16: =C14-C15 -> 105414.82 | D16: =B16-C16 -> -200.97058 | E16: =B16/C16-1 -> -0.0019064737 | F16: {=_xlfn.IFS(D16<0, "U", D16>0, "F", D16=0, "-")} -> U | H16: → GP / Revenue
A17: Gross Margin % | B17: 0.7 | C17: =C16/C14 -> 0.7 | D17: =B17-C17 -> 0 | E17: =B17/C17-1 -> 0 | F17: {=_xlfn.IFS(D17<0, "U", D17>0, "F", D17=0, "-")} -> - | H17: ← From Assumptions tab
A18: Sales & Marketing | B18: 31000 | C18: ='2026 Forecast'!B25/3 -> 30000 | D18: =B18-C18 -> 1000 | E18: =B18/C18-1 -> 0.033333333 | F18: {=_xlfn.IFS(D18<0, "U", D18>0, "F", D18=0, "-")} -> F | H18: ← From Assumptions tab
A19: Research & Development | B19: ='Forecast Assumptions'!B27/3 -> 25000 | C19: ='2026 Forecast'!B26/3 -> 25000 | D19: =B19-C19 -> 0 | E19: =B19/C19-1 -> 0 | F19: {=_xlfn.IFS(D19<0, "U", D19>0, "F", D19=0, "-")} -> - | H19: ← From Assumptions tab
A20: General & Administrative | B20: ='Forecast Assumptions'!B28/3 -> 19000 | C20: ='2026 Forecast'!B27/3 -> 19000 | D20: =B20-C20 -> 0 | E20: =B20/C20-1 -> 0 | F20: {=_xlfn.IFS(D20<0, "U", D20>0, "F", D20=0, "-")} -> - | H20: S&M + R&D + G&A
A21: Total OpEx | B21: =SUM(B18:B20) -> 75000 | C21: ='2026 Forecast'!B28/3 -> 74000 | D21: =B21-C21 -> 1000 | E21: =B21/C21-1 -> 0.013513514 | F21: {=_xlfn.IFS(D21<0, "U", D21>0, "F", D21=0, "-")} -> F | H21: → Gross Profit − Total OpEx
A22: EBITDA | B22: =B16-B21 -> 30213.85 | C22: =C16-C21 -> 31414.821 | D22: =B22-C22 -> -1200.9706 | E22: =B22/C22-1 -> -0.038229427 | F22: {=_xlfn.IFS(D22<0, "U", D22>0, "F", D22=0, "-")} -> U | H22: → EBITDA / Revenue
A23: EBITDA Margin % | B23: =B22/B14 -> 0.20101626 | C23: =C22/C14 -> 0.208608 | D23: =B23-C23 -> -0.0075917319 | E23: =B23/C23-1 -> -0.036392334 | F23: {=IFERROR(_xlfn.IFS(D23<0, "U", D23>0, "F", D23=0, "-"), "-")} -> U
A27: February 2026 — SaaS KPIs
A29: Metric | B29: Value | C29: vs Jan 2026 | D29: Notes
A30: Active Customers | B30: 41 | C30: =IFERROR(B30-_xlfn.XLOOKUP("Active Customers",'KPI Tracker'!$A$4:$A$16,'KPI Tracker'!$B$4:$B$16),"—") -> 2 | D30: From your Feb 28 SQL snapshot
A31: Active Subscriptions | B31: 53 | C31: =IFERROR(B31-_xlfn.XLOOKUP("Active Subscriptions",'KPI Tracker'!$A$4:$A$16,'KPI Tracker'!$B$4:$B$16),"—") -> — | D31: From your Feb 28 SQL snapshot
A32: ARPA | B32: =B9/B30 -> 3665.9878 | C32: =IFERROR(B32-_xlfn.XLOOKUP("ARPA",'KPI Tracker'!$A$4:$A$16,'KPI Tracker'!$B$4:$B$16),"—") -> -46.307067 | D32: Excel 04
A33: Gross Margin | B33: =B17 -> 0.7 | C33: =IFERROR(B33-_xlfn.XLOOKUP("Gross Margin",'KPI Tracker'!$A$4:$A$16,'KPI Tracker'!$B$4:$B$16),"—") -> 0 | D33: Already in your P&L
A34: GRR | B34: =Retention!AA6 -> 0.9961082 | C34: =IFERROR(B34-_xlfn.XLOOKUP("GRR",'KPI Tracker'!$A$4:$A$16,'KPI Tracker'!$B$4:$B$16),"—") -> -0.0038918026 | D34: Excel 03
A35: NRR | B35: =Retention!AA7 -> 0.9961082 | C35: =IFERROR(B35-_xlfn.XLOOKUP("NRR",'KPI Tracker'!$A$4:$A$16,'KPI Tracker'!$B$4:$B$16),"—") -> -0.0038918026 | D35: Excel 03
A36: Quick Ratio | B36: =IFERROR(IF((B6+B7)=0,"N/A — no losses",(B4+B5)/(B6+B7)),"N/A") -> 10.30303 | C36: =IFERROR(IF(ISNUMBER(B36),B36-_xlfn.XLOOKUP("Quick Ratio",'KPI Tracker'!$A$4:$A$16,'KPI Tracker'!$B$4:$B$16),"—"),"—") -> 10.30303 | D36: Excel 02
A37: S&M (actual) | B37: =B18 -> 31000 | C37: =IFERROR(B37-_xlfn.XLOOKUP("S&M (actual)",'KPI Tracker'!$A$4:$A$16,'KPI Tracker'!$B$4:$B$16),"—") -> 1000 | D37: From Lisa's monthly close message
A38: CAC — this month | B38: =IFERROR(IF(B39=0,"—",B37/B39),"—") -> 15500 | C38: =IFERROR(IF(ISNUMBER(B38),B38-_xlfn.XLOOKUP("CAC — monthly",'KPI Tracker'!$A$4:$A$16,'KPI Tracker'!$B$4:$B$16),"—"),"—") -> -14500 | D38: Excel 04 — S&M ÷ new customers acquired this month
A39: New customers acquired | B39: 2 | C39: — | D39: Enter count of new logos signed in Feb
A40: CAC — Q1 to date | B40: =IFERROR(IF(('Jan 2026 A vs F '!B46/'Jan 2026 A vs F '!B47+B39)=0,"—",('Jan 2026 A vs F '!B46+B37)/('Jan 2026 A vs F '!B46/'Jan 2026 A vs F '!B47+B39)),"—") -> 20333.333 | C40: — | D40: Cumulative S&M ÷ cumulative new customers in Q1 so far
A41: LTV | B41: — | C41: — | D41: Quarterly metric — calculated at Q1 close
A42: LTV:CAC | B42: — | C42: — | D42: Quarterly metric — calculated at Q1 close
A43: CAC Payback | B43: — | C43: — | D43: Quarterly metric — calculated at Q1 close
A44: * Monthly CAC note:
A45: Monthly CAC is noisy with small customer counts. Q1 CAC will be the definitive figure after March closes using total Q1 S&M ÷ total Q1 new customers.
...

Sheet Mar 2026 A vs F
A1: MRR Waterfall | H1: MONTHLY CONFIG
A2: Metric | B2: ="Actual - "&TEXT($I$2,"mmm yy") -> Actual - Mar 26 | C2: Forecast - Mar 26 | D2: $ Variance | E2: % Variance | F2: F/U | H2: Current month: | I2: 46082 | J2: ← change this when creating a new month
A3: Opening MRR | B3: =INDEX(Actuals!$B$2:$Y$2,MATCH($I$2,Actuals!$B$1:$Y$1,0)) -> 150305.5 | C3: 150592.6 | D3: =B3-C3 -> -287.1 | E3: =IFERROR(B3/C3-1, 0) -> -0.0019064682 | F3: {=_xlfn.IFS(D3<0, "U", D3>0, "F", D3=0, "-")} -> U | H3: Prior month tab: | I3: Feb 2026 A vs F | J3: ← change this when creating a new month
A4: + New MRR | B4: =INDEX(Actuals!$B$3:$Y$3,MATCH($I$2,Actuals!$B$1:$Y$1,0)) -> 3000 | C4: 4000 | D4: =B4-C4 -> -1000 | E4: =IFERROR(B4/C4-1, 0) -> -0.25 | F4: {=_xlfn.IFS(D4<0, "U", D4>0, "F", D4=0, "-")} -> U | H4: Month-end date: | I4: =EOMONTH(I2,0) -> 46112 | J4: ← formula: last day of current month
A5: + Expansion MRR | B5: =INDEX(Actuals!$B$4:$Y$4,MATCH($I$2,Actuals!$B$1:$Y$1,0)) -> 380 | C5: ='2026 Forecast'!B9/3 -> 715.3475 | D5: =B5-C5 -> -335.3475 | E5: =IFERROR(B5/C5-1, 0) -> -0.46878964 | F5: {=_xlfn.IFS(D5<0, "U", D5>0, "F", D5=0, "-")} -> U
A6: - Contraction MRR | B6: 0 | C6: 0 | D6: =B6-C6 -> 0 | E6: =IFERROR(B6/C6-1, 0) -> 0 | F6: {=_xlfn.IFS(D6<0, "U", D6>0, "F", D6=0, "-")} -> -
A7: − Churned MRR | B7: =INDEX(Actuals!$B$5:$Y$5,MATCH($I$2,Actuals!$B$1:$Y$1,0)) -> 0 | C7: ='2026 Forecast'!B10/3 -> 953.79667 | D7: =C7-B7 -> 953.79667 | E7: =IFERROR(B7/C7-1, 0) -> -1 | F7: {=_xlfn.IFS(D7>0, "F", D7<0, "U", D7=0, "-")} -> F | J7: =INDEX(Actuals!$B$7:$Y$7,MATCH($I$2,Actuals!$B$1:$Y$1,0)) -> 29000
A8: Net New MRR | B8: =B4+B5-B7 -> 3380 | C8: =C4+C5-C7 -> 3761.5508 | D8: =B8-C8 -> -381.55083 | E8: =B8/C8-1 -> -0.10143445 | F8: {=_xlfn.IFS(D8<0, "U", D8>0, "F", D8=0, "-")} -> U
A9: Closing MRR | B9: =B3+B4+B5-B7 -> 153685.5 | C9: =C3+C8 -> 154354.15 | D9: =B9-C9 -> -668.65083 | E9: =B9/C9-1 -> -0.0043319265 | F9: {=_xlfn.IFS(D9<0, "U", D9>0, "F", D9=0, "-")} -> U
A10: Closing ARR | B10: =B9*12 -> 1844226 | C10: =C9*12 -> 1852249.8 | D10: =B10-C10 -> -8023.81 | E10: =B10/C10-1 -> -0.0043319265 | F10: {=_xlfn.IFS(D10<0, "U", D10>0, "F", D10=0, "-")} -> U
A12: P&L
A13: Metric | B13: ="Actual - "&TEXT($I$2,"mmm yy") -> Actual - Mar 26 | C13: Forecast - Mar 26 | D13: $ Variance | E13: % Variance | F13: F/U
A14: Revenue | B14: =B9 -> 153685.5 | C14: =C9 -> 154354.15 | D14: =B14-C14 -> -668.65083 | E14: =B14/C14-1 -> -0.0043319265 | F14: {=_xlfn.IFS(D14<0, "U", D14>0, "F", D14=0, "-")} -> U | H14: → Revenue × (1 − gross margin)
A15: COGS | B15: =B14*(1-B17) -> 46105.65 | C15: =C14*0.3 -> 46306.245 | D15: =B15-C15 -> -200.59525 | E15: =B15/C15-1 -> -0.0043319265 | F15: {=_xlfn.IFS(D15>0, "U", D15<0, "F", D15=0, "-")} -> F | H15: → Revenue − COGS
A16: Gross Profit | B16: =B14-B15 -> 107579.85 | C16: =C14-C15 -> 108047.91 | D16: =B16-C16 -> -468.05558 | E16: =B16/C16-1 -> -0.0043319265 | F16: {=_xlfn.IFS(D16<0, "U", D16>0, "F", D16=0, "-")} -> U | H16: → GP / Revenue
A17: Gross Margin % | B17: 0.7 | C17: =C16/C14 -> 0.7 | D17: =B17-C17 -> 0 | E17: =B17/C17-1 -> 0 | F17: {=_xlfn.IFS(D17<0, "U", D17>0, "F", D17=0, "-")} -> - | H17: ← From Assumptions tab
A18: Sales & Marketing | B18: =INDEX(Actuals!$B$7:$Y$7,MATCH($I$2,Actuals!$B$1:$Y$1,0)) -> 29000 | C18: ='2026 Forecast'!B25/3 -> 30000 | D18: =B18-C18 -> -1000 | E18: =B18/C18-1 -> -0.033333333 | F18: {=_xlfn.IFS(D18<0, "U", D18>0, "F", D18=0, "-")} -> U | H18: ← From Assumptions tab
A19: Research & Development | B19: =INDEX(Actuals!$B$8:$Y$8,MATCH($I$2,Actuals!$B$1:$Y$1,0)) -> 22000 | C19: ='2026 Forecast'!B26/3 -> 25000 | D19: =B19-C19 -> -3000 | E19: =B19/C19-1 -> -0.12 | F19: {=_xlfn.IFS(D19<0, "U", D19>0, "F", D19=0, "-")} -> U | H19: ← From Assumptions tab
A20: General & Administrative | B20: =INDEX(Actuals!$B$9:$Y$9,MATCH($I$2,Actuals!$B$1:$Y$1,0)) -> 22000 | C20: ='2026 Forecast'!B27/3 -> 19000 | D20: =B20-C20 -> 3000 | E20: =B20/C20-1 -> 0.15789474 | F20: {=_xlfn.IFS(D20<0, "U", D20>0, "F", D20=0, "-")} -> F | H20: S&M + R&D + G&A
A21: Total OpEx | B21: =SUM(B18:B20) -> 73000 | C21: ='2026 Forecast'!B28/3 -> 74000 | D21: =B21-C21 -> -1000 | E21: =B21/C21-1 -> -0.013513514 | F21: {=_xlfn.IFS(D21<0, "U", D21>0, "F", D21=0, "-")} -> U | H21: → Gross Profit − Total OpEx
A22: EBITDA | B22: =B16-B21 -> 34579.85 | C22: =C16-C21 -> 34047.906 | D22: =B22-C22 -> 531.94442 | E22: =B22/C22-1 -> 0.015623411 | F22: {=_xlfn.IFS(D22<0, "U", D22>0, "F", D22=0, "-")} -> F | H22: → EBITDA / Revenue
A23: EBITDA Margin % | B23: =B22/B14 -> 0.22500399 | C23: =C22/C14 -> 0.22058303 | D23: =B23-C23 -> 0.00442096 | E23: =B23/C23-1 -> 0.020042158 | F23: {=IFERROR(_xlfn.IFS(D23<0, "U", D23>0, "F", D23=0, "-"), "-")} -> F
A27: March 2026 — SaaS KPIs
A29: Metric | B29: Value | C29: ="vs "&TEXT(EOMONTH($I$2,-1),"mmm yyyy") -> vs Feb 2026 | D29: Notes
A30: Active Customers | B30: =INDEX(Actuals!$B$15:$Y$15,MATCH($I$2,Actuals!$B$1:$Y$1,0)) -> 42 | C30: =IFERROR(B30-_xlfn.XLOOKUP("Active Customers",'KPI Tracker'!$A$4:$A$16,'KPI Tracker'!$C$4:$C$16),"—") -> 1 | D30: From your Mar 31SQL snapshot
A31: Active Subscriptions | B31: =INDEX(Actuals!$B$16:$Y$16,MATCH($I$2,Actuals!$B$1:$Y$1,0)) -> 54 | C31: =B31-INDEX(Actuals!$B$16:$Y$16,MATCH(DATE(YEAR($I$2),MONTH($I$2)-1,1),Actuals!$B$1:$Y$1,0)) -> 1 | D31: From your Mar 31 SQL snapshot
A32: ARPA | B32: =B9/B30 -> 3659.1786 | C32: =IFERROR(B32-INDEX(Actuals!$B$6:$Y$6,MATCH(DATE(YEAR($I$2),MONTH($I$2)-1,1),Actuals!$B$1:$Y$1,0))/INDEX(Actuals!$B$15:$Y$15,MATCH(DATE(YEAR($I$2),MONTH($I$2)-1,1),Actuals!$B$1:$Y$1,0)),"—") -> -6.8092334 | D32: Excel 04
A33: Gross Margin | B33: =B17 -> 0.7 | C33: =0 -> 0 | D33: Already in your P&L
A34: GRR | B34: =INDEX(Retention!$B$6:$AY$6,MATCH($I$2,Retention!$B$4:$AY$4,0)) -> 1 | C34: =B34-INDEX(Retention!$B$6:$AY$6,MATCH(DATE(YEAR($I$2),MONTH($I$2)-1,1),Retention!$B$4:$AY$4,0)) -> 0.0038918026 | D34: Excel 03
A35: NRR | B35: =INDEX(Retention!$B$7:$AY$7,MATCH($I$2,Retention!$B$4:$AY$4,0)) -> 1.0024027 | C35: =B35-INDEX(Retention!$B$7:$AY$7,MATCH(DATE(YEAR($I$2),MONTH($I$2)-1,1),Retention!$B$4:$AY$4,0)) -> 0.0062945164 | D35: Excel 03
A36: Quick Ratio | B36: =IFERROR(IF((B6+B7)=0,"N/A — no losses",(B4+B5)/(B6+B7)),"N/A") -> N/A — no losses | C36: =IFERROR(IF(ISNUMBER(B36),B36-_xlfn.XLOOKUP("Quick Ratio",'KPI Tracker'!$A$4:$A$16,'KPI Tracker'!$B$4:$B$16),"—"),"—") -> — | D36: Excel 02
A37: S&M (actual) | B37: =B18 -> 29000 | C37: =B37-INDEX(Actuals!$B$7:$Y$7,MATCH(DATE(YEAR($I$2),MONTH($I$2)-1,1),Actuals!$B$1:$Y$1,0)) -> -2000 | D37: From Lisa's monthly close message
A38: CAC — this month | B38: =IFERROR(IF(B39=0,"—",B37/B39),"—") -> 14500 | C38: =IFERROR(B38-INDEX(Actuals!$B$7:$Y$7,MATCH(DATE(YEAR($I$2),MONTH($I$2)-1,1),Actuals!$B$1:$Y$1,0))/INDEX(Actuals!$B$14:$Y$14,MATCH(DATE(YEAR($I$2),MONTH($I$2)-1,1),Actuals!$B$1:$Y$1,0)),"—") -> -1000 | D38: Excel 04 — S&M ÷ new customers acquired this month
A39: New customers acquired | B39: =INDEX(Actuals!$B$14:$Y$14,MATCH($I$2,Actuals!$B$1:$Y$1,0)) -> 2 | C39: — | D39: Enter count of new logos signed in Mar
A40: CAC — Q1 to date | B40: =IFERROR(IF(('Jan 2026 A vs F '!B46/'Jan 2026 A vs F '!B47+'Feb 2026 A vs F'!B39+B39)=0,"—",('Jan 2026 A vs F '!B46+'Feb 2026 A vs F'!B37+B37)/('Jan 2026 A vs F '!B46/'Jan 2026 A vs F '!B47+'Feb 2026 A vs F'!B39+B39)),"—") -> 18000 | C40: — | D40: Cumulative S&M ÷ cumulative new customers in Q1 so far
A41: LTV | B41: — | C41: — | D41: Quarterly metric — calculated at Q1 close
A42: LTV:CAC | B42: — | C42: — | D42: Quarterly metric — calculated at Q1 close
A43: CAC Payback | B43: — | C43: — | D43: Quarterly metric — calculated at Q1 close
A44: * Monthly CAC note:
A45: Monthly CAC is noisy with small customer counts. Q1 CAC will be the definitive figure after March closes using total Q1 S&M ÷ total Q1 new customers.
...

Sheet 2026 Forecast
A2: Build formulas referencing the Assumptions tab. No hardcoded numbers.
A3: Black font = formulas. Green font = cross-tab references.
A5: MRR WATERFALL
A6: Metric | B6: Q1 2026 | C6: Q2 2026 | D6: Q3 2026 | E6: Q4 2026 | G6: FY 2026 | I6: Formula hints
A7: Opening MRR | B7: ='Forecast Assumptions'!B6 -> 143069.5 | C7: =B12 -> 154354.15 | D7: =C12 -> 172782.38 | E7: =D12 -> 200718.47 | G7: =B7 -> 143069.5 | I7: Q1 = Opening from Assumptions. Q2+ = prior Q closing.
A8: + New MRR | B8: ='Forecast Assumptions'!B12*'Forecast Assumptions'!B13 -> 12000 | C8: ='Forecast Assumptions'!C12*'Forecast Assumptions'!C13 -> 19200 | D8: ='Forecast Assumptions'!D12*'Forecast Assumptions'!D13 -> 28800 | E8: ='Forecast Assumptions'!E12*'Forecast Assumptions'!E13 -> 30600 | G8: =B8+C8+D8+E8 -> 90600 | I8: → New customers × Avg MRR per new customer
A9: + Expansion MRR | B9: =B7*'Forecast Assumptions'!B14 -> 2146.0425 | C9: =C7*'Forecast Assumptions'!C14 -> 2315.3123 | D9: =D7*'Forecast Assumptions'!D14 -> 2591.7357 | E9: =E7*'Forecast Assumptions'!E14 -> 3010.777 | G9: =B9+C9+D9+E9 -> 10063.868 | I9: → Opening MRR × quarterly expansion rate
A10: − Churned MRR | B10: =B7*'Forecast Assumptions'!B15 -> 2861.39 | C10: =C7*'Forecast Assumptions'!C15 -> 3087.0831 | D10: =D7*'Forecast Assumptions'!D15 -> 3455.6476 | E10: =E7*'Forecast Assumptions'!E15 -> 4014.3694 | G10: =B10+C10+D10+E10 -> 13418.49 | I10: → Opening MRR × quarterly churn rate
A11: Net New MRR | B11: =B8+B9-B10 -> 11284.653 | C11: =C8+C9-C10 -> 18428.229 | D11: =D8+D9-D10 -> 27936.088 | E11: =E8+E9-E10 -> 29596.408 | G11: =G8+G9-G10 -> 87245.377 | I11: → New + Expansion − Churned
A12: Closing MRR | B12: =B7+B11 -> 154354.15 | C12: =C7+C11 -> 172782.38 | D12: =D7+D11 -> 200718.47 | E12: =E7+E11 -> 230314.88 | G12: =E12 -> 230314.88 | I12: → Opening + Net New
A13: Closing ARR | B13: =B12*12 -> 1852249.8 | C13: =C12*12 -> 2073388.6 | D13: =D12*12 -> 2408621.6 | E13: =E12*12 -> 2763778.5 | G13: =G12*12 -> 2763778.5 | I13: → Closing MRR × 12
G14: ← Opening = Q1
G15: ← Sums for flows
G16: ← Q4 closing for balances
A18: PROFIT & LOSS
A19: Metric | B19: Q1 2026 | C19: Q2 2026 | D19: Q3 2026 | E19: Q4 2026 | G19: FY 2026
A20: Revenue | B20: =B12*3 -> 463062.46 | C20: =C12*3 -> 518347.15 | D20: =D12*3 -> 602155.41 | E20: =E12*3 -> 690944.63 | G20: =B20+C20+D20+E20 -> 2274509.6 | I20: → Closing MRR × 3
A21: COGS | B21: =B20*(1-'Forecast Assumptions'!B22) -> 138918.74 | C21: =C20*(1-'Forecast Assumptions'!B22) -> 155504.14 | D21: =D20*(1-'Forecast Assumptions'!B22) -> 180646.62 | E21: =E20*(1-'Forecast Assumptions'!B22) -> 207283.39 | G21: =B21+C21+D21+E21 -> 682352.89 | I21: → Revenue × (1 − gross margin)
A22: Gross Profit | B22: =B20-B21 -> 324143.72 | C22: =C20-C21 -> 362843 | D22: =D20-D21 -> 421508.79 | E22: =E20-E21 -> 483661.24 | G22: =B22+C22+D22+E22 -> 1592156.8 | I22: → Revenue − COGS
A23: Gross Margin % | B23: =B22/B20 -> 0.7 | C23: =C22/C20 -> 0.7 | D23: =D22/D20 -> 0.7 | E23: =E22/E20 -> 0.7 | G23: =G22/G20 -> 0.7 | I23: → GP / Revenue
A25: Sales & Marketing | B25: ='Forecast Assumptions'!B26 -> 90000 | C25: ='Forecast Assumptions'!C26 -> 90000 | D25: ='Forecast Assumptions'!D26 -> 108000 | E25: ='Forecast Assumptions'!E26 -> 108000 | G25: =B25+C25+D25+E25 -> 396000 | I25: ← From Assumptions tab
A26: Research & Development | B26: ='Forecast Assumptions'!B27 -> 75000 | C26: ='Forecast Assumptions'!C27 -> 75000 | D26: ='Forecast Assumptions'!D27 -> 75000 | E26: ='Forecast Assumptions'!E27 -> 75000 | G26: =B26+C26+D26+E26 -> 300000 | I26: ← From Assumptions tab
A27: General & Administrative | B27: ='Forecast Assumptions'!B28 -> 57000 | C27: ='Forecast Assumptions'!C28 -> 57000 | D27: ='Forecast Assumptions'!D28 -> 57000 | E27: ='Forecast Assumptions'!E28 -> 57000 | G27: =B27+C27+D27+E27 -> 228000 | I27: ← From Assumptions tab
A28: Total OpEx | B28: =B25+B26+B27 -> 222000 | C28: =C25+C26+C27 -> 222000 | D28: =D25+D26+D27 -> 240000 | E28: =E25+E26+E27 -> 240000 | G28: =G25+G26+G27 -> 924000 | I28: S&M + R&D + G&A
A30: EBITDA | B30: =B22-B28 -> 102143.72 | C30: =C22-C28 -> 140843 | D30: =D22-D28 -> 181508.79 | E30: =E22-E28 -> 243661.24 | G30: =B30+C30+D30+E30 -> 668156.75 | I30: → Gross Profit − Total OpEx
A31: EBITDA Margin % | B31: =B30/B20 -> 0.22058303 | C31: =C30/C20 -> 0.27171559 | D31: =D30/D20 -> 0.3014318 | E31: =E30/E20 -> 0.35264945 | G31: =G30/G20 -> 0.29375859 | I31: → EBITDA / Revenue
A33: KEY METRICS
A34: Dec 2026 MRR | B34: =E12 -> 230314.88 | I34: → Q4 Closing MRR
A35: Dec 2026 ARR | B35: =B34*12 -> 2763778.5 | I35: → Dec MRR × 12
A36: FY Revenue | B36: =G20 -> 2274509.6 | I36: → Sum of quarterly revenue
A37: MRR Growth % | B37: =(E12-B7)/B7 -> 0.60981116 | I37: → (Closing − Opening) / Opening
A38: New Customers (FY) | B38: ='Forecast Assumptions'!B12+'Forecast Assumptions'!C12+'Forecast Assumptions'!D12+'Forecast Assumptions'!E12 -> 28 | I38: → Sum from Assumptions
A39: Blended CAC | B39: =G25/B38 -> 14142.857 | I39: Total S&M / New customers
A40: CMGR | B40: =(E12/B7)^(1/12)-1 -> 0.040474029 | I40: → (Dec MRR / Jan Opening MRR)^(1/12) − 1 [monthly rate, standard]
A43: SELF-CHECK VALUES | E43: Assumes opening MRR = $143,069.50. Our opening is $150,918.50 (Waterfall tab, Dec 2025 closing). Same model logic, different starting MRR.
A44: Check | B44: Expected | C44: Your Value | D44: Match?
A45: Q1 Closing MRR | B45: 154354.15 | C45: =B12 -> 154354.15 | D45: =IF(ROUND(C45,2)=ROUND(B45,2),"✓","✗ diff: "&TEXT(C45-B45,"$#,##0.00")) -> ✓
A46: Q2 Closing MRR | B46: 172782.38 | C46: =C12 -> 172782.38 | D46: =IF(ROUND(C46,2)=ROUND(B46,2),"✓","✗ diff: "&TEXT(C46-B46,"$#,##0.00")) -> ✓
A47: Q3 Closing MRR | B47: 200718.47 | C47: =D12 -> 200718.47 | D47: =IF(ROUND(C47,2)=ROUND(B47,2),"✓","✗ diff: "&TEXT(C47-B47,"$#,##0.00")) -> ✓
A48: Q4 Closing MRR | B48: 230314.88 | C48: =E12 -> 230314.88 | D48: =IF(ROUND(C48,2)=ROUND(B48,2),"✓","✗ diff: "&TEXT(C48-B48,"$#,##0.00")) -> ✓
...

Sheet KPI Tracker
A1: KPI Tracker
A3: Metric | B3: Jan 2026 | C3: Feb 2026 | D3: Mar 2026 | E3: Q1 2026
A4: Closing MRR | B4: ='Jan 2026 A vs F '!B9 -> 144779.5 | C4: ='Feb 2026 A vs F'!B9 -> 150305.5 | D4: ='Mar 2026 A vs F'!B9 -> 153685.5 | E4: ='Mar 2026 A vs F'!B75 -> 153685.5
