Workbook

Sheet Raw Snapshot
A1: subscription_id | B1: customer_id | C1: company_name | D1: account_owner | E1: region | F1: plan_name | G1: billing_cycle | H1: mrr
A2: SUB025 | B2: CUST025 | C2: Montreal Manufacturing Pro | D2: Sarah Chen | E2: Eastern Canada | F2: Analytics Enterprise | G2: Annual | H2: 6840
A3: SUB031 | B3: CUST031 | C3: Toronto Digital Media | D3: James Wilson | E3: Eastern Canada | F3: Platform Suite | G3: Annual | H3: 6750
A4: SUB018 | B4: CUST018 | C4: Vancouver FinTech Labs | D4: Michael Rodriguez | E4: Western Canada | F4: Analytics Enterprise | G4: Monthly | H4: 6300
A5: SUB016 | B5: CUST016 | C5: Quebec Manufacturing | D5: Sarah Chen | E5: Eastern Canada | F5: Platform Suite | G5: Annual | H5: 6300
A6: SUB053 | B6: CUST027 | C6: Pacific Finance Corp | D6: Michael Rodriguez | E6: Western Canada | F6: Analytics Enterprise | G6: Monthly | H6: 5580
A7: SUB006 | B7: CUST006 | C7: Northern Retail Solutions | D7: Michael Rodriguez | E7: Western Canada | F7: Analytics Enterprise | G7: Annual | H7: 5580
A8: SUB009 | B8: CUST009 | C8: West Coast Logistics | D8: Michael Rodriguez | E8: Western Canada | F8: Platform Suite | G8: Annual | H8: 5400
A9: SUB037 | B9: CUST037 | C9: Maritime SaaS Ventures | D9: Sarah Chen | E9: Eastern Canada | F9: Platform Suite | G9: Monthly | H9: 5250
A10: SUB022 | B10: CUST022 | C10: Toronto Tech Ventures | D10: James Wilson | E10: Eastern Canada | F10: Platform Suite | G10: Monthly | H10: 4950
A11: SUB032 | B11: CUST032 | C11: BC Manufacturing Systems | D11: Michael Rodriguez | E11: Western Canada | F11: Analytics Enterprise | G11: Monthly | H11: 4680
A12: SUB057 | B12: CUST021 | C12: Calgary Commerce Solutions | D12: Michael Rodriguez | E12: Western Canada | F12: Platform Suite | G12: Monthly | H12: 4200
A13: SUB048 | B13: CUST025 | C13: Montreal Manufacturing Pro | D13: Sarah Chen | E13: Eastern Canada | F13: Sales Hub | G13: Monthly | H13: 3960
... A52: SUB017 | B52: CUST017 | C52: Capital Education Tech | D52: James Wilson | E52: Eastern Canada | F52: Analytics Starter | G52: Monthly | H52: 540

Sheet Raw Events
A1: event_id | B1: subscription_id | C1: customer_id | D1: company_name | E1: region | F1: month | G1: event_date | H1: event_date | I1: event_type | J1: old_value | K1: new_value | L1: field_changed | M1: reason | N1: plan_name | O1: billing_cycle | P1: price_per_seat | Q1: discount_percent
A2: EVT001 | B2: SUB001 | C2: CUST001 | D2: TechVision Solutions | E2: Eastern Canada | F2: 45292 | G2: 45299 | H2: 45299 | I2: created | N2: Analytics Growth | O2: Monthly | P2: 95 | Q2: 0
A3: EVT002 | B3: SUB002 | C3: CUST002 | D3: Pacific Analytics Inc | E3: Western Canada | F3: 45292 | G3: 45313 | H3: 45313 | I3: created | N3: Platform Suite | O3: Annual | P3: 1800 | Q3: 0
A4: EVT003 | B4: SUB003 | C4: CUST003 | D4: Maple Healthcare Systems | E4: Eastern Canada | F4: 45323 | G4: 45327 | H4: 45327 | I4: created | N4: Marketing Pro | O4: Monthly | P4: 85 | Q4: 0
A5: EVT004 | B5: SUB004 | C5: CUST004 | D5: Prairie Commerce Group | E5: Western Canada | F5: 45323 | G5: 45341 | H5: 45341 | I5: created | N5: Sales Hub | O5: Monthly | P5: 110 | Q5: 0
A6: EVT005 | B6: SUB055 | C6: CUST004 | D6: Prairie Commerce Group | E6: Western Canada | F6: 45323 | G6: 45341 | H6: 45341 | I6: created | N6: Analytics Enterprise | O6: Monthly | P6: 180 | Q6: 0
A7: EVT006 | B7: SUB005 | C7: CUST005 | D7: Atlantic Media Corp | E7: Eastern Canada | F7: 45352 | G7: 45355 | H7: 45355 | I7: created | N7: Analytics Starter | O7: Monthly | P7: 45 | Q7: 0
A8: EVT007 | B8: SUB006 | C8: CUST006 | D8: Northern Retail Solutions | E8: Western Canada | F8: 45352 | G8: 45369 | H8: 45369 | I8: created | N8: Analytics Enterprise | O8: Annual | P8: 2160 | Q8: 0
A9: EVT008 | B9: SUB007 | C9: CUST007 | D9: Ontario Manufacturing Tech | E9: Eastern Canada | F9: 45383 | G9: 45383 | H9: 45383 | I9: created | N9: Marketing Pro | O9: Monthly | P9: 85 | Q9: 0
A10: EVT009 | B10: SUB050 | C10: CUST007 | D10: Ontario Manufacturing Tech | E10: Eastern Canada | F10: 45383 | G10: 45383 | H10: 45383 | I10: created | N10: Analytics Starter | O10: Monthly | P10: 45 | Q10: 12
A11: EVT010 | B11: SUB008 | C11: CUST008 | D11: Quantum Education Platform | E11: Eastern Canada | F11: 45383 | G11: 45397 | H11: 45397 | I11: created | N11: Analytics Growth | O11: Monthly | P11: 95 | Q11: 0
A12: EVT011 | B12: SUB009 | C12: CUST009 | D12: West Coast Logistics | E12: Western Canada | F12: 45383 | G12: 45411 | H12: 45411 | I12: created | N12: Platform Suite | O12: Annual | P12: 1800 | Q12: 0
A13: EVT012 | B13: SUB010 | C13: CUST010 | D13: Montreal Finance Hub | E13: Eastern Canada | F13: 45413 | G13: 45425 | H13: 45425 | I13: created | N13: Analytics Starter | O13: Monthly | P13: 45 | Q13: 0
... A23: EVT022 | B23: SUB017 | C23: CUST017 | D23: Capital Education Tech | E23: Eastern Canada | F23: 45505 | G23: 45523 | H23: 45523 | I23: created | N23: Analytics Starter | O23: Monthly | P23: 45 | Q23: 0
A24: EVT023 | B24: SUB001 | C24: CUST001 | D24: TechVision Solutions | E24: Eastern Canada | F24: 45505 | G24: 45531 | H24: 45531 | I24: cancelled | J24: active | K24: churned | L24: status | M24: Missing features | N24: Analytics Growth | O24: Monthly | P24: 95 | Q24: 0
A25: EVT024 | B25: SUB018 | C25: CUST018 | D25: Vancouver FinTech Labs | E25: Western Canada | F25: 45536 | G25: 45537 | H25: 45537 | I25: created | N25: Analytics Enterprise | O25: Monthly | P25: 180 | Q25: 0
A26: EVT025 | B26: SUB042 | C26: CUST003 | D26: Maple Healthcare Systems | E26: Eastern Canada | F26: 45536 | G26: 45545 | H26: 45545 | I26: created | N26: Sales Hub | O26: Monthly | P26: 110 | Q26: 0
A27: EVT026 | B27: SUB019 | C27: CUST019 | D27: Central Healthcare Partners | E27: Central Canada | F27: 45536 | G27: 45551 | H27: 45551 | I27: created | N27: Marketing Pro | O27: Monthly | P27: 85 | Q27: 0
A28: EVT027 | B28: SUB060 | C28: CUST019 | D28: Central Healthcare Partners | E28: Central Canada | F28: 45536 | G28: 45551 | H28: 45551 | I28: created | N28: Sales Hub | O28: Monthly | P28: 110 | Q28: 0
A29: EVT028 | B29: SUB020 | C29: CUST020 | D29: Atlantic SaaS Systems | E29: Eastern Canada | F29: 45536 | G29: 45565 | H29: 45565 | I29: created | N29: Sales Hub | O29: Monthly | P29: 110 | Q29: 0
A30: EVT029 | B30: SUB043 | C30: CUST006 | D30: Northern Retail Solutions | E30: Western Canada | F30: 45566 | G30: 45570 | H30: 45570 | I30: created | N30: Marketing Pro | O30: Monthly | P30: 85 | Q30: 0
A31: EVT030 | B31: SUB021 | C31: CUST021 | D31: Calgary Commerce Solutions | E31: Western Canada | F31: 45566 | G31: 45579 | H31: 45579 | I31: created | N31: Analytics Growth | O31: Monthly | P31: 95 | Q31: 0
A32: EVT031 | B32: SUB022 | C32: CUST022 | D32: Toronto Tech Ventures | E32: Eastern Canada | F32: 45566 | G32: 45593 | H32: 45593 | I32: created | N32: Platform Suite | O32: Monthly | P32: 150 | Q32: 0
A33: EVT032 | B33: SUB059 | C33: CUST008 | D33: Quantum Education Platform | E33: Eastern Canada | F33: 45597 | G33: 45601 | H33: 45601 | I33: created | N33: Marketing Pro | O33: Monthly | P33: 85 | Q33: 0
A34: EVT033 | B34: SUB023 | C34: CUST023 | D34: Island Media Productions | E34: Eastern Canada | F34: 45597 | G34: 45607 | H34: 45607 | I34: created | N34: Analytics Starter | O34: Monthly | P34: 45 | Q34: 0
A35: EVT034 | B35: SUB005 | C35: CUST005 | D35: Atlantic Media Corp | E35: Eastern Canada | F35: 45597 | G35: 45616 | H35: 45616 | I35: cancelled | J35: active | K35: churned | L35: status | M35: Price too high | N35: Analytics Starter | O35: Monthly | P35: 45 | Q35: 0
A36: EVT035 | B36: SUB024 | C36: CUST024 | D36: Western Retail Group | E36: Western Canada | F36: 45597 | G36: 45621 | H36: 45621 | I36: created | N36: Marketing Pro | O36: Monthly | P36: 85 | Q36: 0
A37: EVT036 | B37: SUB025 | C37: CUST025 | D37: Montreal Manufacturing Pro | E37: Eastern Canada | F37: 45627 | G37: 45635 | H37: 45635 | I37: created | N37: Analytics Enterprise | O37: Annual | P37: 2160 | Q37: 0
A38: EVT037 | B38: SUB056 | C38: CUST016 | D38: Quebec Manufacturing | E38: Eastern Canada | F38: 45627 | G38: 45638 | H38: 45638 | I38: created | N38: Marketing Pro | O38: Monthly | P38: 85 | Q38: 0
A39: EVT038 | B39: SUB044 | C39: CUST009 | D39: West Coast Logistics | E39: Western Canada | F39: 45627 | G39: 45646 | H39: 45646 | I39: created | N39: Analytics Growth | O39: Monthly | P39: 95 | Q39: 0
A40: EVT039 | B40: SUB008 | C40: CUST008 | D40: Quantum Education Platform | E40: Eastern Canada | F40: 45627 | G40: 45648 | H40: 45648 | I40: cancelled | J40: active | K40: churned | L40: status | M40: Price too high | N40: Analytics Growth | O40: Monthly | P40: 95 | Q40: 0
A41: EVT040 | B41: SUB026 | C41: CUST026 | D41: Ontario Education Connect | E41: Eastern Canada | F41: 45627 | G41: 45649 | H41: 45649 | I41: created | N41: Analytics Growth | O41: Monthly | P41: 95 | Q41: 0
A42: EVT041 | B42: SUB027 | C42: CUST027 | D42: Pacific Finance Corp | E42: Western Canada | F42: 45658 | G42: 45663 | H42: 45663 | I42: created | N42: Sales Hub | O42: Monthly | P42: 110 | Q42: 0
A43: EVT042 | B43: SUB014 | C43: CUST014 | D43: Toronto Media Group | E43: Eastern Canada | F43: 45658 | G43: 45665 | H43: 45665 | I43: price_change | J43: 80 | K43: 85 | L43: price_per_seat | M43: Annual price increase applied at renewal | N43: Marketing Pro | O43: Monthly | P43: 85 | Q43: 0
A44: EVT043 | B44: SUB013 | C44: CUST013 | D44: Alberta Tech Innovators | E44: Western Canada | F44: 45658 | G44: 45672 | H44: 45672 | I44: cancelled | J44: active | K44: churned | L44: status | M44: Switched to competitor | N44: Analytics Starter | O44: Monthly | P44: 45 | Q44: 0
A45: EVT044 | B45: SUB028 | C45: CUST028 | D45: Prairie SaaS Innovations | E45: Central Canada | F45: 45658 | G45: 45677 | H45: 45677 | I45: created | N45: Analytics Starter | O45: Monthly | P45: 45 | Q45: 0
A46: EVT045 | B46: SUB054 | C46: CUST002 | D46: Pacific Analytics Inc | E46: Western Canada | F46: 45658 | G46: 45679 | H46: 45679 | I46: created | N46: Analytics Growth | O46: Annual | P46: 1140 | Q46: 5
A47: EVT046 | B47: SUB057 | C47: CUST021 | D47: Calgary Commerce Solutions | E47: Western Canada | F47: 45658 | G47: 45685 | H47: 45685 | I47: created | N47: Platform Suite | O47: Monthly | P47: 150 | Q47: 0
A48: EVT047 | B48: SUB029 | C48: CUST029 | D48: Halifax Healthcare Tech | E48: Eastern Canada | F48: 45689 | G48: 45691 | H48: 45691 | I48: created | N48: Marketing Pro | O48: Monthly | P48: 85 | Q48: 0
A49: EVT048 | B49: SUB045 | C49: CUST010 | D49: Montreal Finance Hub | E49: Eastern Canada | F49: 45689 | G49: 45696 | H49: 45696 | I49: created | N49: Marketing Pro | O49: Monthly | P49: 85 | Q49: 0
...

Sheet Raw Cash
A1: month | B1: invoice_count | C1: revenue | D1: running_total | E1: prior_month_revenue | F1: pct_change
A2: 45292 | B2: 2 | C2: 48700 | D2: 48700
A3: 45323 | B3: 4 | C3: 10185 | D3: 58885 | E3: 48700 | F3: -79.1
A4: 45352 | B4: 6 | C4: 77640 | D4: 136525 | E4: 10185 | F4: 662.3
A5: 45383 | B5: 8 | C5: 78930 | D5: 215455 | E5: 77640 | F5: 1.7
A6: 45413 | B6: 10 | C6: 17580 | D6: 233035 | E6: 78930 | F6: -77.7
A7: 45444 | B7: 13 | C7: 20595 | D7: 253630 | E7: 17580 | F7: 17.2
A8: 45474 | B8: 16 | C8: 26400 | D8: 280030 | E8: 20595 | F8: 28.2
A9: 45505 | B9: 19 | C9: 106740 | D9: 386770 | E9: 26400 | F9: 304.3
A10: 45536 | B10: 22 | C10: 42010 | D10: 428780 | E10: 106740 | F10: -60.6
A11: 45566 | B11: 25 | C11: 51390 | D11: 480170 | E11: 42010 | F11: 22.3
A12: 45597 | B12: 28 | C12: 55700 | D12: 535870 | E12: 51390 | F12: 8.4
A13: 45627 | B13: 31 | C13: 144560 | D13: 680430 | E13: 55700 | F13: 159.5
A14: 45658 | B14: 33 | C14: 139635 | D14: 820065 | E14: 144560 | F14: -3.4
... A27: 46054 | B27: 2 | C27: 2075 | D27: 2475630 | E27: 179985 | F27: -98.8

Sheet Ref
A1: plan_name | B1: monthly_price
A2: Analytics Starter | B2: 45
A3: Analytics Growth | B3: 95
A4: Analytics Enterprise | B4: 180
A5: Marketing Pro | B5: 85
A6: Sales Hub | B6: 110
A7: Platform Suite | B7: 150
A9: SaaS Growth Benchmarks
A10: Metric | B10: Threshold | C10: Label
A11: MoM Growth | B11: > 10% | C11: Exceptional (early stage)
A12: MoM Growth | B12: 5 – 10% | C12: Strong
A13: MoM Growth | B13: 2 – 5% | C13: Good (post-PMF)
A14: MoM Growth | B14: 0 – 2% | C14: Stalling
A15: MoM Growth | B15: < 0% | C15: Declining
A16: CMGR 6-month | B16: > 15% | C16: Exceptional
A17: CMGR 6-month | B17: 10 – 15% | C17: Strong
A18: CMGR 6-month | B18: 5 – 10% | C18: Good
A19: CMGR 6-month | B19: 2 – 5% | C19: Moderate
A20: CMGR 6-month | B20: < 2% | C20: Stalling
A21: Quick Ratio | B21: > 4.0 | C21: Excellent
... A24: Quick Ratio | B24: < 1.0 | C24: Shrinking

Sheet Engine
A1: event_id | B1: subscription_id | C1: customer_id | D1: company_name | E1: region | F1: month | G1: event_date | H1: event_type | I1: old_value | J1: new_value | K1: field_changed | L1: reason | M1: plan_name | N1: billing_cycle | O1: seats | P1: price_per_seat | Q1: discount_percent | R1: movement | S1: mrr_delta
A2: EVT001 | B2: SUB001 | C2: CUST001 | D2: TechVision Solutions | E2: Eastern Canada | F2: 45292 | G2: 45299 | H2: created | M2: Analytics Growth | N2: Monthly | O2: 20 | P2: 95 | Q2: 0 | R2: {=_xlfn.IFS(H2="created", "New", H2="cancelled", "Churned", AND(H2="seats_change", J2 > I2), "Expansion", AND(H2="seats_change", J2 < I2), "Contraction", AND(H2="price_change", J2 > I2), "Expansion", AND(H2="price_change", J2 < I2), "Contraction", H2="plan_upgrade", "Expansion", H2="plan_downgrade", "Contraction", H2="discount_added", "Contraction")} -> New | S2: {=_xlfn.IFS(H2="created",O2*P2*(1-Q2/100),H2="cancelled",-(O2*P2*(1-Q2/100)),H2="seats_change",(J2-I2)*P2*(1-Q2/100),H2="price_change",(J2-I2)*O2*(1-Q2/100),H2="discount_added",-(O2*P2*(J2-I2)/100),H2="plan_upgrade",O2*(_xlfn.XLOOKUP(J2,tbl_Plans[plan_name],tbl_Plans[monthly_price])-_xlfn.XLOOKUP(I2,tbl_Plans[plan_name],tbl_Plans[monthly_price]))*(1-Q2/100),H2="plan_downgrade",O2*(_xlfn.XLOOKUP(J2,tbl_Plans[plan_name],tbl_Plans[monthly_price])-_xlfn.XLOOKUP(I2,tbl_Plans[plan_name],tbl_Plans[monthly_price]))*(1-Q2/100))*IF(N2="Annual",1/12,1)} -> 1900
A3: EVT002 | B3: SUB002 | C3: CUST002 | D3: Pacific Analytics Inc | E3: Western Canada | F3: 45292 | G3: 45313 | H3: created | M3: Platform Suite | N3: Annual | O3: 26 | P3: 1800 | Q3: 0 | R3: {=_xlfn.IFS(H3="created", "New", H3="cancelled", "Churned", AND(H3="seats_change", J3 > I3), "Expansion", AND(H3="seats_change", J3 < I3), "Contraction", AND(H3="price_change", J3 > I3), "Expansion", AND(H3="price_change", J3 < I3), "Contraction", H3="plan_upgrade", "Expansion", H3="plan_downgrade", "Contraction", H3="discount_added", "Contraction")} -> New | S3: {=_xlfn.IFS(H3="created",O3*P3*(1-Q3/100),H3="cancelled",-(O3*P3*(1-Q3/100)),H3="seats_change",(J3-I3)*P3*(1-Q3/100),H3="price_change",(J3-I3)*O3*(1-Q3/100),H3="discount_added",-(O3*P3*(J3-I3)/100),H3="plan_upgrade",O3*(_xlfn.XLOOKUP(J3,tbl_Plans[plan_name],tbl_Plans[monthly_price])-_xlfn.XLOOKUP(I3,tbl_Plans[plan_name],tbl_Plans[monthly_price]))*(1-Q3/100),H3="plan_downgrade",O3*(_xlfn.XLOOKUP(J3,tbl_Plans[plan_name],tbl_Plans[monthly_price])-_xlfn.XLOOKUP(I3,tbl_Plans[plan_name],tbl_Plans[monthly_price]))*(1-Q3/100))*IF(N3="Annual",1/12,1)} -> 3900
A4: EVT003 | B4: SUB003 | C4: CUST003 | D4: Maple Healthcare Systems | E4: Eastern Canada | F4: 45323 | G4: 45327 | H4: created | M4: Marketing Pro | N4: Monthly | O4: 23 | P4: 85 | Q4: 0 | R4: {=_xlfn.IFS(H4="created", "New", H4="cancelled", "Churned", AND(H4="seats_change", J4 > I4), "Expansion", AND(H4="seats_change", J4 < I4), "Contraction", AND(H4="price_change", J4 > I4), "Expansion", AND(H4="price_change", J4 < I4), "Contraction", H4="plan_upgrade", "Expansion", H4="plan_downgrade", "Contraction", H4="discount_added", "Contraction")} -> New | S4: {=_xlfn.IFS(H4="created",O4*P4*(1-Q4/100),H4="cancelled",-(O4*P4*(1-Q4/100)),H4="seats_change",(J4-I4)*P4*(1-Q4/100),H4="price_change",(J4-I4)*O4*(1-Q4/100),H4="discount_added",-(O4*P4*(J4-I4)/100),H4="plan_upgrade",O4*(_xlfn.XLOOKUP(J4,tbl_Plans[plan_name],tbl_Plans[monthly_price])-_xlfn.XLOOKUP(I4,tbl_Plans[plan_name],tbl_Plans[monthly_price]))*(1-Q4/100),H4="plan_downgrade",O4*(_xlfn.XLOOKUP(J4,tbl_Plans[plan_name],tbl_Plans[monthly_price])-_xlfn.XLOOKUP(I4,tbl_Plans[plan_name],tbl_Plans[monthly_price]))*(1-Q4/100))*IF(N4="Annual",1/12,1)} -> 1955
A5: EVT004 | B5: SUB004 | C5: CUST004 | D5: Prairie Commerce Group | E5: Western Canada | F5: 45323 | G5: 45341 | H5: created | M5: Sales Hub | N5: Monthly | O5: 18 | P5: 110 | Q5: 0 | R5: {=_xlfn.IFS(H5="created", "New", H5="cancelled", "Churned", AND(H5="seats_change", J5 > I5), "Expansion", AND(H5="seats_change", J5 < I5), "Contraction", AND(H5="price_change", J5 > I5), "Expansion", AND(H5="price_change", J5 < I5), "Contraction", H5="plan_upgrade", "Expansion", H5="plan_downgrade", "Contraction", H5="discount_added", "Contraction")} -> New | S5: {=_xlfn.IFS(H5="created",O5*P5*(1-Q5/100),H5="cancelled",-(O5*P5*(1-Q5/100)),H5="seats_change",(J5-I5)*P5*(1-Q5/100),H5="price_change",(J5-I5)*O5*(1-Q5/100),H5="discount_added",-(O5*P5*(J5-I5)/100),H5="plan_upgrade",O5*(_xlfn.XLOOKUP(J5,tbl_Plans[plan_name],tbl_Plans[monthly_price])-_xlfn.XLOOKUP(I5,tbl_Plans[plan_name],tbl_Plans[monthly_price]))*(1-Q5/100),H5="plan_downgrade",O5*(_xlfn.XLOOKUP(J5,tbl_Plans[plan_name],tbl_Plans[monthly_price])-_xlfn.XLOOKUP(I5,tbl_Plans[plan_name],tbl_Plans[monthly_price]))*(1-Q5/100))*IF(N5="Annual",1/12,1)} -> 1980
A6: EVT005 | B6: SUB055 | C6: CUST004 | D6: Prairie Commerce Group | E6: Western Canada | F6: 45323 | G6: 45341 | H6: created | M6: Analytics Enterprise | N6: Monthly | O6: 26 | P6: 180 | Q6: 0 | R6: {=_xlfn.IFS(H6="created", "New", H6="cancelled", "Churned", AND(H6="seats_change", J6 > I6), "Expansion", AND(H6="seats_change", J6 < I6), "Contraction", AND(H6="price_change", J6 > I6), "Expansion", AND(H6="price_change", J6 < I6), "Contraction", H6="plan_upgrade", "Expansion", H6="plan_downgrade", "Contraction", H6="discount_added", "Contraction")} -> New | S6: {=_xlfn.IFS(H6="created",O6*P6*(1-Q6/100),H6="cancelled",-(O6*P6*(1-Q6/100)),H6="seats_change",(J6-I6)*P6*(1-Q6/100),H6="price_change",(J6-I6)*O6*(1-Q6/100),H6="discount_added",-(O6*P6*(J6-I6)/100),H6="plan_upgrade",O6*(_xlfn.XLOOKUP(J6,tbl_Plans[plan_name],tbl_Plans[monthly_price])-_xlfn.XLOOKUP(I6,tbl_Plans[plan_name],tbl_Plans[monthly_price]))*(1-Q6/100),H6="plan_downgrade",O6*(_xlfn.XLOOKUP(J6,tbl_Plans[plan_name],tbl_Plans[monthly_price])-_xlfn.XLOOKUP(I6,tbl_Plans[plan_name],tbl_Plans[monthly_price]))*(1-Q6/100))*IF(N6="Annual",1/12,1)} -> 4680
A7: EVT006 | B7: SUB005 | C7: CUST005 | D7: Atlantic Media Corp | E7: Eastern Canada | F7: 45352 | G7: 45355 | H7: created | M7: Analytics Starter | N7: Monthly | O7: 11 | P7: 45 | Q7: 0 | R7: {=_xlfn.IFS(H7="created", "New", H7="cancelled", "Churned", AND(H7="seats_change", J7 > I7), "Expansion", AND(H7="seats_change", J7 < I7), "Contraction", AND(H7="price_change", J7 > I7), "Expansion", AND(H7="price_change", J7 < I7), "Contraction", H7="plan_upgrade", "Expansion", H7="plan_downgrade", "Contraction", H7="discount_added", "Contraction")} -> New | S7: {=_xlfn.IFS(H7="created",O7*P7*(1-Q7/100),H7="cancelled",-(O7*P7*(1-Q7/100)),H7="seats_change",(J7-I7)*P7*(1-Q7/100),H7="price_change",(J7-I7)*O7*(1-Q7/100),H7="discount_added",-(O7*P7*(J7-I7)/100),H7="plan_upgrade",O7*(_xlfn.XLOOKUP(J7,tbl_Plans[plan_name],tbl_Plans[monthly_price])-_xlfn.XLOOKUP(I7,tbl_Plans[plan_name],tbl_Plans[monthly_price]))*(1-Q7/100),H7="plan_downgrade",O7*(_xlfn.XLOOKUP(J7,tbl_Plans[plan_name],tbl_Plans[monthly_price])-_xlfn.XLOOKUP(I7,tbl_Plans[plan_name],tbl_Plans[monthly_price]))*(1-Q7/100))*IF(N7="Annual",1/12,1)} -> 495
A8: EVT007 | B8: SUB006 | C8: CUST006 | D8: Northern Retail Solutions | E8: Western Canada | F8: 45352 | G8: 45369 | H8: created | M8: Analytics Enterprise | N8: Annual | O8: 31 | P8: 2160 | Q8: 0 | R8: {=_xlfn.IFS(H8="created", "New", H8="cancelled", "Churned", AND(H8="seats_change", J8 > I8), "Expansion", AND(H8="seats_change", J8 < I8), "Contraction", AND(H8="price_change", J8 > I8), "Expansion", AND(H8="price_change", J8 < I8), "Contraction", H8="plan_upgrade", "Expansion", H8="plan_downgrade", "Contraction", H8="discount_added", "Contraction")} -> New | S8: {=_xlfn.IFS(H8="created",O8*P8*(1-Q8/100),H8="cancelled",-(O8*P8*(1-Q8/100)),H8="seats_change",(J8-I8)*P8*(1-Q8/100),H8="price_change",(J8-I8)*O8*(1-Q8/100),H8="discount_added",-(O8*P8*(J8-I8)/100),H8="plan_upgrade",O8*(_xlfn.XLOOKUP(J8,tbl_Plans[plan_name],tbl_Plans[monthly_price])-_xlfn.XLOOKUP(I8,tbl_Plans[plan_name],tbl_Plans[monthly_price]))*(1-Q8/100),H8="plan_downgrade",O8*(_xlfn.XLOOKUP(J8,tbl_Plans[plan_name],tbl_Plans[monthly_price])-_xlfn.XLOOKUP(I8,tbl_Plans[plan_name],tbl_Plans[monthly_price]))*(1-Q8/100))*IF(N8="Annual",1/12,1)} -> 5580
A9: EVT008 | B9: SUB007 | C9: CUST007 | D9: Ontario Manufacturing Tech | E9: Eastern Canada | F9: 45383 | G9: 45383 | H9: created | M9: Marketing Pro | N9: Monthly | O9: 16 | P9: 85 | Q9: 0 | R9: {=_xlfn.IFS(H9="created", "New", H9="cancelled", "Churned", AND(H9="seats_change", J9 > I9), "Expansion", AND(H9="seats_change", J9 < I9), "Contraction", AND(H9="price_change", J9 > I9), "Expansion", AND(H9="price_change", J9 < I9), "Contraction", H9="plan_upgrade", "Expansion", H9="plan_downgrade", "Contraction", H9="discount_added", "Contraction")} -> New | S9: {=_xlfn.IFS(H9="created",O9*P9*(1-Q9/100),H9="cancelled",-(O9*P9*(1-Q9/100)),H9="seats_change",(J9-I9)*P9*(1-Q9/100),H9="price_change",(J9-I9)*O9*(1-Q9/100),H9="discount_added",-(O9*P9*(J9-I9)/100),H9="plan_upgrade",O9*(_xlfn.XLOOKUP(J9,tbl_Plans[plan_name],tbl_Plans[monthly_price])-_xlfn.XLOOKUP(I9,tbl_Plans[plan_name],tbl_Plans[monthly_price]))*(1-Q9/100),H9="plan_downgrade",O9*(_xlfn.XLOOKUP(J9,tbl_Plans[plan_name],tbl_Plans[monthly_price])-_xlfn.XLOOKUP(I9,tbl_Plans[plan_name],tbl_Plans[monthly_price]))*(1-Q9/100))*IF(N9="Annual",1/12,1)} -> 1360
A10: EVT009 | B10: SUB050 | C10: CUST007 | D10: Ontario Manufacturing Tech | E10: Eastern Canada | F10: 45383 | G10: 45383 | H10: created | M10: Analytics Starter | N10: Monthly | O10: 15 | P10: 45 | Q10: 12 | R10: {=_xlfn.IFS(H10="created", "New", H10="cancelled", "Churned", AND(H10="seats_change", J10 > I10), "Expansion", AND(H10="seats_change", J10 < I10), "Contraction", AND(H10="price_change", J10 > I10), "Expansion", AND(H10="price_change", J10 < I10), "Contraction", H10="plan_upgrade", "Expansion", H10="plan_downgrade", "Contraction", H10="discount_added", "Contraction")} -> New | S10: {=_xlfn.IFS(H10="created",O10*P10*(1-Q10/100),H10="cancelled",-(O10*P10*(1-Q10/100)),H10="seats_change",(J10-I10)*P10*(1-Q10/100),H10="price_change",(J10-I10)*O10*(1-Q10/100),H10="discount_added",-(O10*P10*(J10-I10)/100),H10="plan_upgrade",O10*(_xlfn.XLOOKUP(J10,tbl_Plans[plan_name],tbl_Plans[monthly_price])-_xlfn.XLOOKUP(I10,tbl_Plans[plan_name],tbl_Plans[monthly_price]))*(1-Q10/100),H10="plan_downgrade",O10*(_xlfn.XLOOKUP(J10,tbl_Plans[plan_name],tbl_Plans[monthly_price])-_xlfn.XLOOKUP(I10,tbl_Plans[plan_name],tbl_Plans[monthly_price]))*(1-Q10/100))*IF(N10="Annual",1/12,1)} -> 594
A11: EVT010 | B11: SUB008 | C11: CUST008 | D11: Quantum Education Platform | E11: Eastern Canada | F11: 45383 | G11: 45397 | H11: created | M11: Analytics Growth | N11: Monthly | O11: 22 | P11: 95 | Q11: 0 | R11: {=_xlfn.IFS(H11="created", "New", H11="cancelled", "Churned", AND(H11="seats_change", J11 > I11), "Expansion", AND(H11="seats_change", J11 < I11), "Contraction", AND(H11="price_change", J11 > I11), "Expansion", AND(H11="price_change", J11 < I11), "Contraction", H11="plan_upgrade", "Expansion", H11="plan_downgrade", "Contraction", H11="discount_added", "Contraction")} -> New | S11: {=_xlfn.IFS(H11="created",O11*P11*(1-Q11/100),H11="cancelled",-(O11*P11*(1-Q11/100)),H11="seats_change",(J11-I11)*P11*(1-Q11/100),H11="price_change",(J11-I11)*O11*(1-Q11/100),H11="discount_added",-(O11*P11*(J11-I11)/100),H11="plan_upgrade",O11*(_xlfn.XLOOKUP(J11,tbl_Plans[plan_name],tbl_Plans[monthly_price])-_xlfn.XLOOKUP(I11,tbl_Plans[plan_name],tbl_Plans[monthly_price]))*(1-Q11/100),H11="plan_downgrade",O11*(_xlfn.XLOOKUP(J11,tbl_Plans[plan_name],tbl_Plans[monthly_price])-_xlfn.XLOOKUP(I11,tbl_Plans[plan_name],tbl_Plans[monthly_price]))*(1-Q11/100))*IF(N11="Annual",1/12,1)} -> 2090
A12: EVT011 | B12: SUB009 | C12: CUST009 | D12: West Coast Logistics | E12: Western Canada | F12: 45383 | G12: 45411 | H12: created | M12: Platform Suite | N12: Annual | O12: 36 | P12: 1800 | Q12: 0 | R12: {=_xlfn.IFS(H12="created", "New", H12="cancelled", "Churned", AND(H12="seats_change", J12 > I12), "Expansion", AND(H12="seats_change", J12 < I12), "Contraction", AND(H12="price_change", J12 > I12), "Expansion", AND(H12="price_change", J12 < I12), "Contraction", H12="plan_upgrade", "Expansion", H12="plan_downgrade", "Contraction", H12="discount_added", "Contraction")} -> New | S12: {=_xlfn.IFS(H12="created",O12*P12*(1-Q12/100),H12="cancelled",-(O12*P12*(1-Q12/100)),H12="seats_change",(J12-I12)*P12*(1-Q12/100),H12="price_change",(J12-I12)*O12*(1-Q12/100),H12="discount_added",-(O12*P12*(J12-I12)/100),H12="plan_upgrade",O12*(_xlfn.XLOOKUP(J12,tbl_Plans[plan_name],tbl_Plans[monthly_price])-_xlfn.XLOOKUP(I12,tbl_Plans[plan_name],tbl_Plans[monthly_price]))*(1-Q12/100),H12="plan_downgrade",O12*(_xlfn.XLOOKUP(J12,tbl_Plans[plan_name],tbl_Plans[monthly_price])-_xlfn.XLOOKUP(I12,tbl_Plans[plan_name],tbl_Plans[monthly_price]))*(1-Q12/100))*IF(N12="Annual",1/12,1)} -> 5400
A13: EVT012 | B13: SUB010 | C13: CUST010 | D13: Montreal Finance Hub | E13: Eastern Canada | F13: 45413 | G13: 45425 | H13: created | M13: Analytics Starter | N13: Monthly | O13: 13 | P13: 45 | Q13: 0 | R13: {=_xlfn.IFS(H13="created", "New", H13="cancelled", "Churned", AND(H13="seats_change", J13 > I13), "Expansion", AND(H13="seats_change", J13 < I13), "Contraction", AND(H13="price_change", J13 > I13), "Expansion", AND(H13="price_change", J13 < I13), "Contraction", H13="plan_upgrade", "Expansion", H13="plan_downgrade", "Contraction", H13="discount_added", "Contraction")} -> New | S13: {=_xlfn.IFS(H13="created",O13*P13*(1-Q13/100),H13="cancelled",-(O13*P13*(1-Q13/100)),H13="seats_change",(J13-I13)*P13*(1-Q13/100),H13="price_change",(J13-I13)*O13*(1-Q13/100),H13="discount_added",-(O13*P13*(J13-I13)/100),H13="plan_upgrade",O13*(_xlfn.XLOOKUP(J13,tbl_Plans[plan_name],tbl_Plans[monthly_price])-_xlfn.XLOOKUP(I13,tbl_Plans[plan_name],tbl_Plans[monthly_price]))*(1-Q13/100),H13="plan_downgrade",O13*(_xlfn.XLOOKUP(J13,tbl_Plans[plan_name],tbl_Plans[monthly_price])-_xlfn.XLOOKUP(I13,tbl_Plans[plan_name],tbl_Plans[monthly_price]))*(1-Q13/100))*IF(N13="Annual",1/12,1)} -> 585
... A23: EVT022 | B23: SUB017 | C23: CUST017 | D23: Capital Education Tech | E23: Eastern Canada | F23: 45505 | G23: 45523 | H23: created | M23: Analytics Starter | N23: Monthly | O23: 12 | P23: 45 | Q23: 0 | R23: {=_xlfn.IFS(H23="created", "New", H23="cancelled", "Churned", AND(H23="seats_change", J23 > I23), "Expansion", AND(H23="seats_change", J23 < I23), "Contraction", AND(H23="price_change", J23 > I23), "Expansion", AND(H23="price_change", J23 < I23), "Contraction", H23="plan_upgrade", "Expansion", H23="plan_downgrade", "Contraction", H23="discount_added", "Contraction")} -> New | S23: {=_xlfn.IFS(H23="created",O23*P23*(1-Q23/100),H23="cancelled",-(O23*P23*(1-Q23/100)),H23="seats_change",(J23-I23)*P23*(1-Q23/100),H23="price_change",(J23-I23)*O23*(1-Q23/100),H23="discount_added",-(O23*P23*(J23-I23)/100),H23="plan_upgrade",O23*(_xlfn.XLOOKUP(J23,tbl_Plans[plan_name],tbl_Plans[monthly_price])-_xlfn.XLOOKUP(I23,tbl_Plans[plan_name],tbl_Plans[monthly_price]))*(1-Q23/100),H23="plan_downgrade",O23*(_xlfn.XLOOKUP(J23,tbl_Plans[plan_name],tbl_Plans[monthly_price])-_xlfn.XLOOKUP(I23,tbl_Plans[plan_name],tbl_Plans[monthly_price]))*(1-Q23/100))*IF(N23="Annual",1/12,1)} -> 540
A24: EVT023 | B24: SUB001 | C24: CUST001 | D24: TechVision Solutions | E24: Eastern Canada | F24: 45505 | G24: 45531 | H24: cancelled | I24: active | J24: churned | K24: status | L24: Missing features | M24: Analytics Growth | N24: Monthly | O24: 20 | P24: 95 | Q24: 0 | R24: {=_xlfn.IFS(H24="created", "New", H24="cancelled", "Churned", AND(H24="seats_change", J24 > I24), "Expansion", AND(H24="seats_change", J24 < I24), "Contraction", AND(H24="price_change", J24 > I24), "Expansion", AND(H24="price_change", J24 < I24), "Contraction", H24="plan_upgrade", "Expansion", H24="plan_downgrade", "Contraction", H24="discount_added", "Contraction")} -> Churned | S24: {=_xlfn.IFS(H24="created",O24*P24*(1-Q24/100),H24="cancelled",-(O24*P24*(1-Q24/100)),H24="seats_change",(J24-I24)*P24*(1-Q24/100),H24="price_change",(J24-I24)*O24*(1-Q24/100),H24="discount_added",-(O24*P24*(J24-I24)/100),H24="plan_upgrade",O24*(_xlfn.XLOOKUP(J24,tbl_Plans[plan_name],tbl_Plans[monthly_price])-_xlfn.XLOOKUP(I24,tbl_Plans[plan_name],tbl_Plans[monthly_price]))*(1-Q24/100),H24="plan_downgrade",O24*(_xlfn.XLOOKUP(J24,tbl_Plans[plan_name],tbl_Plans[monthly_price])-_xlfn.XLOOKUP(I24,tbl_Plans[plan_name],tbl_Plans[monthly_price]))*(1-Q24/100))*IF(N24="Annual",1/12,1)} -> -1900
A25: EVT024 | B25: SUB018 | C25: CUST018 | D25: Vancouver FinTech Labs | E25: Western Canada | F25: 45536 | G25: 45537 | H25: created | M25: Analytics Enterprise | N25: Monthly | O25: 35 | P25: 180 | Q25: 0 | R25: {=_xlfn.IFS(H25="created", "New", H25="cancelled", "Churned", AND(H25="seats_change", J25 > I25), "Expansion", AND(H25="seats_change", J25 < I25), "Contraction", AND(H25="price_change", J25 > I25), "Expansion", AND(H25="price_change", J25 < I25), "Contraction", H25="plan_upgrade", "Expansion", H25="plan_downgrade", "Contraction", H25="discount_added", "Contraction")} -> New | S25: {=_xlfn.IFS(H25="created",O25*P25*(1-Q25/100),H25="cancelled",-(O25*P25*(1-Q25/100)),H25="seats_change",(J25-I25)*P25*(1-Q25/100),H25="price_change",(J25-I25)*O25*(1-Q25/100),H25="discount_added",-(O25*P25*(J25-I25)/100),H25="plan_upgrade",O25*(_xlfn.XLOOKUP(J25,tbl_Plans[plan_name],tbl_Plans[monthly_price])-_xlfn.XLOOKUP(I25,tbl_Plans[plan_name],tbl_Plans[monthly_price]))*(1-Q25/100),H25="plan_downgrade",O25*(_xlfn.XLOOKUP(J25,tbl_Plans[plan_name],tbl_Plans[monthly_price])-_xlfn.XLOOKUP(I25,tbl_Plans[plan_name],tbl_Plans[monthly_price]))*(1-Q25/100))*IF(N25="Annual",1/12,1)} -> 6300
A26: EVT025 | B26: SUB042 | C26: CUST003 | D26: Maple Healthcare Systems | E26: Eastern Canada | F26: 45536 | G26: 45545 | H26: created | M26: Sales Hub | N26: Monthly | O26: 19 | P26: 110 | Q26: 0 | R26: {=_xlfn.IFS(H26="created", "New", H26="cancelled", "Churned", AND(H26="seats_change", J26 > I26), "Expansion", AND(H26="seats_change", J26 < I26), "Contraction", AND(H26="price_change", J26 > I26), "Expansion", AND(H26="price_change", J26 < I26), "Contraction", H26="plan_upgrade", "Expansion", H26="plan_downgrade", "Contraction", H26="discount_added", "Contraction")} -> New | S26: {=_xlfn.IFS(H26="created",O26*P26*(1-Q26/100),H26="cancelled",-(O26*P26*(1-Q26/100)),H26="seats_change",(J26-I26)*P26*(1-Q26/100),H26="price_change",(J26-I26)*O26*(1-Q26/100),H26="discount_added",-(O26*P26*(J26-I26)/100),H26="plan_upgrade",O26*(_xlfn.XLOOKUP(J26,tbl_Plans[plan_name],tbl_Plans[monthly_price])-_xlfn.XLOOKUP(I26,tbl_Plans[plan_name],tbl_Plans[monthly_price]))*(1-Q26/100),H26="plan_downgrade",O26*(_xlfn.XLOOKUP(J26,tbl_Plans[plan_name],tbl_Plans[monthly_price])-_xlfn.XLOOKUP(I26,tbl_Plans[plan_name],tbl_Plans[monthly_price]))*(1-Q26/100))*IF(N26="Annual",1/12,1)} -> 2090
A27: EVT026 | B27: SUB019 | C27: CUST019 | D27: Central Healthcare Partners | E27: Central Canada | F27: 45536 | G27: 45551 | H27: created | M27: Marketing Pro | N27: Monthly | O27: 19 | P27: 85 | Q27: 0 | R27: {=_xlfn.IFS(H27="created", "New", H27="cancelled", "Churned", AND(H27="seats_change", J27 > I27), "Expansion", AND(H27="seats_change", J27 < I27), "Contraction", AND(H27="price_change", J27 > I27), "Expansion", AND(H27="price_change", J27 < I27), "Contraction", H27="plan_upgrade", "Expansion", H27="plan_downgrade", "Contraction", H27="discount_added", "Contraction")} -> New | S27: {=_xlfn.IFS(H27="created",O27*P27*(1-Q27/100),H27="cancelled",-(O27*P27*(1-Q27/100)),H27="seats_change",(J27-I27)*P27*(1-Q27/100),H27="price_change",(J27-I27)*O27*(1-Q27/100),H27="discount_added",-(O27*P27*(J27-I27)/100),H27="plan_upgrade",O27*(_xlfn.XLOOKUP(J27,tbl_Plans[plan_name],tbl_Plans[monthly_price])-_xlfn.XLOOKUP(I27,tbl_Plans[plan_name],tbl_Plans[monthly_price]))*(1-Q27/100),H27="plan_downgrade",O27*(_xlfn.XLOOKUP(J27,tbl_Plans[plan_name],tbl_Plans[monthly_price])-_xlfn.XLOOKUP(I27,tbl_Plans[plan_name],tbl_Plans[monthly_price]))*(1-Q27/100))*IF(N27="Annual",1/12,1)} -> 1615
A28: EVT027 | B28: SUB060 | C28: CUST019 | D28: Central Healthcare Partners | E28: Central Canada | F28: 45536 | G28: 45551 | H28: created | M28: Sales Hub | N28: Monthly | O28: 16 | P28: 110 | Q28: 0 | R28: {=_xlfn.IFS(H28="created", "New", H28="cancelled", "Churned", AND(H28="seats_change", J28 > I28), "Expansion", AND(H28="seats_change", J28 < I28), "Contraction", AND(H28="price_change", J28 > I28), "Expansion", AND(H28="price_change", J28 < I28), "Contraction", H28="plan_upgrade", "Expansion", H28="plan_downgrade", "Contraction", H28="discount_added", "Contraction")} -> New | S28: {=_xlfn.IFS(H28="created",O28*P28*(1-Q28/100),H28="cancelled",-(O28*P28*(1-Q28/100)),H28="seats_change",(J28-I28)*P28*(1-Q28/100),H28="price_change",(J28-I28)*O28*(1-Q28/100),H28="discount_added",-(O28*P28*(J28-I28)/100),H28="plan_upgrade",O28*(_xlfn.XLOOKUP(J28,tbl_Plans[plan_name],tbl_Plans[monthly_price])-_xlfn.XLOOKUP(I28,tbl_Plans[plan_name],tbl_Plans[monthly_price]))*(1-Q28/100),H28="plan_downgrade",O28*(_xlfn.XLOOKUP(J28,tbl_Plans[plan_name],tbl_Plans[monthly_price])-_xlfn.XLOOKUP(I28,tbl_Plans[plan_name],tbl_Plans[monthly_price]))*(1-Q28/100))*IF(N28="Annual",1/12,1)} -> 1760
A29: EVT028 | B29: SUB020 | C29: CUST020 | D29: Atlantic SaaS Systems | E29: Eastern Canada | F29: 45536 | G29: 45565 | H29: created | M29: Sales Hub | N29: Monthly | O29: 15 | P29: 110 | Q29: 0 | R29: {=_xlfn.IFS(H29="created", "New", H29="cancelled", "Churned", AND(H29="seats_change", J29 > I29), "Expansion", AND(H29="seats_change", J29 < I29), "Contraction", AND(H29="price_change", J29 > I29), "Expansion", AND(H29="price_change", J29 < I29), "Contraction", H29="plan_upgrade", "Expansion", H29="plan_downgrade", "Contraction", H29="discount_added", "Contraction")} -> New | S29: {=_xlfn.IFS(H29="created",O29*P29*(1-Q29/100),H29="cancelled",-(O29*P29*(1-Q29/100)),H29="seats_change",(J29-I29)*P29*(1-Q29/100),H29="price_change",(J29-I29)*O29*(1-Q29/100),H29="discount_added",-(O29*P29*(J29-I29)/100),H29="plan_upgrade",O29*(_xlfn.XLOOKUP(J29,tbl_Plans[plan_name],tbl_Plans[monthly_price])-_xlfn.XLOOKUP(I29,tbl_Plans[plan_name],tbl_Plans[monthly_price]))*(1-Q29/100),H29="plan_downgrade",O29*(_xlfn.XLOOKUP(J29,tbl_Plans[plan_name],tbl_Plans[monthly_price])-_xlfn.XLOOKUP(I29,tbl_Plans[plan_name],tbl_Plans[monthly_price]))*(1-Q29/100))*IF(N29="Annual",1/12,1)} -> 1650
A30: EVT029 | B30: SUB043 | C30: CUST006 | D30: Northern Retail Solutions | E30: Western Canada | F30: 45566 | G30: 45570 | H30: created | M30: Marketing Pro | N30: Monthly | O30: 33 | P30: 85 | Q30: 0 | R30: {=_xlfn.IFS(H30="created", "New", H30="cancelled", "Churned", AND(H30="seats_change", J30 > I30), "Expansion", AND(H30="seats_change", J30 < I30), "Contraction", AND(H30="price_change", J30 > I30), "Expansion", AND(H30="price_change", J30 < I30), "Contraction", H30="plan_upgrade", "Expansion", H30="plan_downgrade", "Contraction", H30="discount_added", "Contraction")} -> New | S30: {=_xlfn.IFS(H30="created",O30*P30*(1-Q30/100),H30="cancelled",-(O30*P30*(1-Q30/100)),H30="seats_change",(J30-I30)*P30*(1-Q30/100),H30="price_change",(J30-I30)*O30*(1-Q30/100),H30="discount_added",-(O30*P30*(J30-I30)/100),H30="plan_upgrade",O30*(_xlfn.XLOOKUP(J30,tbl_Plans[plan_name],tbl_Plans[monthly_price])-_xlfn.XLOOKUP(I30,tbl_Plans[plan_name],tbl_Plans[monthly_price]))*(1-Q30/100),H30="plan_downgrade",O30*(_xlfn.XLOOKUP(J30,tbl_Plans[plan_name],tbl_Plans[monthly_price])-_xlfn.XLOOKUP(I30,tbl_Plans[plan_name],tbl_Plans[monthly_price]))*(1-Q30/100))*IF(N30="Annual",1/12,1)} -> 2805
A31: EVT030 | B31: SUB021 | C31: CUST021 | D31: Calgary Commerce Solutions | E31: Western Canada | F31: 45566 | G31: 45579 | H31: created | M31: Analytics Growth | N31: Monthly | O31: 25 | P31: 95 | Q31: 0 | R31: {=_xlfn.IFS(H31="created", "New", H31="cancelled", "Churned", AND(H31="seats_change", J31 > I31), "Expansion", AND(H31="seats_change", J31 < I31), "Contraction", AND(H31="price_change", J31 > I31), "Expansion", AND(H31="price_change", J31 < I31), "Contraction", H31="plan_upgrade", "Expansion", H31="plan_downgrade", "Contraction", H31="discount_added", "Contraction")} -> New | S31: {=_xlfn.IFS(H31="created",O31*P31*(1-Q31/100),H31="cancelled",-(O31*P31*(1-Q31/100)),H31="seats_change",(J31-I31)*P31*(1-Q31/100),H31="price_change",(J31-I31)*O31*(1-Q31/100),H31="discount_added",-(O31*P31*(J31-I31)/100),H31="plan_upgrade",O31*(_xlfn.XLOOKUP(J31,tbl_Plans[plan_name],tbl_Plans[monthly_price])-_xlfn.XLOOKUP(I31,tbl_Plans[plan_name],tbl_Plans[monthly_price]))*(1-Q31/100),H31="plan_downgrade",O31*(_xlfn.XLOOKUP(J31,tbl_Plans[plan_name],tbl_Plans[monthly_price])-_xlfn.XLOOKUP(I31,tbl_Plans[plan_name],tbl_Plans[monthly_price]))*(1-Q31/100))*IF(N31="Annual",1/12,1)} -> 2375
A32: EVT031 | B32: SUB022 | C32: CUST022 | D32: Toronto Tech Ventures | E32: Eastern Canada | F32: 45566 | G32: 45593 | H32: created | M32: Platform Suite | N32: Monthly | O32: 33 | P32: 150 | Q32: 0 | R32: {=_xlfn.IFS(H32="created", "New", H32="cancelled", "Churned", AND(H32="seats_change", J32 > I32), "Expansion", AND(H32="seats_change", J32 < I32), "Contraction", AND(H32="price_change", J32 > I32), "Expansion", AND(H32="price_change", J32 < I32), "Contraction", H32="plan_upgrade", "Expansion", H32="plan_downgrade", "Contraction", H32="discount_added", "Contraction")} -> New | S32: {=_xlfn.IFS(H32="created",O32*P32*(1-Q32/100),H32="cancelled",-(O32*P32*(1-Q32/100)),H32="seats_change",(J32-I32)*P32*(1-Q32/100),H32="price_change",(J32-I32)*O32*(1-Q32/100),H32="discount_added",-(O32*P32*(J32-I32)/100),H32="plan_upgrade",O32*(_xlfn.XLOOKUP(J32,tbl_Plans[plan_name],tbl_Plans[monthly_price])-_xlfn.XLOOKUP(I32,tbl_Plans[plan_name],tbl_Plans[monthly_price]))*(1-Q32/100),H32="plan_downgrade",O32*(_xlfn.XLOOKUP(J32,tbl_Plans[plan_name],tbl_Plans[monthly_price])-_xlfn.XLOOKUP(I32,tbl_Plans[plan_name],tbl_Plans[monthly_price]))*(1-Q32/100))*IF(N32="Annual",1/12,1)} -> 4950
A33: EVT032 | B33: SUB059 | C33: CUST008 | D33: Quantum Education Platform | E33: Eastern Canada | F33: 45597 | G33: 45601 | H33: created | M33: Marketing Pro | N33: Monthly | O33: 22 | P33: 85 | Q33: 0 | R33: {=_xlfn.IFS(H33="created", "New", H33="cancelled", "Churned", AND(H33="seats_change", J33 > I33), "Expansion", AND(H33="seats_change", J33 < I33), "Contraction", AND(H33="price_change", J33 > I33), "Expansion", AND(H33="price_change", J33 < I33), "Contraction", H33="plan_upgrade", "Expansion", H33="plan_downgrade", "Contraction", H33="discount_added", "Contraction")} -> New | S33: {=_xlfn.IFS(H33="created",O33*P33*(1-Q33/100),H33="cancelled",-(O33*P33*(1-Q33/100)),H33="seats_change",(J33-I33)*P33*(1-Q33/100),H33="price_change",(J33-I33)*O33*(1-Q33/100),H33="discount_added",-(O33*P33*(J33-I33)/100),H33="plan_upgrade",O33*(_xlfn.XLOOKUP(J33,tbl_Plans[plan_name],tbl_Plans[monthly_price])-_xlfn.XLOOKUP(I33,tbl_Plans[plan_name],tbl_Plans[monthly_price]))*(1-Q33/100),H33="plan_downgrade",O33*(_xlfn.XLOOKUP(J33,tbl_Plans[plan_name],tbl_Plans[monthly_price])-_xlfn.XLOOKUP(I33,tbl_Plans[plan_name],tbl_Plans[monthly_price]))*(1-Q33/100))*IF(N33="Annual",1/12,1)} -> 1870
A34: EVT033 | B34: SUB023 | C34: CUST023 | D34: Island Media Productions | E34: Eastern Canada | F34: 45597 | G34: 45607 | H34: created | M34: Analytics Starter | N34: Monthly | O34: 10 | P34: 45 | Q34: 0 | R34: {=_xlfn.IFS(H34="created", "New", H34="cancelled", "Churned", AND(H34="seats_change", J34 > I34), "Expansion", AND(H34="seats_change", J34 < I34), "Contraction", AND(H34="price_change", J34 > I34), "Expansion", AND(H34="price_change", J34 < I34), "Contraction", H34="plan_upgrade", "Expansion", H34="plan_downgrade", "Contraction", H34="discount_added", "Contraction")} -> New | S34: {=_xlfn.IFS(H34="created",O34*P34*(1-Q34/100),H34="cancelled",-(O34*P34*(1-Q34/100)),H34="seats_change",(J34-I34)*P34*(1-Q34/100),H34="price_change",(J34-I34)*O34*(1-Q34/100),H34="discount_added",-(O34*P34*(J34-I34)/100),H34="plan_upgrade",O34*(_xlfn.XLOOKUP(J34,tbl_Plans[plan_name],tbl_Plans[monthly_price])-_xlfn.XLOOKUP(I34,tbl_Plans[plan_name],tbl_Plans[monthly_price]))*(1-Q34/100),H34="plan_downgrade",O34*(_xlfn.XLOOKUP(J34,tbl_Plans[plan_name],tbl_Plans[monthly_price])-_xlfn.XLOOKUP(I34,tbl_Plans[plan_name],tbl_Plans[monthly_price]))*(1-Q34/100))*IF(N34="Annual",1/12,1)} -> 450
A35: EVT034 | B35: SUB005 | C35: CUST005 | D35: Atlantic Media Corp | E35: Eastern Canada | F35: 45597 | G35: 45616 | H35: cancelled | I35: active | J35: churned | K35: status | L35: Price too high | M35: Analytics Starter | N35: Monthly | O35: 11 | P35: 45 | Q35: 0 | R35: {=_xlfn.IFS(H35="created", "New", H35="cancelled", "Churned", AND(H35="seats_change", J35 > I35), "Expansion", AND(H35="seats_change", J35 < I35), "Contraction", AND(H35="price_change", J35 > I35), "Expansion", AND(H35="price_change", J35 < I35), "Contraction", H35="plan_upgrade", "Expansion", H35="plan_downgrade", "Contraction", H35="discount_added", "Contraction")} -> Churned | S35: {=_xlfn.IFS(H35="created",O35*P35*(1-Q35/100),H35="cancelled",-(O35*P35*(1-Q35/100)),H35="seats_change",(J35-I35)*P35*(1-Q35/100),H35="price_change",(J35-I35)*O35*(1-Q35/100),H35="discount_added",-(O35*P35*(J35-I35)/100),H35="plan_upgrade",O35*(_xlfn.XLOOKUP(J35,tbl_Plans[plan_name],tbl_Plans[monthly_price])-_xlfn.XLOOKUP(I35,tbl_Plans[plan_name],tbl_Plans[monthly_price]))*(1-Q35/100),H35="plan_downgrade",O35*(_xlfn.XLOOKUP(J35,tbl_Plans[plan_name],tbl_Plans[monthly_price])-_xlfn.XLOOKUP(I35,tbl_Plans[plan_name],tbl_Plans[monthly_price]))*(1-Q35/100))*IF(N35="Annual",1/12,1)} -> -495
A36: EVT035 | B36: SUB024 | C36: CUST024 | D36: Western Retail Group | E36: Western Canada | F36: 45597 | G36: 45621 | H36: created | M36: Marketing Pro | N36: Monthly | O36: 31 | P36: 85 | Q36: 0 | R36: {=_xlfn.IFS(H36="created", "New", H36="cancelled", "Churned", AND(H36="seats_change", J36 > I36), "Expansion", AND(H36="seats_change", J36 < I36), "Contraction", AND(H36="price_change", J36 > I36), "Expansion", AND(H36="price_change", J36 < I36), "Contraction", H36="plan_upgrade", "Expansion", H36="plan_downgrade", "Contraction", H36="discount_added", "Contraction")} -> New | S36: {=_xlfn.IFS(H36="created",O36*P36*(1-Q36/100),H36="cancelled",-(O36*P36*(1-Q36/100)),H36="seats_change",(J36-I36)*P36*(1-Q36/100),H36="price_change",(J36-I36)*O36*(1-Q36/100),H36="discount_added",-(O36*P36*(J36-I36)/100),H36="plan_upgrade",O36*(_xlfn.XLOOKUP(J36,tbl_Plans[plan_name],tbl_Plans[monthly_price])-_xlfn.XLOOKUP(I36,tbl_Plans[plan_name],tbl_Plans[monthly_price]))*(1-Q36/100),H36="plan_downgrade",O36*(_xlfn.XLOOKUP(J36,tbl_Plans[plan_name],tbl_Plans[monthly_price])-_xlfn.XLOOKUP(I36,tbl_Plans[plan_name],tbl_Plans[monthly_price]))*(1-Q36/100))*IF(N36="Annual",1/12,1)} -> 2635
A37: EVT036 | B37: SUB025 | C37: CUST025 | D37: Montreal Manufacturing Pro | E37: Eastern Canada | F37: 45627 | G37: 45635 | H37: created | M37: Analytics Enterprise | N37: Annual | O37: 38 | P37: 2160 | Q37: 0 | R37: {=_xlfn.IFS(H37="created", "New", H37="cancelled", "Churned", AND(H37="seats_change", J37 > I37), "Expansion", AND(H37="seats_change", J37 < I37), "Contraction", AND(H37="price_change", J37 > I37), "Expansion", AND(H37="price_change", J37 < I37), "Contraction", H37="plan_upgrade", "Expansion", H37="plan_downgrade", "Contraction", H37="discount_added", "Contraction")} -> New | S37: {=_xlfn.IFS(H37="created",O37*P37*(1-Q37/100),H37="cancelled",-(O37*P37*(1-Q37/100)),H37="seats_change",(J37-I37)*P37*(1-Q37/100),H37="price_change",(J37-I37)*O37*(1-Q37/100),H37="discount_added",-(O37*P37*(J37-I37)/100),H37="plan_upgrade",O37*(_xlfn.XLOOKUP(J37,tbl_Plans[plan_name],tbl_Plans[monthly_price])-_xlfn.XLOOKUP(I37,tbl_Plans[plan_name],tbl_Plans[monthly_price]))*(1-Q37/100),H37="plan_downgrade",O37*(_xlfn.XLOOKUP(J37,tbl_Plans[plan_name],tbl_Plans[monthly_price])-_xlfn.XLOOKUP(I37,tbl_Plans[plan_name],tbl_Plans[monthly_price]))*(1-Q37/100))*IF(N37="Annual",1/12,1)} -> 6840
A38: EVT037 | B38: SUB056 | C38: CUST016 | D38: Quebec Manufacturing | E38: Eastern Canada | F38: 45627 | G38: 45638 | H38: created | M38: Marketing Pro | N38: Monthly | O38: 38 | P38: 85 | Q38: 0 | R38: {=_xlfn.IFS(H38="created", "New", H38="cancelled", "Churned", AND(H38="seats_change", J38 > I38), "Expansion", AND(H38="seats_change", J38 < I38), "Contraction", AND(H38="price_change", J38 > I38), "Expansion", AND(H38="price_change", J38 < I38), "Contraction", H38="plan_upgrade", "Expansion", H38="plan_downgrade", "Contraction", H38="discount_added", "Contraction")} -> New | S38: {=_xlfn.IFS(H38="created",O38*P38*(1-Q38/100),H38="cancelled",-(O38*P38*(1-Q38/100)),H38="seats_change",(J38-I38)*P38*(1-Q38/100),H38="price_change",(J38-I38)*O38*(1-Q38/100),H38="discount_added",-(O38*P38*(J38-I38)/100),H38="plan_upgrade",O38*(_xlfn.XLOOKUP(J38,tbl_Plans[plan_name],tbl_Plans[monthly_price])-_xlfn.XLOOKUP(I38,tbl_Plans[plan_name],tbl_Plans[monthly_price]))*(1-Q38/100),H38="plan_downgrade",O38*(_xlfn.XLOOKUP(J38,tbl_Plans[plan_name],tbl_Plans[monthly_price])-_xlfn.XLOOKUP(I38,tbl_Plans[plan_name],tbl_Plans[monthly_price]))*(1-Q38/100))*IF(N38="Annual",1/12,1)} -> 3230
A39: EVT038 | B39: SUB044 | C39: CUST009 | D39: West Coast Logistics | E39: Western Canada | F39: 45627 | G39: 45646 | H39: created | M39: Analytics Growth | N39: Monthly | O39: 35 | P39: 95 | Q39: 0 | R39: {=_xlfn.IFS(H39="created", "New", H39="cancelled", "Churned", AND(H39="seats_change", J39 > I39), "Expansion", AND(H39="seats_change", J39 < I39), "Contraction", AND(H39="price_change", J39 > I39), "Expansion", AND(H39="price_change", J39 < I39), "Contraction", H39="plan_upgrade", "Expansion", H39="plan_downgrade", "Contraction", H39="discount_added", "Contraction")} -> New | S39: {=_xlfn.IFS(H39="created",O39*P39*(1-Q39/100),H39="cancelled",-(O39*P39*(1-Q39/100)),H39="seats_change",(J39-I39)*P39*(1-Q39/100),H39="price_change",(J39-I39)*O39*(1-Q39/100),H39="discount_added",-(O39*P39*(J39-I39)/100),H39="plan_upgrade",O39*(_xlfn.XLOOKUP(J39,tbl_Plans[plan_name],tbl_Plans[monthly_price])-_xlfn.XLOOKUP(I39,tbl_Plans[plan_name],tbl_Plans[monthly_price]))*(1-Q39/100),H39="plan_downgrade",O39*(_xlfn.XLOOKUP(J39,tbl_Plans[plan_name],tbl_Plans[monthly_price])-_xlfn.XLOOKUP(I39,tbl_Plans[plan_name],tbl_Plans[monthly_price]))*(1-Q39/100))*IF(N39="Annual",1/12,1)} -> 3325
A40: EVT039 | B40: SUB008 | C40: CUST008 | D40: Quantum Education Platform | E40: Eastern Canada | F40: 45627 | G40: 45648 | H40: cancelled | I40: active | J40: churned | K40: status | L40: Price too high | M40: Analytics Growth | N40: Monthly | O40: 22 | P40: 95 | Q40: 0 | R40: {=_xlfn.IFS(H40="created", "New", H40="cancelled", "Churned", AND(H40="seats_change", J40 > I40), "Expansion", AND(H40="seats_change", J40 < I40), "Contraction", AND(H40="price_change", J40 > I40), "Expansion", AND(H40="price_change", J40 < I40), "Contraction", H40="plan_upgrade", "Expansion", H40="plan_downgrade", "Contraction", H40="discount_added", "Contraction")} -> Churned | S40: {=_xlfn.IFS(H40="created",O40*P40*(1-Q40/100),H40="cancelled",-(O40*P40*(1-Q40/100)),H40="seats_change",(J40-I40)*P40*(1-Q40/100),H40="price_change",(J40-I40)*O40*(1-Q40/100),H40="discount_added",-(O40*P40*(J40-I40)/100),H40="plan_upgrade",O40*(_xlfn.XLOOKUP(J40,tbl_Plans[plan_name],tbl_Plans[monthly_price])-_xlfn.XLOOKUP(I40,tbl_Plans[plan_name],tbl_Plans[monthly_price]))*(1-Q40/100),H40="plan_downgrade",O40*(_xlfn.XLOOKUP(J40,tbl_Plans[plan_name],tbl_Plans[monthly_price])-_xlfn.XLOOKUP(I40,tbl_Plans[plan_name],tbl_Plans[monthly_price]))*(1-Q40/100))*IF(N40="Annual",1/12,1)} -> -2090
A41: EVT040 | B41: SUB026 | C41: CUST026 | D41: Ontario Education Connect | E41: Eastern Canada | F41: 45627 | G41: 45649 | H41: created | M41: Analytics Growth | N41: Monthly | O41: 16 | P41: 95 | Q41: 0 | R41: {=_xlfn.IFS(H41="created", "New", H41="cancelled", "Churned", AND(H41="seats_change", J41 > I41), "Expansion", AND(H41="seats_change", J41 < I41), "Contraction", AND(H41="price_change", J41 > I41), "Expansion", AND(H41="price_change", J41 < I41), "Contraction", H41="plan_upgrade", "Expansion", H41="plan_downgrade", "Contraction", H41="discount_added", "Contraction")} -> New | S41: {=_xlfn.IFS(H41="created",O41*P41*(1-Q41/100),H41="cancelled",-(O41*P41*(1-Q41/100)),H41="seats_change",(J41-I41)*P41*(1-Q41/100),H41="price_change",(J41-I41)*O41*(1-Q41/100),H41="discount_added",-(O41*P41*(J41-I41)/100),H41="plan_upgrade",O41*(_xlfn.XLOOKUP(J41,tbl_Plans[plan_name],tbl_Plans[monthly_price])-_xlfn.XLOOKUP(I41,tbl_Plans[plan_name],tbl_Plans[monthly_price]))*(1-Q41/100),H41="plan_downgrade",O41*(_xlfn.XLOOKUP(J41,tbl_Plans[plan_name],tbl_Plans[monthly_price])-_xlfn.XLOOKUP(I41,tbl_Plans[plan_name],tbl_Plans[monthly_price]))*(1-Q41/100))*IF(N41="Annual",1/12,1)} -> 1520
A42: EVT041 | B42: SUB027 | C42: CUST027 | D42: Pacific Finance Corp | E42: Western Canada | F42: 45658 | G42: 45663 | H42: created | M42: Sales Hub | N42: Monthly | O42: 28 | P42: 110 | Q42: 0 | R42: {=_xlfn.IFS(H42="created", "New", H42="cancelled", "Churned", AND(H42="seats_change", J42 > I42), "Expansion", AND(H42="seats_change", J42 < I42), "Contraction", AND(H42="price_change", J42 > I42), "Expansion", AND(H42="price_change", J42 < I42), "Contraction", H42="plan_upgrade", "Expansion", H42="plan_downgrade", "Contraction", H42="discount_added", "Contraction")} -> New | S42: {=_xlfn.IFS(H42="created",O42*P42*(1-Q42/100),H42="cancelled",-(O42*P42*(1-Q42/100)),H42="seats_change",(J42-I42)*P42*(1-Q42/100),H42="price_change",(J42-I42)*O42*(1-Q42/100),H42="discount_added",-(O42*P42*(J42-I42)/100),H42="plan_upgrade",O42*(_xlfn.XLOOKUP(J42,tbl_Plans[plan_name],tbl_Plans[monthly_price])-_xlfn.XLOOKUP(I42,tbl_Plans[plan_name],tbl_Plans[monthly_price]))*(1-Q42/100),H42="plan_downgrade",O42*(_xlfn.XLOOKUP(J42,tbl_Plans[plan_name],tbl_Plans[monthly_price])-_xlfn.XLOOKUP(I42,tbl_Plans[plan_name],tbl_Plans[monthly_price]))*(1-Q42/100))*IF(N42="Annual",1/12,1)} -> 3080
A43: EVT042 | B43: SUB014 | C43: CUST014 | D43: Toronto Media Group | E43: Eastern Canada | F43: 45658 | G43: 45665 | H43: price_change | I43: 80 | J43: 85 | K43: price_per_seat | L43: Annual price increase applied at renewal | M43: Marketing Pro | N43: Monthly | O43: 28 | P43: 85 | Q43: 0 | R43: {=_xlfn.IFS(H43="created", "New", H43="cancelled", "Churned", AND(H43="seats_change", J43 > I43), "Expansion", AND(H43="seats_change", J43 < I43), "Contraction", AND(H43="price_change", J43 > I43), "Expansion", AND(H43="price_change", J43 < I43), "Contraction", H43="plan_upgrade", "Expansion", H43="plan_downgrade", "Contraction", H43="discount_added", "Contraction")} -> Expansion | S43: {=_xlfn.IFS(H43="created",O43*P43*(1-Q43/100),H43="cancelled",-(O43*P43*(1-Q43/100)),H43="seats_change",(J43-I43)*P43*(1-Q43/100),H43="price_change",(J43-I43)*O43*(1-Q43/100),H43="discount_added",-(O43*P43*(J43-I43)/100),H43="plan_upgrade",O43*(_xlfn.XLOOKUP(J43,tbl_Plans[plan_name],tbl_Plans[monthly_price])-_xlfn.XLOOKUP(I43,tbl_Plans[plan_name],tbl_Plans[monthly_price]))*(1-Q43/100),H43="plan_downgrade",O43*(_xlfn.XLOOKUP(J43,tbl_Plans[plan_name],tbl_Plans[monthly_price])-_xlfn.XLOOKUP(I43,tbl_Plans[plan_name],tbl_Plans[monthly_price]))*(1-Q43/100))*IF(N43="Annual",1/12,1)} -> 140
A44: EVT043 | B44: SUB013 | C44: CUST013 | D44: Alberta Tech Innovators | E44: Western Canada | F44: 45658 | G44: 45672 | H44: cancelled | I44: active | J44: churned | K44: status | L44: Switched to competitor | M44: Analytics Starter | N44: Monthly | O44: 10 | P44: 45 | Q44: 0 | R44: {=_xlfn.IFS(H44="created", "New", H44="cancelled", "Churned", AND(H44="seats_change", J44 > I44), "Expansion", AND(H44="seats_change", J44 < I44), "Contraction", AND(H44="price_change", J44 > I44), "Expansion", AND(H44="price_change", J44 < I44), "Contraction", H44="plan_upgrade", "Expansion", H44="plan_downgrade", "Contraction", H44="discount_added", "Contraction")} -> Churned | S44: {=_xlfn.IFS(H44="created",O44*P44*(1-Q44/100),H44="cancelled",-(O44*P44*(1-Q44/100)),H44="seats_change",(J44-I44)*P44*(1-Q44/100),H44="price_change",(J44-I44)*O44*(1-Q44/100),H44="discount_added",-(O44*P44*(J44-I44)/100),H44="plan_upgrade",O44*(_xlfn.XLOOKUP(J44,tbl_Plans[plan_name],tbl_Plans[monthly_price])-_xlfn.XLOOKUP(I44,tbl_Plans[plan_name],tbl_Plans[monthly_price]))*(1-Q44/100),H44="plan_downgrade",O44*(_xlfn.XLOOKUP(J44,tbl_Plans[plan_name],tbl_Plans[monthly_price])-_xlfn.XLOOKUP(I44,tbl_Plans[plan_name],tbl_Plans[monthly_price]))*(1-Q44/100))*IF(N44="Annual",1/12,1)} -> -450
A45: EVT044 | B45: SUB028 | C45: CUST028 | D45: Prairie SaaS Innovations | E45: Central Canada | F45: 45658 | G45: 45677 | H45: created | M45: Analytics Starter | N45: Monthly | O45: 15 | P45: 45 | Q45: 0 | R45: {=_xlfn.IFS(H45="created", "New", H45="cancelled", "Churned", AND(H45="seats_change", J45 > I45), "Expansion", AND(H45="seats_change", J45 < I45), "Contraction", AND(H45="price_change", J45 > I45), "Expansion", AND(H45="price_change", J45 < I45), "Contraction", H45="plan_upgrade", "Expansion", H45="plan_downgrade", "Contraction", H45="discount_added", "Contraction")} -> New | S45: {=_xlfn.IFS(H45="created",O45*P45*(1-Q45/100),H45="cancelled",-(O45*P45*(1-Q45/100)),H45="seats_change",(J45-I45)*P45*(1-Q45/100),H45="price_change",(J45-I45)*O45*(1-Q45/100),H45="discount_added",-(O45*P45*(J45-I45)/100),H45="plan_upgrade",O45*(_xlfn.XLOOKUP(J45,tbl_Plans[plan_name],tbl_Plans[monthly_price])-_xlfn.XLOOKUP(I45,tbl_Plans[plan_name],tbl_Plans[monthly_price]))*(1-Q45/100),H45="plan_downgrade",O45*(_xlfn.XLOOKUP(J45,tbl_Plans[plan_name],tbl_Plans[monthly_price])-_xlfn.XLOOKUP(I45,tbl_Plans[plan_name],tbl_Plans[monthly_price]))*(1-Q45/100))*IF(N45="Annual",1/12,1)} -> 675
A46: EVT045 | B46: SUB054 | C46: CUST002 | D46: Pacific Analytics Inc | E46: Western Canada | F46: 45658 | G46: 45679 | H46: created | M46: Analytics Growth | N46: Annual | O46: 22 | P46: 1140 | Q46: 5 | R46: {=_xlfn.IFS(H46="created", "New", H46="cancelled", "Churned", AND(H46="seats_change", J46 > I46), "Expansion", AND(H46="seats_change", J46 < I46), "Contraction", AND(H46="price_change", J46 > I46), "Expansion", AND(H46="price_change", J46 < I46), "Contraction", H46="plan_upgrade", "Expansion", H46="plan_downgrade", "Contraction", H46="discount_added", "Contraction")} -> New | S46: {=_xlfn.IFS(H46="created",O46*P46*(1-Q46/100),H46="cancelled",-(O46*P46*(1-Q46/100)),H46="seats_change",(J46-I46)*P46*(1-Q46/100),H46="price_change",(J46-I46)*O46*(1-Q46/100),H46="discount_added",-(O46*P46*(J46-I46)/100),H46="plan_upgrade",O46*(_xlfn.XLOOKUP(J46,tbl_Plans[plan_name],tbl_Plans[monthly_price])-_xlfn.XLOOKUP(I46,tbl_Plans[plan_name],tbl_Plans[monthly_price]))*(1-Q46/100),H46="plan_downgrade",O46*(_xlfn.XLOOKUP(J46,tbl_Plans[plan_name],tbl_Plans[monthly_price])-_xlfn.XLOOKUP(I46,tbl_Plans[plan_name],tbl_Plans[monthly_price]))*(1-Q46/100))*IF(N46="Annual",1/12,1)} -> 1985.5
A47: EVT046 | B47: SUB057 | C47: CUST021 | D47: Calgary Commerce Solutions | E47: Western Canada | F47: 45658 | G47: 45685 | H47: created | M47: Platform Suite | N47: Monthly | O47: 28 | P47: 150 | Q47: 0 | R47: {=_xlfn.IFS(H47="created", "New", H47="cancelled", "Churned", AND(H47="seats_change", J47 > I47), "Expansion", AND(H47="seats_change", J47 < I47), "Contraction", AND(H47="price_change", J47 > I47), "Expansion", AND(H47="price_change", J47 < I47), "Contraction", H47="plan_upgrade", "Expansion", H47="plan_downgrade", "Contraction", H47="discount_added", "Contraction")} -> New | S47: {=_xlfn.IFS(H47="created",O47*P47*(1-Q47/100),H47="cancelled",-(O47*P47*(1-Q47/100)),H47="seats_change",(J47-I47)*P47*(1-Q47/100),H47="price_change",(J47-I47)*O47*(1-Q47/100),H47="discount_added",-(O47*P47*(J47-I47)/100),H47="plan_upgrade",O47*(_xlfn.XLOOKUP(J47,tbl_Plans[plan_name],tbl_Plans[monthly_price])-_xlfn.XLOOKUP(I47,tbl_Plans[plan_name],tbl_Plans[monthly_price]))*(1-Q47/100),H47="plan_downgrade",O47*(_xlfn.XLOOKUP(J47,tbl_Plans[plan_name],tbl_Plans[monthly_price])-_xlfn.XLOOKUP(I47,tbl_Plans[plan_name],tbl_Plans[monthly_price]))*(1-Q47/100))*IF(N47="Annual",1/12,1)} -> 4200
A48: EVT047 | B48: SUB029 | C48: CUST029 | D48: Halifax Healthcare Tech | E48: Eastern Canada | F48: 45689 | G48: 45691 | H48: created | M48: Marketing Pro | N48: Monthly | O48: 22 | P48: 85 | Q48: 0 | R48: {=_xlfn.IFS(H48="created", "New", H48="cancelled", "Churned", AND(H48="seats_change", J48 > I48), "Expansion", AND(H48="seats_change", J48 < I48), "Contraction", AND(H48="price_change", J48 > I48), "Expansion", AND(H48="price_change", J48 < I48), "Contraction", H48="plan_upgrade", "Expansion", H48="plan_downgrade", "Contraction", H48="discount_added", "Contraction")} -> New | S48: {=_xlfn.IFS(H48="created",O48*P48*(1-Q48/100),H48="cancelled",-(O48*P48*(1-Q48/100)),H48="seats_change",(J48-I48)*P48*(1-Q48/100),H48="price_change",(J48-I48)*O48*(1-Q48/100),H48="discount_added",-(O48*P48*(J48-I48)/100),H48="plan_upgrade",O48*(_xlfn.XLOOKUP(J48,tbl_Plans[plan_name],tbl_Plans[monthly_price])-_xlfn.XLOOKUP(I48,tbl_Plans[plan_name],tbl_Plans[monthly_price]))*(1-Q48/100),H48="plan_downgrade",O48*(_xlfn.XLOOKUP(J48,tbl_Plans[plan_name],tbl_Plans[monthly_price])-_xlfn.XLOOKUP(I48,tbl_Plans[plan_name],tbl_Plans[monthly_price]))*(1-Q48/100))*IF(N48="Annual",1/12,1)} -> 1870
A49: EVT048 | B49: SUB045 | C49: CUST010 | D49: Montreal Finance Hub | E49: Eastern Canada | F49: 45689 | G49: 45696 | H49: created | M49: Marketing Pro | N49: Monthly | O49: 13 | P49: 85 | Q49: 0 | R49: {=_xlfn.IFS(H49="created", "New", H49="cancelled", "Churned", AND(H49="seats_change", J49 > I49), "Expansion", AND(H49="seats_change", J49 < I49), "Contraction", AND(H49="price_change", J49 > I49), "Expansion", AND(H49="price_change", J49 < I49), "Contraction", H49="plan_upgrade", "Expansion", H49="plan_downgrade", "Contraction", H49="discount_added", "Contraction")} -> New | S49: {=_xlfn.IFS(H49="created",O49*P49*(1-Q49/100),H49="cancelled",-(O49*P49*(1-Q49/100)),H49="seats_change",(J49-I49)*P49*(1-Q49/100),H49="price_change",(J49-I49)*O49*(1-Q49/100),H49="discount_added",-(O49*P49*(J49-I49)/100),H49="plan_upgrade",O49*(_xlfn.XLOOKUP(J49,tbl_Plans[plan_name],tbl_Plans[monthly_price])-_xlfn.XLOOKUP(I49,tbl_Plans[plan_name],tbl_Plans[monthly_price]))*(1-Q49/100),H49="plan_downgrade",O49*(_xlfn.XLOOKUP(J49,tbl_Plans[plan_name],tbl_Plans[monthly_price])-_xlfn.XLOOKUP(I49,tbl_Plans[plan_name],tbl_Plans[monthly_price]))*(1-Q49/100))*IF(N49="Annual",1/12,1)} -> 1105
...

Sheet Waterfall
A1: MRR Waterfall - January 2024 to February 2026
A2: Month | B2: Opening | C2: New | D2: Expansion | E2: Contraction | F2: Churned | G2: Net | H2: Closing
A3: 45292 | B3: =0 -> 0 | C3: =SUMIFS(Engine!$S$2:$S$98, Engine!$R$2:$R$98, "New", Engine!$F$2:$F$98, Waterfall!A3) -> 5800 | D3: =SUMIFS(Engine!$S$2:$S$98, Engine!$R$2:$R$98, "Expansion", Engine!$F$2:$F$98, Waterfall!A3) -> 0 | E3: =SUMIFS(Engine!$S$2:$S$98, Engine!$R$2:$R$98, "Contraction", Engine!$F$2:$F$98, Waterfall!A3) -> 0 | F3: =SUMIFS(Engine!$S$2:$S$98, Engine!$R$2:$R$98, "Churned", Engine!$F$2:$F$98, Waterfall!A3) -> 0 | G3: =C3+D3+E3+F3 -> 5800 | H3: =B3+G3 -> 5800
