Workbook

Sheet Historical Baseline
A1: HISTORICAL BASELINE — 2024 & 2025 ACTUALS
A2: Fill this table from your MRR workbook and database. Show your source for every number.
A3: This is the foundation for the 2026 forecast. If these numbers are wrong, everything downstream is wrong.
A5: MRR WATERFALL (QUARTERLY)
A6: Metric | B6: Q1 2024 | C6: Q2 2024 | D6: Q3 2024 | E6: Q4 2024 | F6: Q1 2025 | G6: Q2 2025 | H6: Q3 2025 | I6: Q4 2025 | K6: Source
A7: Opening MRR | B7: =Waterfall!B3 -> 0 | C7: =B13 -> 20490 | D7: =C13 -> 35989 | E7: =D13 -> 63708.5 | F7: =E13 -> 91123.5 | G7: =F13 -> 126539.5 | H7: =G13 -> 152114.5 | I7: =H13 -> 150359.5 | K7: e.g. Waterfall tab, prior Q closing
A8: + New MRR | B8: =SUM(Waterfall!C3:C5) -> 20490 | C8: =SUM(Waterfall!C6:C8) -> 15499 | D8: =SUM(Waterfall!C9:C11) -> 29619.5 | E8: =SUM(Waterfall!C12:C14) -> 30000 | F8: =SUM(Waterfall!C15:C17) -> 36735.5 | G8: =SUM(Waterfall!C18:C20) -> 26470 | H8: =SUM(Waterfall!C21:C23) -> 0 | I8: =SUM(Waterfall!C24:C26) -> 935 | K8: Waterfall tab, sum of New column
A9: + Expansion MRR | B9: =SUM(Waterfall!D3:D5) -> 0 | C9: =SUM(Waterfall!D6:D8) -> 0 | D9: =SUM(Waterfall!D9:D11) -> 0 | E9: =SUM(Waterfall!D12:D14) -> 0 | F9: =SUM(Waterfall!D15:D17) -> 140 | G9: =SUM(Waterfall!D18:D20) -> 2785 | H9: =SUM(Waterfall!D21:D23) -> 5520 | I9: =SUM(Waterfall!D24:D26) -> 1765 | K9: Waterfall tab, sum of Expansion column
A10: − Contraction MRR | B10: =SUM(Waterfall!E3:E5) -> 0 | C10: =SUM(Waterfall!E6:E8) -> 0 | D10: =SUM(Waterfall!E9:E11) -> 0 | E10: =SUM(Waterfall!E12:E14) -> 0 | F10: =SUM(Waterfall!E15:E17) -> -1009.5 | G10: =SUM(Waterfall!E18:E20) -> 0 | H10: =SUM(Waterfall!E21:E23) -> -835 | I10: =SUM(Waterfall!E24:E26) -> -516.5 | K10: Waterfall tab, sum of Contraction column
A11: − Churned MRR | B11: =SUM(Waterfall!F3:F5) -> 0 | C11: =SUM(Waterfall!F6:F8) -> 0 | D11: =SUM(Waterfall!F9:F11) -> -1900 | E11: =SUM(Waterfall!F12:F14) -> -2585 | F11: =SUM(Waterfall!F15:F17) -> -450 | G11: =SUM(Waterfall!F18:F20) -> -3680 | H11: =SUM(Waterfall!F21:F23) -> -6440 | I11: =SUM(Waterfall!F24:F26) -> -1624.5 | K11: Waterfall tab, sum of Churned column
A12: Net New MRR | B12: =B13-B7 -> 20490 | C12: =C13-C7 -> 15499 | D12: =D13-D7 -> 27719.5 | E12: =E13-E7 -> 27415 | F12: =F13-F7 -> 35416 | G12: =G13-G7 -> 25575 | H12: =H13-H7 -> -1755 | I12: =I13-I7 -> -7290 | K12: Should equal Closing − Opening
A13: Closing MRR | B13: =Waterfall!H5 -> 20490 | C13: =Waterfall!H8 -> 35989 | D13: =Waterfall!H11 -> 63708.5 | E13: =Waterfall!H14 -> 91123.5 | F13: =Waterfall!H17 -> 126539.5 | G13: =Waterfall!H20 -> 152114.5 | H13: =Waterfall!H23 -> 150359.5 | I13: 143069.5 | K13: Waterfall tab, last month of quarter
A15: CUSTOMERS & SUBSCRIPTIONS
A16: Metric | B16: Q1 2024 | C16: Q2 2024 | D16: Q3 2024 | E16: Q4 2024 | F16: Q1 2025 | G16: Q2 2025 | H16: Q3 2025 | I16: Q4 2025 | K16: Source
A17: New customers | B17: =Retention!D19-0 -> 4 | C17: =Retention!G19-Retention!D19 -> 7 | D17: =Retention!J19-Retention!G19 -> 6 | E17: =Retention!M19-Retention!J19 -> 6 | F17: =Retention!Q19-Retention!N19 -> 6 | G17: =Retention!T19-Retention!Q19 -> 6 | H17: =Retention!V19-Retention!S19 -> 1 | I17: =SUM('Unit Economics'!J76:J78) -> 0 | K17: S&M data on Unit Economics tab
A18: Churned subscriptions | B18: =SUM(Retention!B17:D17) -> 0 | C18: =SUM(Retention!E17:G17) -> 0 | D18: =SUM(Retention!H17:J17) -> 1 | E18: =SUM(Retention!K17:M17) -> 2 | F18: =SUM(Retention!N17:P17) -> 1 | G18: =SUM(Retention!Q17:S17) -> 3 | H18: =SUM(Retention!T17:V17) -> 2 | I18: =SUM(Retention!W17:Y17) -> 1 | K18: Retention tab
A19: Active subscriptions (end of Q) | B19: =Retention!D16 -> 5 | C19: =Retention!G16 -> 13 | D19: =Retention!J16 -> 21 | E19: =Retention!M16 -> 31 | F19: =Retention!Q16 -> 46 | G19: =Retention!T16 -> 53 | H19: =Retention!W16 -> 51 | I19: =Retention!Z16 -> 51 | K19: Retention tab running count
A20: Active customers (end of Q) | B20: =Retention!D19 -> 4 | C20: =Retention!G19 -> 11 | D20: =Retention!J19 -> 17 | E20: =Retention!M19 -> 23 | F20: =Retention!Q19 -> 31 | G20: =Retention!T19 -> 37 | H20: =Retention!W19 -> 37 | I20: =Retention!Z19 -> 38 | K20: Unique cust IDs with ≥1 active sub
A22: P&L SUMMARY
A23: Metric | B23: Q1 2024 | C23: Q2 2024 | D23: Q3 2024 | E23: Q4 2024 | F23: Q1 2025 | G23: Q2 2025 | H23: Q3 2025 | I23: Q4 2025 | K23: Source
A24: Revenue | B24: =B13*3 -> 61470 | C24: =C13*3 -> 107967 | D24: =D13*3 -> 191125.5 | E24: =E13*3 -> 273370.5 | F24: =F13*3 -> 379618.5 | G24: =G13*3 -> 456343.5 | H24: =H13*3 -> 451078.5 | I24: =I13*3 -> 429208.5 | K24: Sum of monthly MRR from workbook
A25: COGS (30%) | B25: =B24*0.3 -> 18441 | C25: =C24*0.3 -> 32390.1 | D25: =D24*0.3 -> 57337.65 | E25: =E24*0.3 -> 82011.15 | F25: =F24*0.3 -> 113885.55 | G25: =G24*0.3 -> 136903.05 | H25: =H24*0.3 -> 135323.55 | I25: =I24*0.3 -> 128762.55 | K25: Revenue × 30%
A26: Gross Profit | B26: =B24-B25 -> 43029 | C26: =C24-C25 -> 75576.9 | D26: =D24-D25 -> 133787.85 | E26: =E24-E25 -> 191359.35 | F26: =F24-F25 -> 265732.95 | G26: =G24-G25 -> 319440.45 | H26: =H24-H25 -> 315754.95 | I26: =I24-I25 -> 300445.95 | K26: Revenue − COGS
A27: Gross Margin % | B27: =B26/B24 -> 0.7 | C27: =C26/C24 -> 0.7 | D27: =D26/D24 -> 0.7 | E27: =E26/E24 -> 0.7 | F27: =F26/F24 -> 0.7 | G27: =G26/G24 -> 0.7 | H27: =H26/H24 -> 0.7 | I27: =I26/I24 -> 0.7 | K27: GP / Revenue
A28: S&M | B28: 18500 | C28: 29000 | D28: 47000 | E28: 63000 | F28: ='Unit Economics'!I67+'Unit Economics'!I68+'Unit Economics'!I69 -> 88250 | G28: ='Unit Economics'!I70+'Unit Economics'!I71+'Unit Economics'!I72 -> 87550 | H28: ='Unit Economics'!I73+'Unit Economics'!I74+'Unit Economics'!I75 -> 91450 | I28: ='Unit Economics'!I76+'Unit Economics'!I77+'Unit Economics'!I78 -> 74150 | K28: Accounting data, Unit Economics tab
A29: R&D | B29: 15000 | C29: 25000 | D29: 42000 | E29: 57000 | F29: 62000 | G29: 68000 | H29: 72000 | I29: 65000 | K29: Company cost structure
A30: G&A | B30: 8000 | C30: 13000 | D30: 21000 | E30: 28000 | F30: 32000 | G30: 34000 | H30: 36000 | I30: 33000 | K30: Company cost structure
A31: Total OpEx | B31: =B28+B29+B30 -> 41500 | C31: =C28+C29+C30 -> 67000 | D31: =D28+D29+D30 -> 110000 | E31: =E28+E29+E30 -> 148000 | F31: =F28+F29+F30 -> 182250 | G31: =G28+G29+G30 -> 189550 | H31: =H28+H29+H30 -> 199450 | I31: =I28+I29+I30 -> 172150 | K31: S&M + R&D + G&A
A32: EBITDA | B32: =B26-B31 -> 1529 | C32: =C26-C31 -> 8576.9 | D32: =D26-D31 -> 23787.85 | E32: =E26-E31 -> 43359.35 | F32: =F26-F31 -> 83482.95 | G32: =G26-G31 -> 129890.45 | H32: =H26-H31 -> 116304.95 | I32: =I26-I31 -> 128295.95 | K32: Gross Profit − Total OpEx
A33: EBITDA Margin % | B33: =B32/B24 -> 0.024873922 | C33: =C32/C24 -> 0.079440014 | D33: =D32/D24 -> 0.12446194 | E33: =E32/E24 -> 0.1586102 | F33: =IF(F24=0,"",F32/F24) -> 0.21991275 | G33: =IF(G24=0,"",G32/G24) -> 0.28463307 | H33: =IF(H24=0,"",H32/H24) -> 0.25783749 | I33: =IF(I24=0,"",I32/I24) -> 0.29891288 | K33: EBITDA / Revenue
A35: KEY RATES (CALCULATED)
A36: Metric | B36: Q1 2024 | C36: Q2 2024 | D36: Q3 2024 | E36: Q4 2024 | F36: Q1 2025 | G36: Q2 2025 | H36: Q3 2025 | I36: Q4 2025 | K36: Source
A37: MRR churn rate (quarterly) | B37: =IF(B7=0,"",ABS(B11)/B7) | C37: =IF(C7=0,"",ABS(C11)/C7) -> 0 | D37: =IF(D7=0,"",ABS(D11)/D7) -> 0.052793909 | E37: =IF(E7=0,"",ABS(E11)/E7) -> 0.040575433 | F37: =IF(F7=0,"",ABS(F11)/F7) -> 0.0049383529 | G37: =IF(G7=0,"",ABS(G11)/G7) -> 0.029081828 | H37: =IF(H7=0,"",ABS(H11)/H7) -> 0.042336529 | I37: =IF(I7=0,"",ABS(I11)/I7) -> 0.010804106 | K37: Churned MRR / Opening MRR
A38: MRR expansion rate (quarterly) | B38: =IF(B7=0,"",B9/B7) | C38: =IF(C7=0,"",C9/C7) -> 0 | D38: =IF(D7=0,"",D9/D7) -> 0 | E38: =IF(E7=0,"",E9/E7) -> 0 | F38: =IF(F7=0,"",F9/F7) -> 0.0015363765 | G38: =IF(G7=0,"",G9/G7) -> 0.022008938 | H38: =IF(H7=0,"",H9/H7) -> 0.036288454 | I38: =IF(I7=0,"",I9/I7) -> 0.011738533 | K38: Expansion MRR / Opening MRR
A39: Avg MRR per new customer | B39: =IF(B17=0,"",B8/B17) -> 5122.5 | C39: =IF(C17=0,"",C8/C17) -> 2214.1429 | D39: =IF(D17=0,"",D8/D17) -> 4936.5833 | E39: =IF(E17=0,"",E8/E17) -> 5000 | F39: =IF(F17=0,"",F8/F17) -> 6122.5833 | G39: =IF(G17=0,"",G8/G17) -> 4411.6667 | H39: =IF(H17=0,"",H8/H17) -> 0 | I39: N/A | K39: New MRR / New customers
A40: CAC (quarterly S&M / new custs) | B40: =IF(B17=0,"N/A",B28/B17) -> 4625 | C40: =IF(C17=0,"N/A",C28/C17) -> 4142.8571 | D40: =IF(D17=0,"N/A",D28/D17) -> 7833.3333 | E40: =IF(E17=0,"N/A",E28/E17) -> 10500 | F40: =IF(F17=0,"N/A",F28/F17) -> 14708.333 | G40: =IF(G17=0,"N/A",G28/G17) -> 14591.667 | H40: =IF(H17=0,"N/A",H28/H17) -> 91450 | I40: =IF(I17=0,"N/A",I28/I17) -> N/A | K40: Only meaningful if new custs > 0
A43: RECONCILIATION NOTES
A44: Dec 2025 closing MRR (this table): | B44: =I13 -> 143069.5
A45: Feb 2026 snapshot MRR: | B45: ='Unit Economics'!B6 -> 144185.5
A46: Difference: | B46: =B44-B45 -> -1116
...

Sheet Forecast Assumptions
A1: 2026 FORECAST ASSUMPTIONS
A2: From: David Chen, VP Finance — Leadership planning meeting, December 2025
A3: All values are hardcoded inputs. Every formula on the Forecast tab must reference these cells.
A5: STARTING POSITION
A6: Opening MRR (Jan 2026) | B6: ='Historical Baseline'!B44 -> 143069.5 | D6: ← Pull from your Historical Baseline tab
A7: Active subscriptions (Dec 2025) | B7: ='Historical Baseline'!I19 -> 51 | D7: ← Pull from your Historical Baseline tab
A8: Active customers (Dec 2025) | B8: ='Historical Baseline'!I20 -> 38 | D8: ← Pull from your Historical Baseline tab
A10: GROWTH ASSUMPTIONS
A11: Metric | B11: Q1 2026 | C11: Q2 2026 | D11: Q3 2026 | E11: Q4 2026
A12: New customers | B12: 4 | C12: 6 | D12: 9 | E12: 9
A13: Avg MRR per new customer | B13: 3000 | C13: 3200 | D13: 3200 | E13: 3400
A14: Quarterly expansion rate | B14: 0.015 | C14: 0.015 | D14: 0.015 | E14: 0.015
A15: Quarterly churn rate | B15: 0.02 | C15: 0.02 | D15: 0.02 | E15: 0.02
A17: Expansion rate: 0.50%/month compounded to quarterly. Seat adds + upsells from existing base.
A18: Churn rate: 0.67%/month compounded to quarterly. Target ~8% annual (down from 2025 actual).
A19: Both rates apply to BEGINNING-of-quarter MRR, not ending.
A21: MARGIN
A22: Gross margin | B22: 0.7 | C22: Same across all quarters — no cost structure changes planned.
A24: OPERATING EXPENSES
A25: Metric | B25: Q1 2026 | C25: Q2 2026 | D25: Q3 2026 | E25: Q4 2026
A26: Sales & Marketing | B26: 90000 | C26: 90000 | D26: 108000 | E26: 108000
A27: Research & Development | B27: 75000 | C27: 75000 | D27: 75000 | E27: 75000
A28: General & Administrative | B28: 57000 | C28: 57000 | D28: 57000 | E28: 57000
A29: Total OpEx | B29: 222000 | C29: 222000 | D29: 240000 | E29: 240000
A31: S&M increases H2 to fund acquisition push. Not repeating H2 2025 drought.
A33: REVENUE CONVENTION
A34: Quarterly Revenue = Closing MRR × 3
A35: This is the standard convention for forward-looking models: the ending run-rate × months in the period.

Sheet 2026 Forecast
A2: Build formulas referencing the Assumptions tab. No hardcoded numbers.
A3: Black font = formulas. Green font = cross-tab references.
A5: MRR WATERFALL
A6: Metric | B6: Q1 2026 | C6: Q2 2026 | D6: Q3 2026 | E6: Q4 2026 | G6: FY 2026 | I6: Formula hints
A7: Opening MRR | B7: ='Forecast Assumptions'!B6 -> 143069.5 | C7: =B12 -> 154354.15 | D7: =C12 -> 172782.38 | E7: =D12 -> 200718.47 | G7: =B7 -> 143069.5 | I7: Q1 = Opening from Assumptions. Q2+ = prior Q closing.
A8: + New MRR | B8: ='Forecast Assumptions'!B12*'Forecast Assumptions'!B13 -> 12000 | C8: ='Forecast Assumptions'!C12*'Forecast Assumptions'!C13 -> 19200 | D8: ='Forecast Assumptions'!D12*'Forecast Assumptions'!D13 -> 28800 | E8: ='Forecast Assumptions'!E12*'Forecast Assumptions'!E13 -> 30600 | G8: =B8+C8+D8+E8 -> 90600 | I8: → New customers × Avg MRR per new customer
A9: + Expansion MRR | B9: =B7*'Forecast Assumptions'!B14 -> 2146.0425 | C9: =C7*'Forecast Assumptions'!C14 -> 2315.3123 | D9: =D7*'Forecast Assumptions'!D14 -> 2591.7357 | E9: =E7*'Forecast Assumptions'!E14 -> 3010.777 | G9: =B9+C9+D9+E9 -> 10063.868 | I9: → Opening MRR × quarterly expansion rate
A10: − Churned MRR | B10: =B7*'Forecast Assumptions'!B15 -> 2861.39 | C10: =C7*'Forecast Assumptions'!C15 -> 3087.0831 | D10: =D7*'Forecast Assumptions'!D15 -> 3455.6476 | E10: =E7*'Forecast Assumptions'!E15 -> 4014.3694 | G10: =B10+C10+D10+E10 -> 13418.49 | I10: → Opening MRR × quarterly churn rate
A11: Net New MRR | B11: =B8+B9-B10 -> 11284.653 | C11: =C8+C9-C10 -> 18428.229 | D11: =D8+D9-D10 -> 27936.088 | E11: =E8+E9-E10 -> 29596.408 | G11: =G8+G9-G10 -> 87245.377 | I11: → New + Expansion − Churned
A12: Closing MRR | B12: =B7+B11 -> 154354.15 | C12: =C7+C11 -> 172782.38 | D12: =D7+D11 -> 200718.47 | E12: =E7+E11 -> 230314.88 | G12: =E12 -> 230314.88 | I12: → Opening + Net New
A13: Closing ARR | B13: =B12*12 -> 1852249.8 | C13: =C12*12 -> 2073388.6 | D13: =D12*12 -> 2408621.6 | E13: =E12*12 -> 2763778.5 | G13: =G12*12 -> 2763778.5 | I13: → Closing MRR × 12
G14: ← Opening = Q1
G15: ← Sums for flows
G16: ← Q4 closing for balances
A18: PROFIT & LOSS
A19: Metric | B19: Q1 2026 | C19: Q2 2026 | D19: Q3 2026 | E19: Q4 2026 | G19: FY 2026
A20: Revenue | B20: =B12*3 -> 463062.46 | C20: =C12*3 -> 518347.15 | D20: =D12*3 -> 602155.41 | E20: =E12*3 -> 690944.63 | G20: =B20+C20+D20+E20 -> 2274509.6 | I20: → Closing MRR × 3
A21: COGS | B21: =B20*(1-'Forecast Assumptions'!B22) -> 138918.74 | C21: =C20*(1-'Forecast Assumptions'!B22) -> 155504.14 | D21: =D20*(1-'Forecast Assumptions'!B22) -> 180646.62 | E21: =E20*(1-'Forecast Assumptions'!B22) -> 207283.39 | G21: =B21+C21+D21+E21 -> 682352.89 | I21: → Revenue × (1 − gross margin)
A22: Gross Profit | B22: =B20-B21 -> 324143.72 | C22: =C20-C21 -> 362843 | D22: =D20-D21 -> 421508.79 | E22: =E20-E21 -> 483661.24 | G22: =B22+C22+D22+E22 -> 1592156.8 | I22: → Revenue − COGS
A23: Gross Margin % | B23: =B22/B20 -> 0.7 | C23: =C22/C20 -> 0.7 | D23: =D22/D20 -> 0.7 | E23: =E22/E20 -> 0.7 | G23: =G22/G20 -> 0.7 | I23: → GP / Revenue
A25: Sales & Marketing | B25: ='Forecast Assumptions'!B26 -> 90000 | C25: ='Forecast Assumptions'!C26 -> 90000 | D25: ='Forecast Assumptions'!D26 -> 108000 | E25: ='Forecast Assumptions'!E26 -> 108000 | G25: =B25+C25+D25+E25 -> 396000 | I25: ← From Assumptions tab
A26: Research & Development | B26: ='Forecast Assumptions'!B27 -> 75000 | C26: ='Forecast Assumptions'!C27 -> 75000 | D26: ='Forecast Assumptions'!D27 -> 75000 | E26: ='Forecast Assumptions'!E27 -> 75000 | G26: =B26+C26+D26+E26 -> 300000 | I26: ← From Assumptions tab
A27: General & Administrative | B27: ='Forecast Assumptions'!B28 -> 57000 | C27: ='Forecast Assumptions'!C28 -> 57000 | D27: ='Forecast Assumptions'!D28 -> 57000 | E27: ='Forecast Assumptions'!E28 -> 57000 | G27: =B27+C27+D27+E27 -> 228000 | I27: ← From Assumptions tab
A28: Total OpEx | B28: =B25+B26+B27 -> 222000 | C28: =C25+C26+C27 -> 222000 | D28: =D25+D26+D27 -> 240000 | E28: =E25+E26+E27 -> 240000 | G28: =G25+G26+G27 -> 924000 | I28: S&M + R&D + G&A
A30: EBITDA | B30: =B22-B28 -> 102143.72 | C30: =C22-C28 -> 140843 | D30: =D22-D28 -> 181508.79 | E30: =E22-E28 -> 243661.24 | G30: =B30+C30+D30+E30 -> 668156.75 | I30: → Gross Profit − Total OpEx
A31: EBITDA Margin % | B31: =B30/B20 -> 0.22058303 | C31: =C30/C20 -> 0.27171559 | D31: =D30/D20 -> 0.3014318 | E31: =E30/E20 -> 0.35264945 | G31: =G30/G20 -> 0.29375859 | I31: → EBITDA / Revenue
A33: KEY METRICS
A34: Dec 2026 MRR | B34: =E12 -> 230314.88 | I34: → Q4 Closing MRR
A35: Dec 2026 ARR | B35: =B34*12 -> 2763778.5 | I35: → Dec MRR × 12
A36: FY Revenue | B36: =G20 -> 2274509.6 | I36: → Sum of quarterly revenue
A37: MRR Growth % | B37: =(E12-B7)/B7 -> 0.60981116 | I37: → (Closing − Opening) / Opening
A38: New Customers (FY) | B38: ='Forecast Assumptions'!B12+'Forecast Assumptions'!C12+'Forecast Assumptions'!D12+'Forecast Assumptions'!E12 -> 28 | I38: → Sum from Assumptions
A39: Blended CAC | B39: =G25/B38 -> 14142.857 | I39: Total S&M / New customers
A40: CMGR | B40: =(E12/B7)^(1/12)-1 -> 0.040474029 | I40: → (Dec MRR / Jan Opening MRR)^(1/12) − 1 [monthly rate, standard]
A43: SELF-CHECK VALUES | E43: Assumes opening MRR = $143,069.50. Our opening is $150,918.50 (Waterfall tab, Dec 2025 closing). Same model logic, different starting MRR.
A44: Check | B44: Expected | C44: Your Value | D44: Match?
A45: Q1 Closing MRR | B45: 154354.15 | C45: =B12 -> 154354.15 | D45: =IF(ROUND(C45,2)=ROUND(B45,2),"✓","✗ diff: "&TEXT(C45-B45,"$#,##0.00")) -> ✓
A46: Q2 Closing MRR | B46: 172782.38 | C46: =C12 -> 172782.38 | D46: =IF(ROUND(C46,2)=ROUND(B46,2),"✓","✗ diff: "&TEXT(C46-B46,"$#,##0.00")) -> ✓
A47: Q3 Closing MRR | B47: 200718.47 | C47: =D12 -> 200718.47 | D47: =IF(ROUND(C47,2)=ROUND(B47,2),"✓","✗ diff: "&TEXT(C47-B47,"$#,##0.00")) -> ✓
A48: Q4 Closing MRR | B48: 230314.88 | C48: =E12 -> 230314.88 | D48: =IF(ROUND(C48,2)=ROUND(B48,2),"✓","✗ diff: "&TEXT(C48-B48,"$#,##0.00")) -> ✓
...

Sheet Jan 2026 A vs F 
A1: MRR Waterfall
A2: Metric | B2: Actual - Jan 26 | C2: Forecast - Jan 26 | D2: $ Variance | E2: % Variance | F2: F/U
A3: Opening MRR | B3: 143069.5 | C3: ='2026 Forecast'!B7 -> 143069.5 | D3: =B3-C3 -> 0 | E3: =B3/C3-1 -> 0 | F3: {=_xlfn.IFS(D3<0, "U", D3>0, "F", D3=0, "-")} -> -
A4: + New MRR | B4: 1710 | C4: 4000 | D4: =B4-C4 -> -2290 | E4: =B4/C4-1 -> -0.5725 | F4: {=_xlfn.IFS(D4<0, "U", D4>0, "F", D4=0, "-")} -> U
A5: + Expansion MRR | B5: 0 | C5: ='2026 Forecast'!B9/3 -> 715.3475 | D5: =B5-C5 -> -715.3475 | E5: =B5/C5-1 -> -1 | F5: {=_xlfn.IFS(D5<0, "U", D5>0, "F", D5=0, "-")} -> U
A6: − Churned MRR | B6: 0 | C6: ='2026 Forecast'!B10/3 -> 953.79667 | D6: =B6-C6 -> -953.79667 | E6: =B6/C6-1 -> -1 | F6: {=_xlfn.IFS(D6>0, "U", D6<0, "F", D6=0, "-")} -> F
A7: Net New MRR | B7: =B4+B5-B6 -> 1710 | C7: =C4+C5-C6 -> 3761.5508 | D7: =B7-C7 -> -2051.5508 | E7: =B7/C7-1 -> -0.54540027 | F7: {=_xlfn.IFS(D7<0, "U", D7>0, "F", D7=0, "-")} -> U
A8: Closing MRR | B8: =B3+B4+B5-B6 -> 144779.5 | C8: =C3+C7 -> 146831.05 | D8: =B8-C8 -> -2051.5508 | E8: =B8/C8-1 -> -0.013972187 | F8: {=_xlfn.IFS(D8<0, "U", D8>0, "F", D8=0, "-")} -> U
A9: Closing ARR | B9: =B8*12 -> 1737354 | C9: =C8*12 -> 1761972.6 | D9: =B9-C9 -> -24618.61 | E9: =B9/C9-1 -> -0.013972187 | F9: {=_xlfn.IFS(D9<0, "U", D9>0, "F", D9=0, "-")} -> U
A11: P&L
A12: Metric | B12: Actual - Jan 26 | C12: Forecast - Jan 26 | D12: $ Variance | E12: % Variance | F12: F/U
A13: Revenue | B13: =B8 -> 144779.5 | C13: =C8 -> 146831.05 | D13: =B13-C13 -> -2051.5508 | E13: =B13/C13-1 -> -0.013972187 | F13: {=_xlfn.IFS(D13<0, "U", D13>0, "F", D13=0, "-")} -> U
A14: COGS | B14: =B13*(1-B16) -> 43433.85 | C14: =C13*0.3 -> 44049.315 | D14: =B14-C14 -> -615.46525 | E14: =B14/C14-1 -> -0.013972187 | F14: {=_xlfn.IFS(D14>0, "U", D14<0, "F", D14=0, "-")} -> F | H14: → Revenue × (1 − gross margin)
A15: Gross Profit | B15: =B13-B14 -> 101345.65 | C15: =C13-C14 -> 102781.74 | D15: =B15-C15 -> -1436.0856 | E15: =B15/C15-1 -> -0.013972187 | F15: {=_xlfn.IFS(D15<0, "U", D15>0, "F", D15=0, "-")} -> U | H15: → Revenue − COGS
A16: Gross Margin % | B16: 0.7 | C16: =C15/C13 -> 0.7 | E16: =B16/C16-1 -> 0 | F16: {=_xlfn.IFS(D16<0, "U", D16>0, "F", D16=0, "-")} -> - | H16: → GP / Revenue
A17: Sales & Marketing | B17: ='Forecast Assumptions'!B26/3 -> 30000 | C17: ='2026 Forecast'!B25/3 -> 30000 | D17: =B17-C17 -> 0 | E17: =B17/C17-1 -> 0 | F17: {=_xlfn.IFS(D17<0, "U", D17>0, "F", D17=0, "-")} -> - | H17: ← From Assumptions tab
A18: Research & Development | B18: ='Forecast Assumptions'!B27/3 -> 25000 | C18: ='2026 Forecast'!B26/3 -> 25000 | D18: =B18-C18 -> 0 | E18: =B18/C18-1 -> 0 | F18: {=_xlfn.IFS(D18<0, "U", D18>0, "F", D18=0, "-")} -> - | H18: ← From Assumptions tab
A19: General & Administrative | B19: ='Forecast Assumptions'!B28/3 -> 19000 | C19: ='2026 Forecast'!B27/3 -> 19000 | D19: =B19-C19 -> 0 | E19: =B19/C19-1 -> 0 | F19: {=_xlfn.IFS(D19<0, "U", D19>0, "F", D19=0, "-")} -> - | H19: ← From Assumptions tab
A20: Total OpEx | B20: =SUM(B17:B19) -> 74000 | C20: ='2026 Forecast'!B28/3 -> 74000 | D20: =B20-C20 -> 0 | E20: =B20/C20-1 -> 0 | F20: {=_xlfn.IFS(D20<0, "U", D20>0, "F", D20=0, "-")} -> - | H20: S&M + R&D + G&A
A21: EBITDA | B21: =B15-B20 -> 27345.65 | C21: =C15-C20 -> 28781.736 | D21: =B21-C21 -> -1436.0856 | E21: =B21/C21-1 -> -0.049895726 | F21: {=_xlfn.IFS(D21<0, "U", D21>0, "F", D21=0, "-")} -> U | H21: → Gross Profit − Total OpEx
A22: EBITDA Margin % | B22: =B21/B13 -> 0.18887791 | C22: =C21/C13 -> 0.19601941 | D22: =B22-C22 -> -0.0071414931 | E22: =B22/C22-1 -> -0.036432582 | F22: {=_xlfn.IFS(D22<0, "U", D22>0, "F", D22=0, "-")} -> U | H22: → EBITDA / Revenue
A24: Summary:
A25: January closed with an MRR of $144,780, -$2,051.55 (-1.4%) below expectation.
A26: This is due to the lack of new customers acquired this month.
A27: There was only 1 new customer signing this month which is less than the expected 1.3 new customers
A28: The customers revenue was $1,710 which is 43% less than the planned rate of $3000 per customer.
A29: There was no expansion recorded this month versus the expected $715.35.
A30: Offsetting this was the lack of churned MRR this month which resulted in a favorable variance of $954.
A31: EBITDA of $27,345.65 was 5% lower than the expected $28,781.74. This was driven by the shortfall in Gross Profit due to the Closing MRR being less than anticipated.
A32: Operating Expenses were in line with expectation.
A33: Currently, Q1 is approximately $6000 less than planned, which could be fixed with a strong performance in February.

Sheet Engine
A1: event_id | B1: subscription_id | C1: customer_id | D1: company_name | E1: region | F1: month | G1: event_date | H1: event_type | I1: old_value | J1: new_value | K1: field_changed | L1: reason | M1: plan_name | N1: billing_cycle | O1: seats | P1: price_per_seat | Q1: discount_percent | R1: movement | S1: mrr_delta | T1: is_new_logo | U1: is_logo_churn | V1: is_logo_reactivation
A2: EVT001 | B2: SUB001 | C2: CUST001 | D2: TechVision Solutions | E2: Eastern Canada | F2: 45292 | G2: 45299 | H2: created | M2: Analytics Growth | N2: Monthly | O2: 20 | P2: 95 | Q2: 0 | R2: {=_xlfn.IFS(H2="created", "New", H2="cancelled", "Churned", AND(H2="seats_change", J2 > I2), "Expansion", AND(H2="seats_change", J2 < I2), "Contraction", AND(H2="price_change", J2 > I2), "Expansion", AND(H2="price_change", J2 < I2), "Contraction", H2="plan_upgrade", "Expansion", H2="plan_downgrade", "Contraction", H2="discount_added", "Contraction")} -> New | S2: {=IF(N2="Monthly",_xlfn.IFS(H2="created",O2*P2*(1-Q2/100),H2="cancelled",-(O2*P2*(1-Q2/100)),H2="seats_change",(J2-I2)*P2*(1-Q2/100),H2="price_change",(J2-I2)*O2*(1-Q2/100),H2="discount_added",-(O2*P2*(J2-I2)/100),H2="plan_upgrade",O2*(_xlfn.XLOOKUP(J2,$M:$M,$P:$P)-_xlfn.XLOOKUP(I2,$M:$M,$P:$P))*(1-Q2/100),H2="plan_downgrade",O2*(_xlfn.XLOOKUP(J2,$M:$M,$P:$P)-_xlfn.XLOOKUP(I2,$M:$M,$P:$P))*(1-Q2/100)),_xlfn.IFS(H2="created",O2*P2*(1-Q2/100)/12,H2="cancelled",-(O2*P2*(1-Q2/100))/12,H2="seats_change",(J2-I2)*P2*(1-Q2/100)/12,H2="price_change",(J2-I2)*O2*(1-Q2/100)/12,H2="plan_upgrade",(O2*(_xlfn.XLOOKUP(J2,$M:$M,$P:$P)-_xlfn.XLOOKUP(I2,$M:$M,$P:$P))*(1-Q2/100))/12,H2="plan_downgrade",(O2*(_xlfn.XLOOKUP(J2,$M:$M,$P:$P)-_xlfn.XLOOKUP(I2,$M:$M,$P:$P))*(1-Q2/100))/12,H2="discount_added",-(O2*P2*(J2-I2)/100)/12))} -> 1900 | T2: =IF(H2<>"created",0,IF(COUNTIFS($C$1:C1,$C2,$H$1:H1,"created")=0,1,0)) -> 1 | U2: =IF(H2<>"cancelled",0,IF(COUNTIFS($C$2:$C$98,$C2,$H$2:$H$98,"created",$F$2:$F$98,"<="&F2)-COUNTIFS($C$2:$C$98,$C2,$H$2:$H$98,"cancelled",$F$2:$F$98,"<="&F2)=0,1,0)) -> 0 | V2: =IF(AND(H2="created",T2=0,COUNTIFS($C$2:$C$98,$C2,$H$2:$H$98,"cancelled",$F$2:$F$98,"<"&F2)>0,COUNTIFS($C$2:$C$98,$C2,$H$2:$H$98,"created",$F$2:$F$98,"<"&F2)-COUNTIFS($C$2:$C$98,$C2,$H$2:$H$98,"cancelled",$F$2:$F$98,"<"&F2)=0),1,0) -> 0
A3: EVT002 | B3: SUB002 | C3: CUST002 | D3: Pacific Analytics Inc | E3: Western Canada | F3: 45292 | G3: 45313 | H3: created | M3: Platform Suite | N3: Annual | O3: 26 | P3: 1800 | Q3: 0 | R3: {=_xlfn.IFS(H3="created", "New", H3="cancelled", "Churned", AND(H3="seats_change", J3 > I3), "Expansion", AND(H3="seats_change", J3 < I3), "Contraction", AND(H3="price_change", J3 > I3), "Expansion", AND(H3="price_change", J3 < I3), "Contraction", H3="plan_upgrade", "Expansion", H3="plan_downgrade", "Contraction", H3="discount_added", "Contraction")} -> New | S3: {=IF(N3="Monthly",_xlfn.IFS(H3="created",O3*P3*(1-Q3/100),H3="cancelled",-(O3*P3*(1-Q3/100)),H3="seats_change",(J3-I3)*P3*(1-Q3/100),H3="price_change",(J3-I3)*O3*(1-Q3/100),H3="discount_added",-(O3*P3*(J3-I3)/100),H3="plan_upgrade",O3*(_xlfn.XLOOKUP(J3,$M:$M,$P:$P)-_xlfn.XLOOKUP(I3,$M:$M,$P:$P))*(1-Q3/100),H3="plan_downgrade",O3*(_xlfn.XLOOKUP(J3,$M:$M,$P:$P)-_xlfn.XLOOKUP(I3,$M:$M,$P:$P))*(1-Q3/100)),_xlfn.IFS(H3="created",O3*P3*(1-Q3/100)/12,H3="cancelled",-(O3*P3*(1-Q3/100))/12,H3="seats_change",(J3-I3)*P3*(1-Q3/100)/12,H3="price_change",(J3-I3)*O3*(1-Q3/100)/12,H3="plan_upgrade",(O3*(_xlfn.XLOOKUP(J3,$M:$M,$P:$P)-_xlfn.XLOOKUP(I3,$M:$M,$P:$P))*(1-Q3/100))/12,H3="plan_downgrade",(O3*(_xlfn.XLOOKUP(J3,$M:$M,$P:$P)-_xlfn.XLOOKUP(I3,$M:$M,$P:$P))*(1-Q3/100))/12,H3="discount_added",-(O3*P3*(J3-I3)/100)/12))} -> 3900 | T3: =IF(H3<>"created",0,IF(COUNTIFS($C$1:C2,$C3,$H$1:H2,"created")=0,1,0)) -> 1 | U3: =IF(H3<>"cancelled",0,IF(COUNTIFS($C$2:$C$98,$C3,$H$2:$H$98,"created",$F$2:$F$98,"<="&F3)-COUNTIFS($C$2:$C$98,$C3,$H$2:$H$98,"cancelled",$F$2:$F$98,"<="&F3)=0,1,0)) -> 0 | V3: =IF(AND(H3="created",T3=0,COUNTIFS($C$2:$C$98,$C3,$H$2:$H$98,"cancelled",$F$2:$F$98,"<"&F3)>0,COUNTIFS($C$2:$C$98,$C3,$H$2:$H$98,"created",$F$2:$F$98,"<"&F3)-COUNTIFS($C$2:$C$98,$C3,$H$2:$H$98,"cancelled",$F$2:$F$98,"<"&F3)=0),1,0) -> 0
A4: EVT003 | B4: SUB003 | C4: CUST003 | D4: Maple Healthcare Systems | E4: Eastern Canada | F4: 45323 | G4: 45327 | H4: created | M4: Marketing Pro | N4: Monthly | O4: 23 | P4: 85 | Q4: 0 | R4: {=_xlfn.IFS(H4="created", "New", H4="cancelled", "Churned", AND(H4="seats_change", J4 > I4), "Expansion", AND(H4="seats_change", J4 < I4), "Contraction", AND(H4="price_change", J4 > I4), "Expansion", AND(H4="price_change", J4 < I4), "Contraction", H4="plan_upgrade", "Expansion", H4="plan_downgrade", "Contraction", H4="discount_added", "Contraction")} -> New | S4: {=IF(N4="Monthly",_xlfn.IFS(H4="created",O4*P4*(1-Q4/100),H4="cancelled",-(O4*P4*(1-Q4/100)),H4="seats_change",(J4-I4)*P4*(1-Q4/100),H4="price_change",(J4-I4)*O4*(1-Q4/100),H4="discount_added",-(O4*P4*(J4-I4)/100),H4="plan_upgrade",O4*(_xlfn.XLOOKUP(J4,$M:$M,$P:$P)-_xlfn.XLOOKUP(I4,$M:$M,$P:$P))*(1-Q4/100),H4="plan_downgrade",O4*(_xlfn.XLOOKUP(J4,$M:$M,$P:$P)-_xlfn.XLOOKUP(I4,$M:$M,$P:$P))*(1-Q4/100)),_xlfn.IFS(H4="created",O4*P4*(1-Q4/100)/12,H4="cancelled",-(O4*P4*(1-Q4/100))/12,H4="seats_change",(J4-I4)*P4*(1-Q4/100)/12,H4="price_change",(J4-I4)*O4*(1-Q4/100)/12,H4="plan_upgrade",(O4*(_xlfn.XLOOKUP(J4,$M:$M,$P:$P)-_xlfn.XLOOKUP(I4,$M:$M,$P:$P))*(1-Q4/100))/12,H4="plan_downgrade",(O4*(_xlfn.XLOOKUP(J4,$M:$M,$P:$P)-_xlfn.XLOOKUP(I4,$M:$M,$P:$P))*(1-Q4/100))/12,H4="discount_added",-(O4*P4*(J4-I4)/100)/12))} -> 1955 | T4: =IF(H4<>"created",0,IF(COUNTIFS($C$1:C3,$C4,$H$1:H3,"created")=0,1,0)) -> 1 | U4: =IF(H4<>"cancelled",0,IF(COUNTIFS($C$2:$C$98,$C4,$H$2:$H$98,"created",$F$2:$F$98,"<="&F4)-COUNTIFS($C$2:$C$98,$C4,$H$2:$H$98,"cancelled",$F$2:$F$98,"<="&F4)=0,1,0)) -> 0 | V4: =IF(AND(H4="created",T4=0,COUNTIFS($C$2:$C$98,$C4,$H$2:$H$98,"cancelled",$F$2:$F$98,"<"&F4)>0,COUNTIFS($C$2:$C$98,$C4,$H$2:$H$98,"created",$F$2:$F$98,"<"&F4)-COUNTIFS($C$2:$C$98,$C4,$H$2:$H$98,"cancelled",$F$2:$F$98,"<"&F4)=0),1,0) -> 0
A5: EVT004 | B5: SUB004 | C5: CUST004 | D5: Prairie Commerce Group | E5: Western Canada | F5: 45323 | G5: 45341 | H5: created | M5: Sales Hub | N5: Monthly | O5: 18 | P5: 110 | Q5: 0 | R5: {=_xlfn.IFS(H5="created", "New", H5="cancelled", "Churned", AND(H5="seats_change", J5 > I5), "Expansion", AND(H5="seats_change", J5 < I5), "Contraction", AND(H5="price_change", J5 > I5), "Expansion", AND(H5="price_change", J5 < I5), "Contraction", H5="plan_upgrade", "Expansion", H5="plan_downgrade", "Contraction", H5="discount_added", "Contraction")} -> New | S5: {=IF(N5="Monthly",_xlfn.IFS(H5="created",O5*P5*(1-Q5/100),H5="cancelled",-(O5*P5*(1-Q5/100)),H5="seats_change",(J5-I5)*P5*(1-Q5/100),H5="price_change",(J5-I5)*O5*(1-Q5/100),H5="discount_added",-(O5*P5*(J5-I5)/100),H5="plan_upgrade",O5*(_xlfn.XLOOKUP(J5,$M:$M,$P:$P)-_xlfn.XLOOKUP(I5,$M:$M,$P:$P))*(1-Q5/100),H5="plan_downgrade",O5*(_xlfn.XLOOKUP(J5,$M:$M,$P:$P)-_xlfn.XLOOKUP(I5,$M:$M,$P:$P))*(1-Q5/100)),_xlfn.IFS(H5="created",O5*P5*(1-Q5/100)/12,H5="cancelled",-(O5*P5*(1-Q5/100))/12,H5="seats_change",(J5-I5)*P5*(1-Q5/100)/12,H5="price_change",(J5-I5)*O5*(1-Q5/100)/12,H5="plan_upgrade",(O5*(_xlfn.XLOOKUP(J5,$M:$M,$P:$P)-_xlfn.XLOOKUP(I5,$M:$M,$P:$P))*(1-Q5/100))/12,H5="plan_downgrade",(O5*(_xlfn.XLOOKUP(J5,$M:$M,$P:$P)-_xlfn.XLOOKUP(I5,$M:$M,$P:$P))*(1-Q5/100))/12,H5="discount_added",-(O5*P5*(J5-I5)/100)/12))} -> 1980 | T5: =IF(H5<>"created",0,IF(COUNTIFS($C$1:C4,$C5,$H$1:H4,"created")=0,1,0)) -> 1 | U5: =IF(H5<>"cancelled",0,IF(COUNTIFS($C$2:$C$98,$C5,$H$2:$H$98,"created",$F$2:$F$98,"<="&F5)-COUNTIFS($C$2:$C$98,$C5,$H$2:$H$98,"cancelled",$F$2:$F$98,"<="&F5)=0,1,0)) -> 0 | V5: =IF(AND(H5="created",T5=0,COUNTIFS($C$2:$C$98,$C5,$H$2:$H$98,"cancelled",$F$2:$F$98,"<"&F5)>0,COUNTIFS($C$2:$C$98,$C5,$H$2:$H$98,"created",$F$2:$F$98,"<"&F5)-COUNTIFS($C$2:$C$98,$C5,$H$2:$H$98,"cancelled",$F$2:$F$98,"<"&F5)=0),1,0) -> 0
A6: EVT005 | B6: SUB055 | C6: CUST004 | D6: Prairie Commerce Group | E6: Western Canada | F6: 45323 | G6: 45341 | H6: created | M6: Analytics Enterprise | N6: Monthly | O6: 26 | P6: 180 | Q6: 0 | R6: {=_xlfn.IFS(H6="created", "New", H6="cancelled", "Churned", AND(H6="seats_change", J6 > I6), "Expansion", AND(H6="seats_change", J6 < I6), "Contraction", AND(H6="price_change", J6 > I6), "Expansion", AND(H6="price_change", J6 < I6), "Contraction", H6="plan_upgrade", "Expansion", H6="plan_downgrade", "Contraction", H6="discount_added", "Contraction")} -> New | S6: {=IF(N6="Monthly",_xlfn.IFS(H6="created",O6*P6*(1-Q6/100),H6="cancelled",-(O6*P6*(1-Q6/100)),H6="seats_change",(J6-I6)*P6*(1-Q6/100),H6="price_change",(J6-I6)*O6*(1-Q6/100),H6="discount_added",-(O6*P6*(J6-I6)/100),H6="plan_upgrade",O6*(_xlfn.XLOOKUP(J6,$M:$M,$P:$P)-_xlfn.XLOOKUP(I6,$M:$M,$P:$P))*(1-Q6/100),H6="plan_downgrade",O6*(_xlfn.XLOOKUP(J6,$M:$M,$P:$P)-_xlfn.XLOOKUP(I6,$M:$M,$P:$P))*(1-Q6/100)),_xlfn.IFS(H6="created",O6*P6*(1-Q6/100)/12,H6="cancelled",-(O6*P6*(1-Q6/100))/12,H6="seats_change",(J6-I6)*P6*(1-Q6/100)/12,H6="price_change",(J6-I6)*O6*(1-Q6/100)/12,H6="plan_upgrade",(O6*(_xlfn.XLOOKUP(J6,$M:$M,$P:$P)-_xlfn.XLOOKUP(I6,$M:$M,$P:$P))*(1-Q6/100))/12,H6="plan_downgrade",(O6*(_xlfn.XLOOKUP(J6,$M:$M,$P:$P)-_xlfn.XLOOKUP(I6,$M:$M,$P:$P))*(1-Q6/100))/12,H6="discount_added",-(O6*P6*(J6-I6)/100)/12))} -> 4680 | T6: =IF(H6<>"created",0,IF(COUNTIFS($C$1:C5,$C6,$H$1:H5,"created")=0,1,0)) -> 0 | U6: =IF(H6<>"cancelled",0,IF(COUNTIFS($C$2:$C$98,$C6,$H$2:$H$98,"created",$F$2:$F$98,"<="&F6)-COUNTIFS($C$2:$C$98,$C6,$H$2:$H$98,"cancelled",$F$2:$F$98,"<="&F6)=0,1,0)) -> 0 | V6: =IF(AND(H6="created",T6=0,COUNTIFS($C$2:$C$98,$C6,$H$2:$H$98,"cancelled",$F$2:$F$98,"<"&F6)>0,COUNTIFS($C$2:$C$98,$C6,$H$2:$H$98,"created",$F$2:$F$98,"<"&F6)-COUNTIFS($C$2:$C$98,$C6,$H$2:$H$98,"cancelled",$F$2:$F$98,"<"&F6)=0),1,0) -> 0
A7: EVT006 | B7: SUB005 | C7: CUST005 | D7: Atlantic Media Corp | E7: Eastern Canada | F7: 45352 | G7: 45355 | H7: created | M7: Analytics Starter | N7: Monthly | O7: 11 | P7: 45 | Q7: 0 | R7: {=_xlfn.IFS(H7="created", "New", H7="cancelled", "Churned", AND(H7="seats_change", J7 > I7), "Expansion", AND(H7="seats_change", J7 < I7), "Contraction", AND(H7="price_change", J7 > I7), "Expansion", AND(H7="price_change", J7 < I7), "Contraction", H7="plan_upgrade", "Expansion", H7="plan_downgrade", "Contraction", H7="discount_added", "Contraction")} -> New | S7: {=IF(N7="Monthly",_xlfn.IFS(H7="created",O7*P7*(1-Q7/100),H7="cancelled",-(O7*P7*(1-Q7/100)),H7="seats_change",(J7-I7)*P7*(1-Q7/100),H7="price_change",(J7-I7)*O7*(1-Q7/100),H7="discount_added",-(O7*P7*(J7-I7)/100),H7="plan_upgrade",O7*(_xlfn.XLOOKUP(J7,$M:$M,$P:$P)-_xlfn.XLOOKUP(I7,$M:$M,$P:$P))*(1-Q7/100),H7="plan_downgrade",O7*(_xlfn.XLOOKUP(J7,$M:$M,$P:$P)-_xlfn.XLOOKUP(I7,$M:$M,$P:$P))*(1-Q7/100)),_xlfn.IFS(H7="created",O7*P7*(1-Q7/100)/12,H7="cancelled",-(O7*P7*(1-Q7/100))/12,H7="seats_change",(J7-I7)*P7*(1-Q7/100)/12,H7="price_change",(J7-I7)*O7*(1-Q7/100)/12,H7="plan_upgrade",(O7*(_xlfn.XLOOKUP(J7,$M:$M,$P:$P)-_xlfn.XLOOKUP(I7,$M:$M,$P:$P))*(1-Q7/100))/12,H7="plan_downgrade",(O7*(_xlfn.XLOOKUP(J7,$M:$M,$P:$P)-_xlfn.XLOOKUP(I7,$M:$M,$P:$P))*(1-Q7/100))/12,H7="discount_added",-(O7*P7*(J7-I7)/100)/12))} -> 495 | T7: =IF(H7<>"created",0,IF(COUNTIFS($C$1:C6,$C7,$H$1:H6,"created")=0,1,0)) -> 1 | U7: =IF(H7<>"cancelled",0,IF(COUNTIFS($C$2:$C$98,$C7,$H$2:$H$98,"created",$F$2:$F$98,"<="&F7)-COUNTIFS($C$2:$C$98,$C7,$H$2:$H$98,"cancelled",$F$2:$F$98,"<="&F7)=0,1,0)) -> 0 | V7: =IF(AND(H7="created",T7=0,COUNTIFS($C$2:$C$98,$C7,$H$2:$H$98,"cancelled",$F$2:$F$98,"<"&F7)>0,COUNTIFS($C$2:$C$98,$C7,$H$2:$H$98,"created",$F$2:$F$98,"<"&F7)-COUNTIFS($C$2:$C$98,$C7,$H$2:$H$98,"cancelled",$F$2:$F$98,"<"&F7)=0),1,0) -> 0
A8: EVT007 | B8: SUB006 | C8: CUST006 | D8: Northern Retail Solutions | E8: Western Canada | F8: 45352 | G8: 45369 | H8: created | M8: Analytics Enterprise | N8: Annual | O8: 31 | P8: 2160 | Q8: 0 | R8: {=_xlfn.IFS(H8="created", "New", H8="cancelled", "Churned", AND(H8="seats_change", J8 > I8), "Expansion", AND(H8="seats_change", J8 < I8), "Contraction", AND(H8="price_change", J8 > I8), "Expansion", AND(H8="price_change", J8 < I8), "Contraction", H8="plan_upgrade", "Expansion", H8="plan_downgrade", "Contraction", H8="discount_added", "Contraction")} -> New | S8: {=IF(N8="Monthly",_xlfn.IFS(H8="created",O8*P8*(1-Q8/100),H8="cancelled",-(O8*P8*(1-Q8/100)),H8="seats_change",(J8-I8)*P8*(1-Q8/100),H8="price_change",(J8-I8)*O8*(1-Q8/100),H8="discount_added",-(O8*P8*(J8-I8)/100),H8="plan_upgrade",O8*(_xlfn.XLOOKUP(J8,$M:$M,$P:$P)-_xlfn.XLOOKUP(I8,$M:$M,$P:$P))*(1-Q8/100),H8="plan_downgrade",O8*(_xlfn.XLOOKUP(J8,$M:$M,$P:$P)-_xlfn.XLOOKUP(I8,$M:$M,$P:$P))*(1-Q8/100)),_xlfn.IFS(H8="created",O8*P8*(1-Q8/100)/12,H8="cancelled",-(O8*P8*(1-Q8/100))/12,H8="seats_change",(J8-I8)*P8*(1-Q8/100)/12,H8="price_change",(J8-I8)*O8*(1-Q8/100)/12,H8="plan_upgrade",(O8*(_xlfn.XLOOKUP(J8,$M:$M,$P:$P)-_xlfn.XLOOKUP(I8,$M:$M,$P:$P))*(1-Q8/100))/12,H8="plan_downgrade",(O8*(_xlfn.XLOOKUP(J8,$M:$M,$P:$P)-_xlfn.XLOOKUP(I8,$M:$M,$P:$P))*(1-Q8/100))/12,H8="discount_added",-(O8*P8*(J8-I8)/100)/12))} -> 5580 | T8: =IF(H8<>"created",0,IF(COUNTIFS($C$1:C7,$C8,$H$1:H7,"created")=0,1,0)) -> 1 | U8: =IF(H8<>"cancelled",0,IF(COUNTIFS($C$2:$C$98,$C8,$H$2:$H$98,"created",$F$2:$F$98,"<="&F8)-COUNTIFS($C$2:$C$98,$C8,$H$2:$H$98,"cancelled",$F$2:$F$98,"<="&F8)=0,1,0)) -> 0 | V8: =IF(AND(H8="created",T8=0,COUNTIFS($C$2:$C$98,$C8,$H$2:$H$98,"cancelled",$F$2:$F$98,"<"&F8)>0,COUNTIFS($C$2:$C$98,$C8,$H$2:$H$98,"created",$F$2:$F$98,"<"&F8)-COUNTIFS($C$2:$C$98,$C8,$H$2:$H$98,"cancelled",$F$2:$F$98,"<"&F8)=0),1,0) -> 0
A9: EVT008 | B9: SUB007 | C9: CUST007 | D9: Ontario Manufacturing Tech | E9: Eastern Canada | F9: 45383 | G9: 45383 | H9: created | M9: Marketing Pro | N9: Monthly | O9: 16 | P9: 85 | Q9: 0 | R9: {=_xlfn.IFS(H9="created", "New", H9="cancelled", "Churned", AND(H9="seats_change", J9 > I9), "Expansion", AND(H9="seats_change", J9 < I9), "Contraction", AND(H9="price_change", J9 > I9), "Expansion", AND(H9="price_change", J9 < I9), "Contraction", H9="plan_upgrade", "Expansion", H9="plan_downgrade", "Contraction", H9="discount_added", "Contraction")} -> New | S9: {=IF(N9="Monthly",_xlfn.IFS(H9="created",O9*P9*(1-Q9/100),H9="cancelled",-(O9*P9*(1-Q9/100)),H9="seats_change",(J9-I9)*P9*(1-Q9/100),H9="price_change",(J9-I9)*O9*(1-Q9/100),H9="discount_added",-(O9*P9*(J9-I9)/100),H9="plan_upgrade",O9*(_xlfn.XLOOKUP(J9,$M:$M,$P:$P)-_xlfn.XLOOKUP(I9,$M:$M,$P:$P))*(1-Q9/100),H9="plan_downgrade",O9*(_xlfn.XLOOKUP(J9,$M:$M,$P:$P)-_xlfn.XLOOKUP(I9,$M:$M,$P:$P))*(1-Q9/100)),_xlfn.IFS(H9="created",O9*P9*(1-Q9/100)/12,H9="cancelled",-(O9*P9*(1-Q9/100))/12,H9="seats_change",(J9-I9)*P9*(1-Q9/100)/12,H9="price_change",(J9-I9)*O9*(1-Q9/100)/12,H9="plan_upgrade",(O9*(_xlfn.XLOOKUP(J9,$M:$M,$P:$P)-_xlfn.XLOOKUP(I9,$M:$M,$P:$P))*(1-Q9/100))/12,H9="plan_downgrade",(O9*(_xlfn.XLOOKUP(J9,$M:$M,$P:$P)-_xlfn.XLOOKUP(I9,$M:$M,$P:$P))*(1-Q9/100))/12,H9="discount_added",-(O9*P9*(J9-I9)/100)/12))} -> 1360 | T9: =IF(H9<>"created",0,IF(COUNTIFS($C$1:C8,$C9,$H$1:H8,"created")=0,1,0)) -> 1 | U9: =IF(H9<>"cancelled",0,IF(COUNTIFS($C$2:$C$98,$C9,$H$2:$H$98,"created",$F$2:$F$98,"<="&F9)-COUNTIFS($C$2:$C$98,$C9,$H$2:$H$98,"cancelled",$F$2:$F$98,"<="&F9)=0,1,0)) -> 0 | V9: =IF(AND(H9="created",T9=0,COUNTIFS($C$2:$C$98,$C9,$H$2:$H$98,"cancelled",$F$2:$F$98,"<"&F9)>0,COUNTIFS($C$2:$C$98,$C9,$H$2:$H$98,"created",$F$2:$F$98,"<"&F9)-COUNTIFS($C$2:$C$98,$C9,$H$2:$H$98,"cancelled",$F$2:$F$98,"<"&F9)=0),1,0) -> 0
A10: EVT009 | B10: SUB050 | C10: CUST007 | D10: Ontario Manufacturing Tech | E10: Eastern Canada | F10: 45383 | G10: 45383 | H10: created | M10: Analytics Starter | N10: Monthly | O10: 15 | P10: 45 | Q10: 12 | R10: {=_xlfn.IFS(H10="created", "New", H10="cancelled", "Churned", AND(H10="seats_change", J10 > I10), "Expansion", AND(H10="seats_change", J10 < I10), "Contraction", AND(H10="price_change", J10 > I10), "Expansion", AND(H10="price_change", J10 < I10), "Contraction", H10="plan_upgrade", "Expansion", H10="plan_downgrade", "Contraction", H10="discount_added", "Contraction")} -> New | S10: {=IF(N10="Monthly",_xlfn.IFS(H10="created",O10*P10*(1-Q10/100),H10="cancelled",-(O10*P10*(1-Q10/100)),H10="seats_change",(J10-I10)*P10*(1-Q10/100),H10="price_change",(J10-I10)*O10*(1-Q10/100),H10="discount_added",-(O10*P10*(J10-I10)/100),H10="plan_upgrade",O10*(_xlfn.XLOOKUP(J10,$M:$M,$P:$P)-_xlfn.XLOOKUP(I10,$M:$M,$P:$P))*(1-Q10/100),H10="plan_downgrade",O10*(_xlfn.XLOOKUP(J10,$M:$M,$P:$P)-_xlfn.XLOOKUP(I10,$M:$M,$P:$P))*(1-Q10/100)),_xlfn.IFS(H10="created",O10*P10*(1-Q10/100)/12,H10="cancelled",-(O10*P10*(1-Q10/100))/12,H10="seats_change",(J10-I10)*P10*(1-Q10/100)/12,H10="price_change",(J10-I10)*O10*(1-Q10/100)/12,H10="plan_upgrade",(O10*(_xlfn.XLOOKUP(J10,$M:$M,$P:$P)-_xlfn.XLOOKUP(I10,$M:$M,$P:$P))*(1-Q10/100))/12,H10="plan_downgrade",(O10*(_xlfn.XLOOKUP(J10,$M:$M,$P:$P)-_xlfn.XLOOKUP(I10,$M:$M,$P:$P))*(1-Q10/100))/12,H10="discount_added",-(O10*P10*(J10-I10)/100)/12))} -> 594 | T10: =IF(H10<>"created",0,IF(COUNTIFS($C$1:C9,$C10,$H$1:H9,"created")=0,1,0)) -> 0 | U10: =IF(H10<>"cancelled",0,IF(COUNTIFS($C$2:$C$98,$C10,$H$2:$H$98,"created",$F$2:$F$98,"<="&F10)-COUNTIFS($C$2:$C$98,$C10,$H$2:$H$98,"cancelled",$F$2:$F$98,"<="&F10)=0,1,0)) -> 0 | V10: =IF(AND(H10="created",T10=0,COUNTIFS($C$2:$C$98,$C10,$H$2:$H$98,"cancelled",$F$2:$F$98,"<"&F10)>0,COUNTIFS($C$2:$C$98,$C10,$H$2:$H$98,"created",$F$2:$F$98,"<"&F10)-COUNTIFS($C$2:$C$98,$C10,$H$2:$H$98,"cancelled",$F$2:$F$98,"<"&F10)=0),1,0) -> 0
A11: EVT010 | B11: SUB008 | C11: CUST008 | D11: Quantum Education Platform | E11: Eastern Canada | F11: 45383 | G11: 45397 | H11: created | M11: Analytics Growth | N11: Monthly | O11: 22 | P11: 95 | Q11: 0 | R11: {=_xlfn.IFS(H11="created", "New", H11="cancelled", "Churned", AND(H11="seats_change", J11 > I11), "Expansion", AND(H11="seats_change", J11 < I11), "Contraction", AND(H11="price_change", J11 > I11), "Expansion", AND(H11="price_change", J11 < I11), "Contraction", H11="plan_upgrade", "Expansion", H11="plan_downgrade", "Contraction", H11="discount_added", "Contraction")} -> New | S11: {=IF(N11="Monthly",_xlfn.IFS(H11="created",O11*P11*(1-Q11/100),H11="cancelled",-(O11*P11*(1-Q11/100)),H11="seats_change",(J11-I11)*P11*(1-Q11/100),H11="price_change",(J11-I11)*O11*(1-Q11/100),H11="discount_added",-(O11*P11*(J11-I11)/100),H11="plan_upgrade",O11*(_xlfn.XLOOKUP(J11,$M:$M,$P:$P)-_xlfn.XLOOKUP(I11,$M:$M,$P:$P))*(1-Q11/100),H11="plan_downgrade",O11*(_xlfn.XLOOKUP(J11,$M:$M,$P:$P)-_xlfn.XLOOKUP(I11,$M:$M,$P:$P))*(1-Q11/100)),_xlfn.IFS(H11="created",O11*P11*(1-Q11/100)/12,H11="cancelled",-(O11*P11*(1-Q11/100))/12,H11="seats_change",(J11-I11)*P11*(1-Q11/100)/12,H11="price_change",(J11-I11)*O11*(1-Q11/100)/12,H11="plan_upgrade",(O11*(_xlfn.XLOOKUP(J11,$M:$M,$P:$P)-_xlfn.XLOOKUP(I11,$M:$M,$P:$P))*(1-Q11/100))/12,H11="plan_downgrade",(O11*(_xlfn.XLOOKUP(J11,$M:$M,$P:$P)-_xlfn.XLOOKUP(I11,$M:$M,$P:$P))*(1-Q11/100))/12,H11="discount_added",-(O11*P11*(J11-I11)/100)/12))} -> 2090 | T11: =IF(H11<>"created",0,IF(COUNTIFS($C$1:C10,$C11,$H$1:H10,"created")=0,1,0)) -> 1 | U11: =IF(H11<>"cancelled",0,IF(COUNTIFS($C$2:$C$98,$C11,$H$2:$H$98,"created",$F$2:$F$98,"<="&F11)-COUNTIFS($C$2:$C$98,$C11,$H$2:$H$98,"cancelled",$F$2:$F$98,"<="&F11)=0,1,0)) -> 0 | V11: =IF(AND(H11="created",T11=0,COUNTIFS($C$2:$C$98,$C11,$H$2:$H$98,"cancelled",$F$2:$F$98,"<"&F11)>0,COUNTIFS($C$2:$C$98,$C11,$H$2:$H$98,"created",$F$2:$F$98,"<"&F11)-COUNTIFS($C$2:$C$98,$C11,$H$2:$H$98,"cancelled",$F$2:$F$98,"<"&F11)=0),1,0) -> 0
A12: EVT011 | B12: SUB009 | C12: CUST009 | D12: West Coast Logistics | E12: Western Canada | F12: 45383 | G12: 45411 | H12: created | M12: Platform Suite | N12: Annual | O12: 36 | P12: 1800 | Q12: 0 | R12: {=_xlfn.IFS(H12="created", "New", H12="cancelled", "Churned", AND(H12="seats_change", J12 > I12), "Expansion", AND(H12="seats_change", J12 < I12), "Contraction", AND(H12="price_change", J12 > I12), "Expansion", AND(H12="price_change", J12 < I12), "Contraction", H12="plan_upgrade", "Expansion", H12="plan_downgrade", "Contraction", H12="discount_added", "Contraction")} -> New | S12: {=IF(N12="Monthly",_xlfn.IFS(H12="created",O12*P12*(1-Q12/100),H12="cancelled",-(O12*P12*(1-Q12/100)),H12="seats_change",(J12-I12)*P12*(1-Q12/100),H12="price_change",(J12-I12)*O12*(1-Q12/100),H12="discount_added",-(O12*P12*(J12-I12)/100),H12="plan_upgrade",O12*(_xlfn.XLOOKUP(J12,$M:$M,$P:$P)-_xlfn.XLOOKUP(I12,$M:$M,$P:$P))*(1-Q12/100),H12="plan_downgrade",O12*(_xlfn.XLOOKUP(J12,$M:$M,$P:$P)-_xlfn.XLOOKUP(I12,$M:$M,$P:$P))*(1-Q12/100)),_xlfn.IFS(H12="created",O12*P12*(1-Q12/100)/12,H12="cancelled",-(O12*P12*(1-Q12/100))/12,H12="seats_change",(J12-I12)*P12*(1-Q12/100)/12,H12="price_change",(J12-I12)*O12*(1-Q12/100)/12,H12="plan_upgrade",(O12*(_xlfn.XLOOKUP(J12,$M:$M,$P:$P)-_xlfn.XLOOKUP(I12,$M:$M,$P:$P))*(1-Q12/100))/12,H12="plan_downgrade",(O12*(_xlfn.XLOOKUP(J12,$M:$M,$P:$P)-_xlfn.XLOOKUP(I12,$M:$M,$P:$P))*(1-Q12/100))/12,H12="discount_added",-(O12*P12*(J12-I12)/100)/12))} -> 5400 | T12: =IF(H12<>"created",0,IF(COUNTIFS($C$1:C11,$C12,$H$1:H11,"created")=0,1,0)) -> 1 | U12: =IF(H12<>"cancelled",0,IF(COUNTIFS($C$2:$C$98,$C12,$H$2:$H$98,"created",$F$2:$F$98,"<="&F12)-COUNTIFS($C$2:$C$98,$C12,$H$2:$H$98,"cancelled",$F$2:$F$98,"<="&F12)=0,1,0)) -> 0 | V12: =IF(AND(H12="created",T12=0,COUNTIFS($C$2:$C$98,$C12,$H$2:$H$98,"cancelled",$F$2:$F$98,"<"&F12)>0,COUNTIFS($C$2:$C$98,$C12,$H$2:$H$98,"created",$F$2:$F$98,"<"&F12)-COUNTIFS($C$2:$C$98,$C12,$H$2:$H$98,"cancelled",$F$2:$F$98,"<"&F12)=0),1,0) -> 0
A13: EVT012 | B13: SUB010 | C13: CUST010 | D13: Montreal Finance Hub | E13: Eastern Canada | F13: 45413 | G13: 45425 | H13: created | M13: Analytics Starter | N13: Monthly | O13: 13 | P13: 45 | Q13: 0 | R13: {=_xlfn.IFS(H13="created", "New", H13="cancelled", "Churned", AND(H13="seats_change", J13 > I13), "Expansion", AND(H13="seats_change", J13 < I13), "Contraction", AND(H13="price_change", J13 > I13), "Expansion", AND(H13="price_change", J13 < I13), "Contraction", H13="plan_upgrade", "Expansion", H13="plan_downgrade", "Contraction", H13="discount_added", "Contraction")} -> New | S13: {=IF(N13="Monthly",_xlfn.IFS(H13="created",O13*P13*(1-Q13/100),H13="cancelled",-(O13*P13*(1-Q13/100)),H13="seats_change",(J13-I13)*P13*(1-Q13/100),H13="price_change",(J13-I13)*O13*(1-Q13/100),H13="discount_added",-(O13*P13*(J13-I13)/100),H13="plan_upgrade",O13*(_xlfn.XLOOKUP(J13,$M:$M,$P:$P)-_xlfn.XLOOKUP(I13,$M:$M,$P:$P))*(1-Q13/100),H13="plan_downgrade",O13*(_xlfn.XLOOKUP(J13,$M:$M,$P:$P)-_xlfn.XLOOKUP(I13,$M:$M,$P:$P))*(1-Q13/100)),_xlfn.IFS(H13="created",O13*P13*(1-Q13/100)/12,H13="cancelled",-(O13*P13*(1-Q13/100))/12,H13="seats_change",(J13-I13)*P13*(1-Q13/100)/12,H13="price_change",(J13-I13)*O13*(1-Q13/100)/12,H13="plan_upgrade",(O13*(_xlfn.XLOOKUP(J13,$M:$M,$P:$P)-_xlfn.XLOOKUP(I13,$M:$M,$P:$P))*(1-Q13/100))/12,H13="plan_downgrade",(O13*(_xlfn.XLOOKUP(J13,$M:$M,$P:$P)-_xlfn.XLOOKUP(I13,$M:$M,$P:$P))*(1-Q13/100))/12,H13="discount_added",-(O13*P13*(J13-I13)/100)/12))} -> 585 | T13: =IF(H13<>"created",0,IF(COUNTIFS($C$1:C12,$C13,$H$1:H12,"created")=0,1,0)) -> 1 | U13: =IF(H13<>"cancelled",0,IF(COUNTIFS($C$2:$C$98,$C13,$H$2:$H$98,"created",$F$2:$F$98,"<="&F13)-COUNTIFS($C$2:$C$98,$C13,$H$2:$H$98,"cancelled",$F$2:$F$98,"<="&F13)=0,1,0)) -> 0 | V13: =IF(AND(H13="created",T13=0,COUNTIFS($C$2:$C$98,$C13,$H$2:$H$98,"cancelled",$F$2:$F$98,"<"&F13)>0,COUNTIFS($C$2:$C$98,$C13,$H$2:$H$98,"created",$F$2:$F$98,"<"&F13)-COUNTIFS($C$2:$C$98,$C13,$H$2:$H$98,"cancelled",$F$2:$F$98,"<"&F13)=0),1,0) -> 0
... A23: EVT022 | B23: SUB017 | C23: CUST017 | D23: Capital Education Tech | E23: Eastern Canada | F23: 45505 | G23: 45523 | H23: created | M23: Analytics Starter | N23: Monthly | O23: 12 | P23: 45 | Q23: 0 | R23: {=_xlfn.IFS(H23="created", "New", H23="cancelled", "Churned", AND(H23="seats_change", J23 > I23), "Expansion", AND(H23="seats_change", J23 < I23), "Contraction", AND(H23="price_change", J23 > I23), "Expansion", AND(H23="price_change", J23 < I23), "Contraction", H23="plan_upgrade", "Expansion", H23="plan_downgrade", "Contraction", H23="discount_added", "Contraction")} -> New | S23: {=IF(N23="Monthly",_xlfn.IFS(H23="created",O23*P23*(1-Q23/100),H23="cancelled",-(O23*P23*(1-Q23/100)),H23="seats_change",(J23-I23)*P23*(1-Q23/100),H23="price_change",(J23-I23)*O23*(1-Q23/100),H23="discount_added",-(O23*P23*(J23-I23)/100),H23="plan_upgrade",O23*(_xlfn.XLOOKUP(J23,$M:$M,$P:$P)-_xlfn.XLOOKUP(I23,$M:$M,$P:$P))*(1-Q23/100),H23="plan_downgrade",O23*(_xlfn.XLOOKUP(J23,$M:$M,$P:$P)-_xlfn.XLOOKUP(I23,$M:$M,$P:$P))*(1-Q23/100)),_xlfn.IFS(H23="created",O23*P23*(1-Q23/100)/12,H23="cancelled",-(O23*P23*(1-Q23/100))/12,H23="seats_change",(J23-I23)*P23*(1-Q23/100)/12,H23="price_change",(J23-I23)*O23*(1-Q23/100)/12,H23="plan_upgrade",(O23*(_xlfn.XLOOKUP(J23,$M:$M,$P:$P)-_xlfn.XLOOKUP(I23,$M:$M,$P:$P))*(1-Q23/100))/12,H23="plan_downgrade",(O23*(_xlfn.XLOOKUP(J23,$M:$M,$P:$P)-_xlfn.XLOOKUP(I23,$M:$M,$P:$P))*(1-Q23/100))/12,H23="discount_added",-(O23*P23*(J23-I23)/100)/12))} -> 540 | T23: =IF(H23<>"created",0,IF(COUNTIFS($C$1:C22,$C23,$H$1:H22,"created")=0,1,0)) -> 1 | U23: =IF(H23<>"cancelled",0,IF(COUNTIFS($C$2:$C$98,$C23,$H$2:$H$98,"created",$F$2:$F$98,"<="&F23)-COUNTIFS($C$2:$C$98,$C23,$H$2:$H$98,"cancelled",$F$2:$F$98,"<="&F23)=0,1,0)) -> 0 | V23: =IF(AND(H23="created",T23=0,COUNTIFS($C$2:$C$98,$C23,$H$2:$H$98,"cancelled",$F$2:$F$98,"<"&F23)>0,COUNTIFS($C$2:$C$98,$C23,$H$2:$H$98,"created",$F$2:$F$98,"<"&F23)-COUNTIFS($C$2:$C$98,$C23,$H$2:$H$98,"cancelled",$F$2:$F$98,"<"&F23)=0),1,0) -> 0
A24: EVT023 | B24: SUB001 | C24: CUST001 | D24: TechVision Solutions | E24: Eastern Canada | F24: 45505 | G24: 45531 | H24: cancelled | I24: active | J24: churned | K24: status | L24: Missing features | M24: Analytics Growth | N24: Monthly | O24: 20 | P24: 95 | Q24: 0 | R24: {=_xlfn.IFS(H24="created", "New", H24="cancelled", "Churned", AND(H24="seats_change", J24 > I24), "Expansion", AND(H24="seats_change", J24 < I24), "Contraction", AND(H24="price_change", J24 > I24), "Expansion", AND(H24="price_change", J24 < I24), "Contraction", H24="plan_upgrade", "Expansion", H24="plan_downgrade", "Contraction", H24="discount_added", "Contraction")} -> Churned | S24: {=IF(N24="Monthly",_xlfn.IFS(H24="created",O24*P24*(1-Q24/100),H24="cancelled",-(O24*P24*(1-Q24/100)),H24="seats_change",(J24-I24)*P24*(1-Q24/100),H24="price_change",(J24-I24)*O24*(1-Q24/100),H24="discount_added",-(O24*P24*(J24-I24)/100),H24="plan_upgrade",O24*(_xlfn.XLOOKUP(J24,$M:$M,$P:$P)-_xlfn.XLOOKUP(I24,$M:$M,$P:$P))*(1-Q24/100),H24="plan_downgrade",O24*(_xlfn.XLOOKUP(J24,$M:$M,$P:$P)-_xlfn.XLOOKUP(I24,$M:$M,$P:$P))*(1-Q24/100)),_xlfn.IFS(H24="created",O24*P24*(1-Q24/100)/12,H24="cancelled",-(O24*P24*(1-Q24/100))/12,H24="seats_change",(J24-I24)*P24*(1-Q24/100)/12,H24="price_change",(J24-I24)*O24*(1-Q24/100)/12,H24="plan_upgrade",(O24*(_xlfn.XLOOKUP(J24,$M:$M,$P:$P)-_xlfn.XLOOKUP(I24,$M:$M,$P:$P))*(1-Q24/100))/12,H24="plan_downgrade",(O24*(_xlfn.XLOOKUP(J24,$M:$M,$P:$P)-_xlfn.XLOOKUP(I24,$M:$M,$P:$P))*(1-Q24/100))/12,H24="discount_added",-(O24*P24*(J24-I24)/100)/12))} -> -1900 | T24: =IF(H24<>"created",0,IF(COUNTIFS($C$1:C23,$C24,$H$1:H23,"created")=0,1,0)) -> 0 | U24: =IF(H24<>"cancelled",0,IF(COUNTIFS($C$2:$C$98,$C24,$H$2:$H$98,"created",$F$2:$F$98,"<="&F24)-COUNTIFS($C$2:$C$98,$C24,$H$2:$H$98,"cancelled",$F$2:$F$98,"<="&F24)=0,1,0)) -> 0 | V24: =IF(AND(H24="created",T24=0,COUNTIFS($C$2:$C$98,$C24,$H$2:$H$98,"cancelled",$F$2:$F$98,"<"&F24)>0,COUNTIFS($C$2:$C$98,$C24,$H$2:$H$98,"created",$F$2:$F$98,"<"&F24)-COUNTIFS($C$2:$C$98,$C24,$H$2:$H$98,"cancelled",$F$2:$F$98,"<"&F24)=0),1,0) -> 0
A25: EVT024 | B25: SUB018 | C25: CUST018 | D25: Vancouver FinTech Labs | E25: Western Canada | F25: 45536 | G25: 45537 | H25: created | M25: Analytics Enterprise | N25: Monthly | O25: 35 | P25: 180 | Q25: 0 | R25: {=_xlfn.IFS(H25="created", "New", H25="cancelled", "Churned", AND(H25="seats_change", J25 > I25), "Expansion", AND(H25="seats_change", J25 < I25), "Contraction", AND(H25="price_change", J25 > I25), "Expansion", AND(H25="price_change", J25 < I25), "Contraction", H25="plan_upgrade", "Expansion", H25="plan_downgrade", "Contraction", H25="discount_added", "Contraction")} -> New | S25: {=IF(N25="Monthly",_xlfn.IFS(H25="created",O25*P25*(1-Q25/100),H25="cancelled",-(O25*P25*(1-Q25/100)),H25="seats_change",(J25-I25)*P25*(1-Q25/100),H25="price_change",(J25-I25)*O25*(1-Q25/100),H25="discount_added",-(O25*P25*(J25-I25)/100),H25="plan_upgrade",O25*(_xlfn.XLOOKUP(J25,$M:$M,$P:$P)-_xlfn.XLOOKUP(I25,$M:$M,$P:$P))*(1-Q25/100),H25="plan_downgrade",O25*(_xlfn.XLOOKUP(J25,$M:$M,$P:$P)-_xlfn.XLOOKUP(I25,$M:$M,$P:$P))*(1-Q25/100)),_xlfn.IFS(H25="created",O25*P25*(1-Q25/100)/12,H25="cancelled",-(O25*P25*(1-Q25/100))/12,H25="seats_change",(J25-I25)*P25*(1-Q25/100)/12,H25="price_change",(J25-I25)*O25*(1-Q25/100)/12,H25="plan_upgrade",(O25*(_xlfn.XLOOKUP(J25,$M:$M,$P:$P)-_xlfn.XLOOKUP(I25,$M:$M,$P:$P))*(1-Q25/100))/12,H25="plan_downgrade",(O25*(_xlfn.XLOOKUP(J25,$M:$M,$P:$P)-_xlfn.XLOOKUP(I25,$M:$M,$P:$P))*(1-Q25/100))/12,H25="discount_added",-(O25*P25*(J25-I25)/100)/12))} -> 6300 | T25: =IF(H25<>"created",0,IF(COUNTIFS($C$1:C24,$C25,$H$1:H24,"created")=0,1,0)) -> 1 | U25: =IF(H25<>"cancelled",0,IF(COUNTIFS($C$2:$C$98,$C25,$H$2:$H$98,"created",$F$2:$F$98,"<="&F25)-COUNTIFS($C$2:$C$98,$C25,$H$2:$H$98,"cancelled",$F$2:$F$98,"<="&F25)=0,1,0)) -> 0 | V25: =IF(AND(H25="created",T25=0,COUNTIFS($C$2:$C$98,$C25,$H$2:$H$98,"cancelled",$F$2:$F$98,"<"&F25)>0,COUNTIFS($C$2:$C$98,$C25,$H$2:$H$98,"created",$F$2:$F$98,"<"&F25)-COUNTIFS($C$2:$C$98,$C25,$H$2:$H$98,"cancelled",$F$2:$F$98,"<"&F25)=0),1,0) -> 0
A26: EVT025 | B26: SUB042 | C26: CUST003 | D26: Maple Healthcare Systems | E26: Eastern Canada | F26: 45536 | G26: 45545 | H26: created | M26: Sales Hub | N26: Monthly | O26: 19 | P26: 110 | Q26: 0 | R26: {=_xlfn.IFS(H26="created", "New", H26="cancelled", "Churned", AND(H26="seats_change", J26 > I26), "Expansion", AND(H26="seats_change", J26 < I26), "Contraction", AND(H26="price_change", J26 > I26), "Expansion", AND(H26="price_change", J26 < I26), "Contraction", H26="plan_upgrade", "Expansion", H26="plan_downgrade", "Contraction", H26="discount_added", "Contraction")} -> New | S26: {=IF(N26="Monthly",_xlfn.IFS(H26="created",O26*P26*(1-Q26/100),H26="cancelled",-(O26*P26*(1-Q26/100)),H26="seats_change",(J26-I26)*P26*(1-Q26/100),H26="price_change",(J26-I26)*O26*(1-Q26/100),H26="discount_added",-(O26*P26*(J26-I26)/100),H26="plan_upgrade",O26*(_xlfn.XLOOKUP(J26,$M:$M,$P:$P)-_xlfn.XLOOKUP(I26,$M:$M,$P:$P))*(1-Q26/100),H26="plan_downgrade",O26*(_xlfn.XLOOKUP(J26,$M:$M,$P:$P)-_xlfn.XLOOKUP(I26,$M:$M,$P:$P))*(1-Q26/100)),_xlfn.IFS(H26="created",O26*P26*(1-Q26/100)/12,H26="cancelled",-(O26*P26*(1-Q26/100))/12,H26="seats_change",(J26-I26)*P26*(1-Q26/100)/12,H26="price_change",(J26-I26)*O26*(1-Q26/100)/12,H26="plan_upgrade",(O26*(_xlfn.XLOOKUP(J26,$M:$M,$P:$P)-_xlfn.XLOOKUP(I26,$M:$M,$P:$P))*(1-Q26/100))/12,H26="plan_downgrade",(O26*(_xlfn.XLOOKUP(J26,$M:$M,$P:$P)-_xlfn.XLOOKUP(I26,$M:$M,$P:$P))*(1-Q26/100))/12,H26="discount_added",-(O26*P26*(J26-I26)/100)/12))} -> 2090 | T26: =IF(H26<>"created",0,IF(COUNTIFS($C$1:C25,$C26,$H$1:H25,"created")=0,1,0)) -> 0 | U26: =IF(H26<>"cancelled",0,IF(COUNTIFS($C$2:$C$98,$C26,$H$2:$H$98,"created",$F$2:$F$98,"<="&F26)-COUNTIFS($C$2:$C$98,$C26,$H$2:$H$98,"cancelled",$F$2:$F$98,"<="&F26)=0,1,0)) -> 0 | V26: =IF(AND(H26="created",T26=0,COUNTIFS($C$2:$C$98,$C26,$H$2:$H$98,"cancelled",$F$2:$F$98,"<"&F26)>0,COUNTIFS($C$2:$C$98,$C26,$H$2:$H$98,"created",$F$2:$F$98,"<"&F26)-COUNTIFS($C$2:$C$98,$C26,$H$2:$H$98,"cancelled",$F$2:$F$98,"<"&F26)=0),1,0) -> 0
A27: EVT026 | B27: SUB019 | C27: CUST019 | D27: Central Healthcare Partners | E27: Central Canada | F27: 45536 | G27: 45551 | H27: created | M27: Marketing Pro | N27: Monthly | O27: 19 | P27: 85 | Q27: 0 | R27: {=_xlfn.IFS(H27="created", "New", H27="cancelled", "Churned", AND(H27="seats_change", J27 > I27), "Expansion", AND(H27="seats_change", J27 < I27), "Contraction", AND(H27="price_change", J27 > I27), "Expansion", AND(H27="price_change", J27 < I27), "Contraction", H27="plan_upgrade", "Expansion", H27="plan_downgrade", "Contraction", H27="discount_added", "Contraction")} -> New | S27: {=IF(N27="Monthly",_xlfn.IFS(H27="created",O27*P27*(1-Q27/100),H27="cancelled",-(O27*P27*(1-Q27/100)),H27="seats_change",(J27-I27)*P27*(1-Q27/100),H27="price_change",(J27-I27)*O27*(1-Q27/100),H27="discount_added",-(O27*P27*(J27-I27)/100),H27="plan_upgrade",O27*(_xlfn.XLOOKUP(J27,$M:$M,$P:$P)-_xlfn.XLOOKUP(I27,$M:$M,$P:$P))*(1-Q27/100),H27="plan_downgrade",O27*(_xlfn.XLOOKUP(J27,$M:$M,$P:$P)-_xlfn.XLOOKUP(I27,$M:$M,$P:$P))*(1-Q27/100)),_xlfn.IFS(H27="created",O27*P27*(1-Q27/100)/12,H27="cancelled",-(O27*P27*(1-Q27/100))/12,H27="seats_change",(J27-I27)*P27*(1-Q27/100)/12,H27="price_change",(J27-I27)*O27*(1-Q27/100)/12,H27="plan_upgrade",(O27*(_xlfn.XLOOKUP(J27,$M:$M,$P:$P)-_xlfn.XLOOKUP(I27,$M:$M,$P:$P))*(1-Q27/100))/12,H27="plan_downgrade",(O27*(_xlfn.XLOOKUP(J27,$M:$M,$P:$P)-_xlfn.XLOOKUP(I27,$M:$M,$P:$P))*(1-Q27/100))/12,H27="discount_added",-(O27*P27*(J27-I27)/100)/12))} -> 1615 | T27: =IF(H27<>"created",0,IF(COUNTIFS($C$1:C26,$C27,$H$1:H26,"created")=0,1,0)) -> 1 | U27: =IF(H27<>"cancelled",0,IF(COUNTIFS($C$2:$C$98,$C27,$H$2:$H$98,"created",$F$2:$F$98,"<="&F27)-COUNTIFS($C$2:$C$98,$C27,$H$2:$H$98,"cancelled",$F$2:$F$98,"<="&F27)=0,1,0)) -> 0 | V27: =IF(AND(H27="created",T27=0,COUNTIFS($C$2:$C$98,$C27,$H$2:$H$98,"cancelled",$F$2:$F$98,"<"&F27)>0,COUNTIFS($C$2:$C$98,$C27,$H$2:$H$98,"created",$F$2:$F$98,"<"&F27)-COUNTIFS($C$2:$C$98,$C27,$H$2:$H$98,"cancelled",$F$2:$F$98,"<"&F27)=0),1,0) -> 0
A28: EVT027 | B28: SUB060 | C28: CUST019 | D28: Central Healthcare Partners | E28: Central Canada | F28: 45536 | G28: 45551 | H28: created | M28: Sales Hub | N28: Monthly | O28: 16 | P28: 110 | Q28: 0 | R28: {=_xlfn.IFS(H28="created", "New", H28="cancelled", "Churned", AND(H28="seats_change", J28 > I28), "Expansion", AND(H28="seats_change", J28 < I28), "Contraction", AND(H28="price_change", J28 > I28), "Expansion", AND(H28="price_change", J28 < I28), "Contraction", H28="plan_upgrade", "Expansion", H28="plan_downgrade", "Contraction", H28="discount_added", "Contraction")} -> New | S28: {=IF(N28="Monthly",_xlfn.IFS(H28="created",O28*P28*(1-Q28/100),H28="cancelled",-(O28*P28*(1-Q28/100)),H28="seats_change",(J28-I28)*P28*(1-Q28/100),H28="price_change",(J28-I28)*O28*(1-Q28/100),H28="discount_added",-(O28*P28*(J28-I28)/100),H28="plan_upgrade",O28*(_xlfn.XLOOKUP(J28,$M:$M,$P:$P)-_xlfn.XLOOKUP(I28,$M:$M,$P:$P))*(1-Q28/100),H28="plan_downgrade",O28*(_xlfn.XLOOKUP(J28,$M:$M,$P:$P)-_xlfn.XLOOKUP(I28,$M:$M,$P:$P))*(1-Q28/100)),_xlfn.IFS(H28="created",O28*P28*(1-Q28/100)/12,H28="cancelled",-(O28*P28*(1-Q28/100))/12,H28="seats_change",(J28-I28)*P28*(1-Q28/100)/12,H28="price_change",(J28-I28)*O28*(1-Q28/100)/12,H28="plan_upgrade",(O28*(_xlfn.XLOOKUP(J28,$M:$M,$P:$P)-_xlfn.XLOOKUP(I28,$M:$M,$P:$P))*(1-Q28/100))/12,H28="plan_downgrade",(O28*(_xlfn.XLOOKUP(J28,$M:$M,$P:$P)-_xlfn.XLOOKUP(I28,$M:$M,$P:$P))*(1-Q28/100))/12,H28="discount_added",-(O28*P28*(J28-I28)/100)/12))} -> 1760 | T28: =IF(H28<>"created",0,IF(COUNTIFS($C$1:C27,$C28,$H$1:H27,"created")=0,1,0)) -> 0 | U28: =IF(H28<>"cancelled",0,IF(COUNTIFS($C$2:$C$98,$C28,$H$2:$H$98,"created",$F$2:$F$98,"<="&F28)-COUNTIFS($C$2:$C$98,$C28,$H$2:$H$98,"cancelled",$F$2:$F$98,"<="&F28)=0,1,0)) -> 0 | V28: =IF(AND(H28="created",T28=0,COUNTIFS($C$2:$C$98,$C28,$H$2:$H$98,"cancelled",$F$2:$F$98,"<"&F28)>0,COUNTIFS($C$2:$C$98,$C28,$H$2:$H$98,"created",$F$2:$F$98,"<"&F28)-COUNTIFS($C$2:$C$98,$C28,$H$2:$H$98,"cancelled",$F$2:$F$98,"<"&F28)=0),1,0) -> 0
A29: EVT028 | B29: SUB020 | C29: CUST020 | D29: Atlantic SaaS Systems | E29: Eastern Canada | F29: 45536 | G29: 45565 | H29: created | M29: Sales Hub | N29: Monthly | O29: 15 | P29: 110 | Q29: 0 | R29: {=_xlfn.IFS(H29="created", "New", H29="cancelled", "Churned", AND(H29="seats_change", J29 > I29), "Expansion", AND(H29="seats_change", J29 < I29), "Contraction", AND(H29="price_change", J29 > I29), "Expansion", AND(H29="price_change", J29 < I29), "Contraction", H29="plan_upgrade", "Expansion", H29="plan_downgrade", "Contraction", H29="discount_added", "Contraction")} -> New | S29: {=IF(N29="Monthly",_xlfn.IFS(H29="created",O29*P29*(1-Q29/100),H29="cancelled",-(O29*P29*(1-Q29/100)),H29="seats_change",(J29-I29)*P29*(1-Q29/100),H29="price_change",(J29-I29)*O29*(1-Q29/100),H29="discount_added",-(O29*P29*(J29-I29)/100),H29="plan_upgrade",O29*(_xlfn.XLOOKUP(J29,$M:$M,$P:$P)-_xlfn.XLOOKUP(I29,$M:$M,$P:$P))*(1-Q29/100),H29="plan_downgrade",O29*(_xlfn.XLOOKUP(J29,$M:$M,$P:$P)-_xlfn.XLOOKUP(I29,$M:$M,$P:$P))*(1-Q29/100)),_xlfn.IFS(H29="created",O29*P29*(1-Q29/100)/12,H29="cancelled",-(O29*P29*(1-Q29/100))/12,H29="seats_change",(J29-I29)*P29*(1-Q29/100)/12,H29="price_change",(J29-I29)*O29*(1-Q29/100)/12,H29="plan_upgrade",(O29*(_xlfn.XLOOKUP(J29,$M:$M,$P:$P)-_xlfn.XLOOKUP(I29,$M:$M,$P:$P))*(1-Q29/100))/12,H29="plan_downgrade",(O29*(_xlfn.XLOOKUP(J29,$M:$M,$P:$P)-_xlfn.XLOOKUP(I29,$M:$M,$P:$P))*(1-Q29/100))/12,H29="discount_added",-(O29*P29*(J29-I29)/100)/12))} -> 1650 | T29: =IF(H29<>"created",0,IF(COUNTIFS($C$1:C28,$C29,$H$1:H28,"created")=0,1,0)) -> 1 | U29: =IF(H29<>"cancelled",0,IF(COUNTIFS($C$2:$C$98,$C29,$H$2:$H$98,"created",$F$2:$F$98,"<="&F29)-COUNTIFS($C$2:$C$98,$C29,$H$2:$H$98,"cancelled",$F$2:$F$98,"<="&F29)=0,1,0)) -> 0 | V29: =IF(AND(H29="created",T29=0,COUNTIFS($C$2:$C$98,$C29,$H$2:$H$98,"cancelled",$F$2:$F$98,"<"&F29)>0,COUNTIFS($C$2:$C$98,$C29,$H$2:$H$98,"created",$F$2:$F$98,"<"&F29)-COUNTIFS($C$2:$C$98,$C29,$H$2:$H$98,"cancelled",$F$2:$F$98,"<"&F29)=0),1,0) -> 0
